Workbook
Name \\\\: #REF!
Name \\\\: #REF!
Name \\\\: #REF!
Name \0: #REF!
Name \0: #REF!
Name \0: #REF!
Name \0: #REF!
Name \0: #REF!
Name \a: #REF!
Name \a: #REF!
Name \a: #REF!
Name \a: #REF!
Name \a: #REF!
Name \b: #REF!
Name \b: #REF!
Name \b: #REF!
Name \b: #REF!
Name \b: #REF!
Name \bbb: #REF!
Name \bbb: #REF!
Name \bbb: #REF!
Name \bbb: #REF!
Name \bbb: #REF!
Name \C: #REF!
Name \C: #REF!
Name \C: #REF!
Name \C: #REF!
Name \C: #REF!
Name \C: #REF!
Name \d: #REF!
Name \d: #REF!
Name \d: #REF!
Name \d: #REF!
Name \d: #REF!
Name \e: #REF!
Name \e: #REF!
Name \e: #REF!
Name \f: #N/A
Name \G: #REF!
Name \G: #REF!
Name \G: #REF!
Name \i: #REF!
Name \i: #REF!
Name \i: #REF!
Name \i: #REF!
Name \i: #REF!
Name \J: #REF!
Name \J: #REF!
Name \J: #REF!
Name \K: #REF!
Name \K: #REF!
Name \K: #REF!
Name \l: #REF!
Name \l: #REF!
Name \l: #REF!
Name \m: #REF!
Name \m: #REF!
Name \m: #REF!
Name \m: #REF!
Name \m: #REF!

Sheet FY22-25 IFRS（合并）
B2: CONSOLIDATED STATEMENTS OF PROFIT OR LOSS AND OTHER COMPREHENSIVE INCOME(RMB '000) | E2: IFRS-2021审定数 | G2: IFRS-2022审定数 | I2: IFRS-2023审定数 | K2: IFRS-2024审定数 | M2: IFRS-20240630审定数 | O2: IFRS-250630审定数 | Q2: IFRS-251231
B3: Continuing operations
A4: 营业收入 | B4: Revenue | E4: -79100967 | G4: -2.2281308e+08 | I4: -5.3080586e+08 | K4: -6.5543777e+08 | M4: -2.9311173e+08 | O4: -3.2580849e+08 | Q4: -7.8881792e+08
A5: 营业成本 | B5: Cost of sales | E5: 57146960 | G5: 1.3701032e+08 | I5: 2.8764505e+08 | K5: 4.3035922e+08 | M5: 1.9238482e+08 | O5: 2.2289836e+08 | Q5: 5.1674726e+08
B6: Gross profit | E6: =E4+E5 -> -21954007 | G6: =G4+G5 -> -85802758 | I6: =I4+I5 -> -2.4316081e+08 | K6: =K4+K5 -> -2.2507854e+08 | M6: =M4+M5 -> -1.0072691e+08 | O6: =O4+O5 -> -1.0291013e+08 | Q6: =Q4+Q5 -> -2.7207066e+08
A7: 其他收益 | B7: Other income | E7: -54187.55 | G7: -17971825 | I7: -15975719 | K7: -10846056 | M7: -7396419.4 | O7: -1171485.1 | Q7: -2554126.1
A8: 其他净(损失)/收益 | B8: Other net (loss)/gain | E8: -12669457 | G8: 124678.46 | I8: -37881.56 | K8: 678379.24 | M8: 659901.6 | O8: -167407.18 | Q8: -716563.08
A9: 销售费用 | B9: Selling and marketing expenses | E9: 29718059 | G9: 38110116 | I9: 1.0986149e+08 | K9: 84743936 | M9: 38445226 | O9: 22879865 | Q9: 55235424
A10: 管理费用 | B10: Administrative expenses | E10: 58667135 | G10: 47511905 | I10: 48367874 | K10: 39037309 | M10: 21478502 | O10: 17205791 | Q10: 55632191
A11: 研发费用 | B11: Research and development expenses | E11: 54066977 | G11: 75433068 | I11: 1.295689e+08 | K11: 1.5012925e+08 | M11: 82098448 | O11: 66538960 | Q11: 1.6334213e+08
A12: 信用减值损失 | B12: Impairment loss on financial assets | E12: 1446834.2 | G12: 3552828.8 | I12: 11750182 | K12: 21169519 | M12: 10345025 | O12: 6114900 | Q12: 27595443
B13: Loss from operations | E13: =SUM(E6:E12) -> 1.0922135e+08 | G13: =SUM(G6:G12) -> 60958013 | I13: =SUM(I6:I12) -> 40374033 | K13: =SUM(K6:K12) -> 59833791 | M13: =SUM(M6:M12) -> 44903776 | O13: =SUM(O6:O12) -> 8490494.6 | Q13: =SUM(Q6:Q12) -> 26463835
A14: 财务收入 | B14: Finance income | E14: -14076544 | G14: -9458184.8 | I14: -4606419.3 | K14: -2239349.8 | M14: -623760.44 | O14: -464884.35 | Q14: -856870.83
A15: 财务成本 | B15: Finance costs | E15: 0 | G15: 759096.24 | I15: 435137.11 | K15: 239820.09 | M15: 158049.15 | O15: 99442.49 | Q15: 143669.04
A16: 投资收益 | B16: Share of profits less losses of an associate | E16: 0 | G16: 0 | I16: 1104040.8 | K16: 26695.484 | M16: 0 | O16: 164418.73 | Q16: 164418.73
A17: 向投资者发行金融工具的公允价值变动 | B17: Changes in the carrying amount of redeemable preferred shares | E17: 58659747 | G17: 58659747 | I17: 58659747 | K17: 53838398 | M17: 29329873 | O17: 0 | Q17: 0
A18: 公允价值变动损益 | B18: Fair Value Through Other Comprehensive Income | E18: 0 | G18: 0 | I18: 0 | K18: 0 | M18: 0 | O18: 0 | Q18: 0
B19: Loss before taxation from continuing operations | E19: =SUM(E13:E17) -> 1.5380456e+08 | G19: =SUM(G13:G17) -> 1.1091867e+08 | I19: =SUM(I13:I17) -> 95966539 | K19: =SUM(K13:K17) -> 1.1169935e+08 | M19: =SUM(M13:M17) -> 73767938 | O19: =SUM(O13:O17) -> 8289471.4 | Q19: =SUM(Q13:Q17) -> 25915052
A20: 所得税费用 | B20: Income tax | E20: 0 | G20: 134240.41 | I20: -59685.84 | K20: 0 | M20: 0 | O20: 0 | Q20: 0
B21: Profit/(loss) for the year from continuing operations | E21: =SUM(E19:E20) -> 1.5380456e+08 | G21: =SUM(G19:G20) -> 1.1105291e+08 | I21: =SUM(I19:I20) -> 95906853 | K21: =SUM(K19:K20) -> 1.1169935e+08 | M21: =SUM(M19:M20) -> 73767938 | O21: =SUM(O19:O20) -> 8289471.4 | Q21: =SUM(Q19:Q20) -> 25915052
B23: Other comprehensive income for the year/period (after tax)
B24: Exchange differences on translation of financial statements of overseas subsidiaries | Q24: 474532.31
B26: Other comprehensive income for the year/period | E26: =E24 -> 0 | G26: =G24 -> 0 | I26: =I24 -> 0 | K26: =K24 -> 0 | M26: =M24 -> 0 | O26: =O24 -> 0 | Q26: =Q24 -> 474532.31
B28: Total comprehensive income for the year/period attributable to equity shareholders of the Company | E28: =E26+E21 -> 1.5380456e+08 | G28: =G26+G21 -> 1.1105291e+08 | I28: =I26+I21 -> 95906853 | K28: =K26+K21 -> 1.1169935e+08 | M28: =M26+M21 -> 73767938 | O28: =O26+O21 -> 8289471.4 | Q28: =Q26+Q21 -> 26389585
B30: Check
B32: CONSOLIDATED STATEMENTS OF FINANCIAL POSITION(RMB '000) | E32: IFRS-2021审定数 | G32: IFRS-2022审定数 | I32: IFRS-2023审定数 | K32: IFRS-2024审定数 | M32: IFRS-20240630审定数 | O32: IFRS-250630审定数 | Q32: IFRS-251231
B33: Expressed in RMB
B34: Non-current assets
A35: 物业、厂房及设备 | B35: Property, plant and equipment | E35: 13062838 | G35: 13977867 | I35: 13965362 | K35: 9842079.2 | M35: 12862054 | O35: 7201488 | Q35: 4746012.2
A36: 使用权资产 | B36: Right-of-use assets | E36: 18557943 | G36: 13111789 | I36: 6703851.9 | K36: 3465689.7 | M36: 6123908.5 | O36: 6342883.4 | Q36: 4886520.2
A37: 无形资产 | B37: Intangible assets | E37: 2013506.7 | G37: 1266086.5 | I37: 713394.6 | K37: 493005.35 | M37: 544443.18 | O37: 455394.83 | Q37: 417784.31
B38: Contract assets - LT | E38: 0 | G38: 428119.63 | I38: 1358136.9 | K38: 7137320.7 | M38: 2243838.9 | O38: 5588050.3 | Q38: 5463100.5
A39: 长期股权投资 | B39: Interests in an associates | E39: 2000000 | G39: 0 | I39: 0 | K39: 173304.52 | M39: 0 | O39: 198885.79 | Q39: 0
B40: Interests in subsidiaries
A41: 预付款项、按金及其他应收款项 - 长期 | B41: Prepayments, deposits and other receivables - LT | E41: 0 | G41: 0 | I41: 0 | K41: 0 | M41: 0 | O41: 0 | Q41: 0
A42: 长期应收款 | B42: Long-term receivables | E42: 0 | G42: 0 | I42: 0 | K42: 0 | M42: 0 | O42: 0 | Q42: 0
E43: =SUM(E35:E42) -> 35634288 | G43: =SUM(G35:G42) -> 28783861 | I43: =SUM(I35:I42) -> 22740745 | K43: =SUM(K35:K42) -> 21111399 | M43: =SUM(M35:M42) -> 21774245 | O43: =SUM(O35:O42) -> 19786702 | Q43: =SUM(Q35:Q42) -> 15513417
B44: Current assets
A45: 存货 | B45: Inventories | E45: 1483376.3 | G45: 297941.71 | I45: 14994415 | K45: 42367810 | M45: 694616.1 | O45: 70024651 | Q45: 79207862
A46: 应收账款 | B46: Trade receivables | E46: 28679317 | G46: 57107464 | I46: 1.4671723e+08 | K46: 2.3247504e+08 | M46: 2.613989e+08 | O46: 2.1485723e+08 | Q46: 2.8163701e+08
...

Sheet PL>>

Sheet 收入拆分
B1: Revenue | C1: 营业收入 | D1: 2022 | E1: 2023 | F1: 2024 | G1: 2025
B2: GJ digital human intelligent platform | C2: 硅基数字人智能交互（ICT+数字人智能产品） | D2: =(-收入成本拆分!D6-收入成本拆分!D7)/1000 -> 139864.03 | E2: =(-收入成本拆分!F6-收入成本拆分!F7)/1000 -> 460050.82 | F2: =(-收入成本拆分!H6-收入成本拆分!H7)/1000 -> 612656 | G2: =(-收入成本拆分!J6-收入成本拆分!J7)/1000 -> 722872.01
B3: GJ intelligent voice | C3: 硅基智能语音 | D3: =-收入成本拆分!D8/1000 -> 68752.075 | E3: =-收入成本拆分!F8/1000 -> 25312.277 | F3: =-收入成本拆分!H8/1000 -> 16788.507 | G3: =-收入成本拆分!J8/1000 -> 3974.9551
B4: GJ video production, livestreaming | C4: 硅基数字人视频、直播 | D4: =-收入成本拆分!D9/1000 -> 14196.979 | E4: =-收入成本拆分!F9/1000 -> 45442.759 | F4: =-收入成本拆分!H9/1000 -> 25993.256 | G4: =-收入成本拆分!J9/1000 -> 10583.474
B5: GJ Autopilot AIGC Agents | C5: 硅基全自动内容生产 | D5: 0 | E5: 0 | F5: 0 | G5: =-收入成本拆分!J10/1000 -> 51387.72
B6: Total revenue | C6: 收入合计 | D6: =D3+D4+D2+D5 -> 222813.08 | E6: =E3+E4+E2+E5 -> 530805.86 | F6: =F3+F4+F2+F5 -> 655437.77 | G6: =G3+G4+G2+G5 -> 788818.16
B8: Cost | C8: 营业成本 | D8: 2022 | E8: 2023 | F8: 2024 | G8: 2025
B9: GJ digital human intelligent platform | C9: 硅基数字人智能交互（ICT+数字人智能产品） | D9: =(收入成本拆分!D17+收入成本拆分!D18+收入成本拆分!D33)/1000 -> 83068.019 | E9: =(收入成本拆分!F17+收入成本拆分!F18+收入成本拆分!F33)/1000 -> 261270.72 | F9: =(收入成本拆分!H17+收入成本拆分!H18+收入成本拆分!H33)/1000 -> 411907.13 | G9: =(收入成本拆分!J17+收入成本拆分!J18+收入成本拆分!J33)/1000 -> 482503.68
B10: GJ intelligent voice | C10: 硅基智能语音 | D10: =收入成本拆分!D19/1000 -> 46230.954 | E10: =收入成本拆分!F19/1000 -> 17584.907 | F10: =收入成本拆分!H19/1000 -> 9888.2588 | G10: =收入成本拆分!J19/1000 -> 2951.9147
B11: GJ video production, livestreaming | C11: 硅基数字人视频、直播 | D11: =收入成本拆分!D20/1000 -> 7981.1702 | E11: =收入成本拆分!F20/1000 -> 8789.4208 | F11: =收入成本拆分!H20/1000 -> 8563.8367 | G11: =收入成本拆分!J20/1000 -> 8139.8702
B12: GJ Autopilot AIGC Agents | C12: 硅基全自动内容生产 | D12: 0 | E12: 0 | F12: 0 | G12: =收入成本拆分!J21/1000 -> 23151.796
B13: Total cost | C13: 成本合计 | D13: =SUM(D9:D12) -> 137280.14 | E13: =SUM(E9:E12) -> 287645.05 | F13: =SUM(F9:F12) -> 430359.22 | G13: =SUM(G9:G12) -> 516747.26
B15: Gross Margin | C15: 毛利率 | D15: 2022 | E15: 2023 | F15: 2024 | G15: 2025
B16: GJ digital human intelligent platform | C16: 硅基数字人智能交互（ICT+数字人智能产品） | D16: =(D2-D9)/D2 -> 0.40608017 | E16: =(E2-E9)/E2 -> 0.43208291 | F16: =(F2-F9)/F2 -> 0.32766981 | G16: =(G2-G9)/G2 -> 0.33251851
B17: GJ intelligent voice | C17: 硅基智能语音 | D17: =(D3-D10)/D3 -> 0.32757005 | E17: =(E3-E10)/E3 -> 0.3052815 | F17: =(F3-F10)/F3 -> 0.41101023 | G17: =(G3-G10)/G3 -> 0.25737157
B18: GJ video production, livestreaming | C18: 硅基数字人视频、直播 | D18: =(D4-D11)/D4 -> 0.43782616 | E18: =(E4-E11)/E4 -> 0.80658259 | F18: =(F4-F11)/F4 -> 0.67053621 | G18: =(G4-G11)/G4 -> 0.23088864
B19: GJ Autopilot AIGC Agents | C19: 硅基全自动内容生产 | G19: =(G5-G12)/G5 -> 0.54946831
B20: Gross margin% | C20: 毛利率 | D20: =(D6-D13)/D6 -> 0.38387754 | E20: =(E6-E13)/E6 -> 0.45809744 | F20: =(F6-F13)/F6 -> 0.34340185 | G20: =(G6-G13)/G6 -> 0.34490952
E22: 287645 | F22: 430359 | G22: 516747
E23: =E22-E13 -> -0.051423308 | F23: =F22-F13 -> -0.22178934 | G23: =G22-G13 -> -0.2645

Sheet 收入成本拆分
B3: 营业收入 | D3: 22年度 | F3: 23年度 | H3: 24年度 | J3: 25年度
D4: a | F4: b | H4: c | J4: d
B5: Customised AI workforce solutions | D5: =SUM(D6:D8) -> -2.086161e+08 | F5: =SUM(F6:F8) -> -4.853631e+08 | H5: =SUM(H6:H8) -> -6.2944451e+08 | J5: =SUM(J6:J10) -> -7.8881816e+08
B6: ICT services | D6: -37081816 | F6: -1.947907e+08 | H6: -4.2215234e+08 | J6: -3.2335846e+08
B7: AIGC services | D7: -1.0278221e+08 | F7: -2.6526012e+08 | H7: -1.9050367e+08 | J7: -3.9951355e+08
B8: AI voice services | D8: -68752074 | F8: -25312277 | H8: -16788507 | J8: -3974955.1
B9: Standardised and productized AI workforce solutions | D9: -14196979 | F9: -45442759 | H9: -25993256 | J9: -10583474
B10: GJ Autopilot AIGC Agents | J10: -51387720
B11: 合计 | D11: =SUM(D6:D9) -> -2.2281308e+08 | F11: =SUM(F6:F9) -> -5.3080586e+08 | H11: =SUM(H6:H9) -> -6.5543777e+08 | J11: =SUM(J6:J10) -> -7.8881816e+08
D12: =ROUND(D11-'[1]FY22-25630 IFRS（合并）'!G4,0) -> 0 | F12: =ROUND(F11-'[1]FY22-25630 IFRS（合并）'!I4,0) -> 0 | H12: =ROUND(H11-'[1]FY22-25630 IFRS（合并）'!K4,0) -> 0 | J12: =ROUND(J11-'[1]FY22-25 IFRS（合并）'!$AB$4,0) -> 0
B14: 营业成本
B16: Customised AI workforce solutions | D16: =D17+D18+D19 -> 1.2896516e+08 | F16: =F17+F18+F19 -> 2.7851244e+08 | H16: =H17+H18+H19 -> 4.2108509e+08 | J16: =J17+J18+J19 -> 4.8517689e+08
B17: ICT services | D17: =[1]PL2!E9 -> 27239174 | F17: =[1]PL2!I9 -> 1.3326885e+08 | H17: =[1]PL2!M9 -> 3.0115375e+08 | J17: 2.3036163e+08
B18: AIGC services | D18: =[1]PL2!E15 -> 55495031 | F18: =[1]PL2!I15 -> 1.2765868e+08 | H18: =[1]PL2!M15 -> 1.1004309e+08 | J18: =251772193.51-837866.44+1207721.07-278709.95 -> 2.5186334e+08
B19: AI voice services | D19: =[1]PL2!E31+[1]PL2!E35 -> 46230954 | F19: =[1]PL2!I31+[1]PL2!I35 -> 17584907 | H19: =[1]PL2!M31+[1]PL2!M35 -> 9888258.8 | J19: 2951914.7
B20: Standardised and productized AI workforce solutions | D20: =[1]PL2!E23 -> 7981170.2 | F20: =[1]PL2!I23 -> 8789420.8 | H20: =[1]PL2!M23 -> 8563836.7 | J20: 8139870.2
B21: GJ Autopilot AIGC Agents | D21: 0 | F21: 0 | J21: 23151796
B22: 合计 | D22: =SUM(D17:D21) -> 1.3694633e+08 | F22: =SUM(F17:F21) -> 2.8730186e+08 | H22: =SUM(H17:H21) -> 4.2964893e+08 | J22: =SUM(J17:J21) -> 5.1646855e+08
B24: 毛利 | D24: =-(-D11-D22)/D11 -> 0.38537572 | F24: =-(-F11-F22)/F11 -> 0.45874399 | H24: =-(-H11-H22)/H11 -> 0.34448555 | J24: =-(-J11-J22)/J11 -> 0.34526285
B26: Customised AI workforce solutions | D26: =-(-D5-D16)/D5 -> 0.38180631 | F26: =-(-F5-F16)/F5 -> 0.42617714 | H26: =-(-H5-H16)/H5 -> 0.3310211 | J26: =-(-J5-J16)/J5 -> 0.3849319
B27: ICT services | D27: =-(-D6-D17)/D6 -> 0.26543043 | F27: =-(-F6-F17)/F6 -> 0.31583568 | H27: =-(-H6-H17)/H6 -> 0.28662305 | J27: =-(-J6-J17)/J6 -> 0.28759669
B28: AIGC services | D28: =-(-D7-D18)/D7 -> 0.46007164 | F28: =-(-F7-F18)/F7 -> 0.51874151 | H28: =-(-H7-H18)/H7 -> 0.42235711 | J28: =-(-J7-J18)/J7 -> 0.36957498
B29: AI voice services | D29: =-(-D8-D19)/D8 -> 0.32757005 | F29: =-(-F8-F19)/F8 -> 0.3052815 | H29: =-(-H8-H19)/H8 -> 0.41101023 | J29: =-(-J8-J19)/J8 -> 0.25737157
B30: Standardised and productized AI workforce solutions | D30: =-(-D9-D20)/D9 -> 0.43782616 | F30: =-(-F9-F20)/F9 -> 0.80658259 | H30: =-(-H9-H20)/H9 -> 0.67053621 | J30: =-(-J9-J20)/J9 -> 0.23088864
B31: GJ Autopilot AIGC Agents | D31: n/a | F31: n/a | H31: n/a | J31: =-(-J10-J21)/J10 -> 0.54946831
B33: 税金及附加 | D33: 333814.56 | F33: 343189.27 | H33: 710292.53 | J33: 278709.95
D34: SPT | F34: ='[1]FY22-25 IFRS（合并）'!$J$5 -> 2.8764505e+08 | H34: ='[1]FY22-25 IFRS（合并）'!$L$5 -> 4.3035922e+08 | J34: ='[1]FY22-25 IFRS（合并）'!$AB$5 -> 5.1674726e+08
F35: =F22+F33 -> 2.8764505e+08 | H35: =H22+H33 -> 4.3035922e+08 | J35: =J22+J33 -> 5.1674726e+08
F36: =F35/1000 -> 287645.05 | G36: =G35/1000 -> 0 | H36: =H35/1000 -> 430359.22 | I36: =I35/1000 -> 0 | J36: =J35/1000 -> 516747.26

Sheet PL1
B3: 营业收入 | D3: 22年度 | F3: 23年度 | H3: 24年度 | J3: 25年度 | L3: 2024年1-6月 | N3: 2025年1-6月
D4: a | F4: b | H4: c | J4: d | L4: d1 | N4: d2
B5: Customised AI workforce solutions | D5: =SUM(D6:D8) -> -2.086161e+08 | F5: =SUM(F6:F8) -> -4.853631e+08 | H5: =SUM(H6:H8) -> -6.2944451e+08 | J5: =SUM(J6:J10) -> -7.8881816e+08 | L5: =SUM(L6:L8) -> -2.8004144e+08 | N5: =SUM(N6:N8) -> -3.1884501e+08
B6: ICT services | D6: -37081816 | F6: -1.947907e+08 | H6: -4.2215234e+08 | J6: -3.2335846e+08 | L6: -2.0269747e+08 | N6: -2.0980538e+08
B7: AIGC services | D7: -1.0278221e+08 | F7: -2.6526012e+08 | H7: -1.9050367e+08 | J7: -3.9951355e+08 | L7: -68796248 | N7: -1.070887e+08
B8: AI voice services | D8: -68752074 | F8: -25312277 | H8: -16788507 | J8: -3974955.1 | L8: -8547718 | N8: -1950936.2
B9: Standardised and productized AI workforce solutions | D9: -14196979 | F9: -45442759 | H9: -25993256 | J9: -10583474 | L9: -13070291 | N9: -6963475.6
B10: 全自动内容生产 | J10: -51387720
B11: 合计 | D11: =SUM(D6:D9) -> -2.2281308e+08 | F11: =SUM(F6:F9) -> -5.3080586e+08 | H11: =SUM(H6:H9) -> -6.5543777e+08 | J11: =SUM(J6:J10) -> -7.8881816e+08 | L11: =SUM(L6:L9) -> -2.9311173e+08 | N11: =SUM(N6:N9) -> -3.2580849e+08
D12: =ROUND(D11-'FY22-25 IFRS（合并）'!G4,0) -> 0 | F12: =ROUND(F11-'FY22-25 IFRS（合并）'!I4,0) -> 0 | H12: =ROUND(H11-'FY22-25 IFRS（合并）'!K4,0) -> 0 | J12: =ROUND(J11-'FY22-25 IFRS（合并）'!Q4,0) -> -236 | L12: =ROUND(L11-'FY22-25 IFRS（合并）'!M4,0) -> 0 | N12: =ROUND(N11-'FY22-25 IFRS（合并）'!O4,0) -> 0
B15: 收入地区 | D15: 22年度 | F15: 23年度 | H15: 24年度 | J15: 25年度 | L15: 2024年1-6月 | N15: 2025年1-6月
B17: 境内 | D17: -2.2281308e+08 | F17: -5.3080586e+08 | H17: -6.5543777e+08 | J17: =J11 -> -7.8881816e+08 | L17: -2.9311173e+08 | N17: -3.2580849e+08
B18: 境外 | D18: 0 | F18: 0 | H18: 0 | J18: 0 | L18: 0 | N18: 0
B20: 合计 | D20: =SUM(D17:D18) -> -2.2281308e+08 | F20: =SUM(F17:F18) -> -5.3080586e+08 | H20: =SUM(H17:H18) -> -6.5543777e+08 | J20: =SUM(J17:J18) -> -7.8881816e+08 | L20: =SUM(L17:L18) -> -2.9311173e+08 | N20: =SUM(N17:N18) -> -3.2580849e+08
D21: =ROUND(D20-'FY22-25 IFRS（合并）'!G4,0) -> 0 | F21: =ROUND(F20-'FY22-25 IFRS（合并）'!I4,0) -> 0 | H21: =ROUND(H20-'FY22-25 IFRS（合并）'!K4,0) -> 0 | J21: =ROUND(J20-'[1]FY22-25 IFRS（合并）'!$AB$4,0) -> 0 | L21: =ROUND(L20-'FY22-25 IFRS（合并）'!M4,0) -> 0 | N21: =ROUND(N20-#REF!,0) -> #REF!
B24: 收入来源 | D24: 22年度 | F24: 23年度 | H24: 24年度 | J24: 25年度 | L24: 2024年1-6月 | N24: 2025年1-6月
B26: 独立第三方
B27: 控股股东及其联系人
B28: 其他关联方
B30: 合计 | D30: =SUM(D25:D28) -> 0 | F30: =SUM(F25:F28) -> 0 | H30: =SUM(H25:H28) -> 0 | J30: =SUM(J25:J28) -> 0 | L30: =SUM(L25:L28) -> 0 | N30: =SUM(N25:N28) -> 0
B33: 客户类型 | D33: 22年度 | F33: 23年度 | H33: 24年度 | J33: 25年度 | L33: 2024年1-6月 | N33: 2025年1-6月
B35: 国企
B36: 非国企
B38: 合计 | D38: =SUM(D34:D36) -> 0 | F38: =SUM(F34:F36) -> 0 | H38: =SUM(H34:H36) -> 0 | J38: =SUM(J34:J36) -> 0 | L38: =SUM(L34:L36) -> 0 | N38: =SUM(N34:N36) -> 0
B40: 收入地区 | D40: 22年度 | F40: 23年度 | H40: 24年度 | J40: 25年度 | L40: 2024年1-6月 | N40: 2025年1-6月
B42: 华东
B43: 华南
B44: xxx
B46: 合计 | D46: =SUM(D41:D43) -> 0 | F46: =SUM(F41:F43) -> 0 | H46: =SUM(H41:H43) -> 0 | J46: =SUM(J41:J43) -> 0 | L46: =SUM(L41:L43) -> 0 | N46: =SUM(N41:N43) -> 0

Sheet 附 收入by客商
D1: =SUM(D3:D2218)+'FY22-25 IFRS（合并）'!G4 -> 0.64094365 | E1: =SUM(E3:E2218)+'FY22-25 IFRS（合并）'!I4 -> 0.13584453 | F1: =SUM(F3:F2218)+'FY22-25 IFRS（合并）'!K4 -> -9.2952838 | G1: =SUM(G3:G2218)+'FY22-25 IFRS（合并）'!Q4 -> 235.85321
B2: 客户名称 | C2: 合并客户名称 | D2: 2022年 | E2: 2023年 | F2: 2024年 | G2: 2025年 | H2: 2025年H1
B3: 中移建设有限公司江苏分公司 | C3: 中国移动通信有限公司 | D3: 0 | E3: 18232458 | F3: 79186060 | G3: 72540462 | H3: 58710255
B4: 中移建设有限公司南京分公司 | C4: 中国移动通信有限公司 | D4: 0 | E4: 406784.14 | F4: 48031472 | G4: 37809940 | H4: 28842016
B5: 嘉环科技股份有限公司 | C5: 嘉环科技股份有限公司 | G5: 27322508 | H5: 27322508
B6: 中移建设有限公司无锡分公司 | C6: 中国移动通信有限公司 | D6: 1960377.4 | E6: 59068021 | F6: 32463211 | G6: 40190109 | H6: 27954531
B7: 广州和联通信科技有限公司 | C7: 广州和联通信科技有限公司 | G7: 16664604 | H7: 16664604
B8: 中移铁通有限公司连云港分公司 | C8: 中国移动通信有限公司 | D8: 0 | E8: 26635473 | F8: 36644440 | G8: 16522641 | H8: 16522642
B9: 富康尼科技（泰州）有限公司 | C9: 富康尼科技（泰州）有限公司 | F9: 5167482.8 | G9: 27011581 | H9: 15819077
B10: 江苏磬石软件科技有限公司 | C10: 江苏磬石软件科技有限公司 | F10: 23170359 | G10: 20471733 | H10: 13995775
B11: 中移铁通有限公司徐州分公司 | C11: 中国移动通信有限公司 | F11: 12724993 | G11: 13738295 | H11: 13738295
B12: 中移建设有限公司苏州分公司 | C12: 中国移动通信有限公司 | F12: 56415094 | G12: 38468396 | H12: 11311321
B13: 中移铁通有限公司盐城分公司 | C13: 中国移动通信有限公司 | D13: 22377659 | E13: 18458625 | F13: 3960472.3 | G13: 12613212 | H13: 10830708
B14: 中移建设有限公司南通分公司 | C14: 中国移动通信有限公司 | F14: 53326065 | G14: 14218185 | H14: 9521188.7
B15: 中国移动通信集团江苏有限公司徐州分公司 | C15: 中国移动通信有限公司 | F15: 9797169.8 | G15: 7948113.2 | H15: 7948113.2
B16: 中移建设有限公司徐州分公司 | C16: 中国移动通信有限公司 | G16: 6213490.6 | H16: 6213490.6
B17: 中国移动通信集团江苏有限公司无锡分公司 | C17: 中国移动通信有限公司 | G17: 7941914.2 | H17: 6138735.8
B18: 联想（北京）信息技术有限公司 | C18: 联想（北京）有限公司 | F18: 11325225 | G18: 9254625 | H18: 6029100
B19: 中移铁通有限公司无锡分公司 | C19: 中国移动通信有限公司 | D19: 389905.66 | E19: 24214283 | F19: 8306886.8 | G19: 12487929 | H19: 4440094.3
B20: 无锡银通软件科技有限公司 | C20: 无锡银通软件科技有限公司 | E20: 2523584.9 | F20: 3136792.5 | G20: 4273584.9 | H20: 4273584.9
B21: 江苏赞奇科技股份有限公司 | C21: 江苏赞奇科技股份有限公司 | F21: 3883018.9 | G21: 3584905.7 | H21: 3584905.7
B22: 联想（北京）有限公司 | C22: 联想（北京）有限公司 | E22: 2174000 | F22: 7327070 | G22: 9439500 | H22: 9439500
B23: 杭州聚昂科技有限公司 | C23: 杭州聚昂科技有限公司 | G23: 2830188.7 | H23: 2830188.7
B24: 中国移动通信集团江苏有限公司常州分公司 | C24: 中国移动通信有限公司 | D24: 0 | E24: 8154785.5 | F24: 34187830 | G24: 2735849 | H24: 2735849.1
B25: 中国移动通信集团江苏有限公司南京分公司 | C25: 中国移动通信有限公司 | G25: 2735849 | H25: 2735849.1
B26: 中移铁通有限公司南通分公司 | C26: 中国移动通信有限公司 | D26: 0 | E26: 1966199.8 | F26: 0 | G26: 2990579.3 | H26: 2990579.2
B27: 南京信非技术有限公司 | C27: 南京信非技术有限公司 | F27: 10601368 | G27: 19418653 | H27: 1976382.4
B28: 江苏蓝色云湾数字科技有限公司 | C28: 江苏蓝色云湾数字科技有限公司 | G28: 1698490.6 | H28: 1698490.6
B29: 南通领讯信息技术有限公司 | C29: 南通领讯信息技术有限公司 | G29: 1132075.5 | H29: 1132075.5
B30: 其他零售 | C30: 个人 | D30: 2050029.9 | E30: 6153032.2 | F30: 2117004.4 | G30: 1251501 | H30: 944851.15
B31: 中信银行股份有限公司 | C31: 中信银行股份有限公司 | D31: 1335849.1 | E31: 13547.14 | F31: 1417754.7 | G31: 1256150.9 | H31: 858452.83
B32: 苏州吉天信息技术有限公司 | C32: 苏州吉天信息技术有限公司 | G32: 665070.75 | H32: 665070.75
B33: 溧阳市栗里文旅投资发展有限公司 | C33: 溧阳市栗里文旅投资发展有限公司 | G33: 542915.34 | H33: 555094.33
B34: 南京银行股份有限公司 | C34: 南京银行股份有限公司 | D34: 2828573.2 | E34: 1955526.8 | F34: 491528.29 | G34: 678301.89 | H34: 542452.84
B35: 厦门市美亚柏科信息安全研究所有限公司 | C35: 厦门市美亚柏科信息安全研究所有限公司 | F35: 130575.22 | G35: 444646.02 | H35: 444646.02
B36: 中国中金财富证券有限公司 | C36: 中国中金财富证券有限公司 | E36: 56132.08 | F36: 43396.22 | G36: 820905 | H36: 410452.5
B37: 北京粉笔上岸科技有限公司 | C37: 北京粉笔上岸科技有限公司 | F37: 16981.13 | G37: 405660.37 | H37: 405660.37
B38: 华为云计算技术有限公司 | C38: 华为技术有限公司 | D38: 2338206.1 | E38: 4391701.3 | F38: 4477077 | G38: 560872.8 | H38: 270432.23
B39: 陕西星辰智创科技有限公司 | C39: 陕西星辰智创科技有限公司 | F39: 9433.96 | G39: 266666.96 | H39: 227987.72
B40: 武汉木子柒广告有限公司 | C40: 武汉木子柒广告有限公司 | E40: 77017.03 | F40: 30260.38 | G40: 193701.89 | H40: 193701.89
...

Sheet contract liability
B1: Contract liability
B2: The Group | C2: As at 31 December | M2: End | O2: The Company | P2: As at 31 December
C3: 2022 | E3: 2023 | G3: 2024 | P3: 2022 | R3: 2023 | T3: 2024
C4: RMB’000 | E4: RMB’000 | G4: RMB’000 | P4: RMB’000 | R4: RMB’000 | T4: RMB’000
B6: Balance at the beginning of the year | C6: 0 | E6: 3139 | G6: 41127 | O6: Balance at the beginning of the year | P6: 0 | R6: 3139 | T6: 36207
B7: Decrease in contract liabilities as a result of recognizing revenue during the year that was included in the contract liabilities at the beginning of the year | C7: -7138 | E7: -43704 | G7: -108809 | O7: Decrease in contract liabilities as a result of recognizing revenue during the year that was included in the contract liabilities at the beginning of the year | P7: -1729 | R7: -43704 | T7: -108809
B8: Increase in contract liabilities as a result of receiving advance payments during the year | C8: 10465 | E8: 81692 | G8: 117435 | O8: Increase in contract liabilities as a result of receiving advance payments during the year | P8: -3398 | R8: 76772 | T8: 114439
B10: Balance at the end of the year | C10: =ROUND(SUM(C6:C9)/1.06,0) -> 3139 | E10: 41127 | G10: =SUM(G6:G9) -> 49753 | O10: Balance at the end of the year | P10: =SUM(P6:P9) -> -5127 | R10: =SUM(R6:R9) -> 36207 | T10: =SUM(T6:T9) -> 41837
O11: End
B16: Contract liability
B17: The Group | C17: As at 31 December | K17: As at 30 June | M17: End | O17: The Company | P17: As at 31 December | V17: As at 30 June
C18: 2022 | E18: 2023 | G18: 2024 | I18: 2025 | K18: 2025 | O18: 南京硅基 | P18: 2022 | R18: 2023 | T18: 2024 | V18: 2025
C19: RMB’000 | E19: RMB’000 | G19: RMB’000 | I19: RMB’000 | K19: RMB’000 | P19: RMB’000 | R19: RMB’000 | T19: RMB’000 | V19: RMB’000
A21: A | B21: Balance at the beginning of the year | C21: 6339661.7 | E21: 6804807.3 | G21: 46497256 | I21: 50236540 | K21: 50236540 | O21: Balance at the beginning of the year | P21: 1961479 | R21: 6804807.3 | T21: 41577312 | V21: 42298948
A22: B | B22: Decrease in contract liabilities as a result of recognizing revenue during the year that was included in the contract liabilities at the beginning of the year | C22: -6339661.7 | E22: -3243364.9 | G22: -33496871 | I22: -34671804 | K22: -33748518 | O22: Decrease in contract liabilities as a result of recognizing revenue during the year that was included in the contract liabilities at the beginning of the year | P22: -1961479 | R22: -3243364.9 | T22: -30860203 | V22: -32288646
A23: C | B23: Increase in contract liabilities as a result of receiving advance payments during the year | C23: 25192450 | E23: 1.3510211e+08 | G23: 1.5239679e+08 | I23: 1.4774352e+08 | K23: 44080148 | O23: Increase in contract liabilities as a result of receiving advance payments during the year | P23: 27497312 | R23: 1.2410581e+08 | T23: 1.3104298e+08 | V23: 39500708
A24: D | B24: Decrease in contract liabilities as a result of recognising revenue during the same year | C24: -18387643 | E24: -92166298 | G24: -1.1516063e+08 | I24: -87733993 | K24: -40537263 | P24: -20692505 | R24: -86089937 | T24: -99461143 | V24: -38044521
I25: 0
A26: E | B26: Balance at the end of the year | C26: 6804807.3 | E26: 46497256 | G26: 50236540 | I26: 75574267 | K26: 20030907 | O26: Balance at the end of the year | P26: 6804807.3 | R26: 41577312 | T26: 42298948 | V26: 11466489
O27: End
A30: A | B30: 运营商一体化改造 | C30: 0 | E30: 2829686.3 | G30: 20468113 | I30: 2830487.5 | K30: 2830487.5 | N30: A | O30: 运营商一体化改造 | P30: 0 | R30: 2829686.3 | T30: 20468113 | V30: 2830487.5 | Y30: by 收入板块movement
A31: A | B31: SaaS | C31: 6339661.7 | E31: 3975121 | G31: 26029143 | I31: 19917016 | K31: 19917016 | N31: A | O31: SaaS | P31: 1961479 | R31: 3975121 | T31: 21109200 | V31: 11979424
A32: A | B32: 数字人智能服务产品 | C32: 0 | E32: 0 | G32: 0 | I32: 27489036 | K32: 27489036 | N32: A | O32: 数字人智能服务产品 | P32: 0 | R32: 0 | T32: 0 | V32: 27489036 | Y32: SaaS | Z32: 2022 | AB32: 2023 | AD32: 2024 | AF32: 20250630
A33: A | B33: 全自动内容生产
Y34: 期初余额 | Z34: 6339661.7 | AB34: 3975121 | AD34: 26029143 | AF34: 19917016
A35: B | B35: 运营商一体化改造 | C35: 0 | E35: -2829686.3 | G35: -20468113 | I35: -2830487.5 | K35: -2830487.5 | N35: B | O35: 运营商一体化改造 | P35: 0 | R35: -2829686.3 | T35: -20468113 | V35: -2830487.5 | Y35: 往年预收本年确认收入 | Z35: -6339661.7 | AB35: -413678.59 | AD35: -13028759 | AF35: -3428994
A36: B | B36: SaaS | C36: -6339661.7 | E36: -413678.59 | G36: -13028759 | I36: -4352280.6 | K36: -3428994 | N36: B | O36: SaaS | P36: -1961479 | R36: -413678.59 | T36: -10392090 | V36: -1969122.4 | Y36: 本年新增 | Z36: 14910830 | AB36: 70223347 | AD36: 28265927 | AF36: 6477348.7
A37: B | B37: 数字人智能服务产品 | C37: 0 | E37: 0 | G37: 0 | I37: -27489036 | K37: -27489036 | N37: B | O37: 数字人智能服务产品 | P37: 0 | R37: 0 | T37: 0 | V37: -27489036 | Y37: 当年预收当年确认收入 | Z37: -10935709 | AB37: -47755646 | AD37: -21349295 | AF37: -3952290.1
A38: B | B38: 全自动内容生产
Y39: 期末余额 | Z39: 3975121 | AB39: 26029143 | AD39: 19917016 | AF39: 19013081
A40: C | B40: 运营商一体化改造 | C40: 10281620 | E40: 64878765 | G40: 96641824 | I40: 63100330 | K40: 37602799 | N40: C | O40: 运营商一体化改造 | P40: 10281620 | R40: 64878765 | T40: 96641824 | V40: 37602799 | Y40: 当年收入金额 | Z40: 17275370 | AB40: 48169325 | AD40: 34378054 | AF40: 7381284.1
A41: C | B41: SaaS | C41: 14910830 | E41: 70223347 | G41: 28265927 | I41: 8373593.3 | K41: 6477348.7 | N41: C | O41: SaaS | P41: 17215692 | R41: 59227043 | T41: 6912121 | V41: 1897908.4 | Z41: =Z40+Z37+Z35 -> 0.0039998991 | AB41: =AB40+AB37+AB35 -> -0.0017998034 | AD41: =AD40+AD37+AD35 -> -0.091599897 | AF41: =AF40+AF37+AF35 -> -0.0034000003
A42: C | B42: 数字人智能服务产品 | C42: 0 | E42: 0 | G42: 27489036 | I42: 65000000 | K42: 0 | N42: C | O42: 数字人智能服务产品 | P42: 0 | R42: 0 | T42: 27489036 | V42: 0
A43: C | B43: 全自动内容生产 | I43: 11269600
Y44: ICT | Z44: 2022 | AB44: 2023 | AD44: 2024 | AF44: 20250630
A45: D | B45: 运营商一体化改造 | C45: -7451934 | E45: -44410652 | G45: -93811337 | I45: -55613282 | K45: -36584973 | N45: D | O45: 运营商一体化改造 | P45: -7451934 | R45: -44410652 | T45: -93811337 | V45: -36584973 | Y45: 期初余额 | Z45: 0 | AB45: 2829686.3 | AD45: 20468113 | AF45: 2830487.5
A46: D | B46: SaaS | C46: -10935709 | E46: -47755646 | G46: -21349295 | I46: -6866202 | K46: -3952290.1 | N46: D | O46: SaaS | P46: -13240571 | R46: -41679285 | T46: -5649806.1 | V46: -1459547.4 | Y46: 往年预收本年确认收入 | Z46: 0 | AB46: -2829686.3 | AD46: -20468113 | AF46: -2830487.5
A47: D | B47: 数字人智能服务产品 | C47: 0 | E47: 0 | G47: 0 | I47: -18131701 | N47: D | O47: 数字人智能服务产品 | P47: 0 | R47: 0 | T47: 0 | Y47: 本年新增 | Z47: 10281620 | AB47: 64878765 | AD47: 96641824 | AF47: 37602799
A48: D | B48: 全自动内容生产 | I48: -7122807.5
Y49: 当年预收当年确认收入 | Z49: -7451934 | AB49: -44410652 | AD49: -93811337 | AF49: -36584973
...

Sheet PL2
C6: 2022 | E6: 2022 | G6: 2023 | I6: 2023 | K6: 2024 | M6: 2024 | O6: 2025 | Q6: 2025 | S6: 202406 | U6: 202406 | W6: 202506 | Y6: 202506
B7: 对应收入类型 | C7: 账面金额 | D7: 调整金额 | E7: 审定金额 | F7: 占比 | G7: 账面金额 | H7: 调整金额 | I7: 审定金额 | J7: 占比 | K7: 账面金额 | L7: 调整金额 | M7: 审定金额 | N7: 占比 | O7: 账面金额 | P7: 调整金额 | Q7: 审定金额 | R7: 占比 | S7: 账面金额 | T7: 调整金额 | U7: 审定金额 | V7: 占比 | W7: 账面金额 | X7: 调整金额 | Y7: 审定金额 | Z7: 占比
A9: ICT services | B9: 运营商一体化改造 | C9: 74497340 | D9: -47258167 | E9: =SUM(E10:E13) -> 27239174 | G9: 1.4411145e+08 | H9: -10842596 | I9: =SUM(I10:I13) -> 1.3326885e+08 | K9: 2.6579023e+08 | L9: 35363513 | M9: =SUM(M10:M13) -> 3.0115375e+08 | O9: =SUM(O10:O13) -> 2.3036163e+08 | P9: =SUM(P10:P13) -> 0 | Q9: =SUM(Q10:Q13) -> 2.3036163e+08 | S9: 95318080 | T9: 48498110 | U9: =SUM(U10:U13) -> 1.4381619e+08 | W9: 1.5361374e+08 | X9: -2272615.1 | Y9: =SUM(Y10:Y13) -> 1.5134113e+08
B10: 运营商项目实施费用 | C10: 74497340 | D10: -47258167 | E10: 27239174 | F10: 1 | G10: 1.4411145e+08 | H10: -10835596 | I10: 1.3327585e+08 | J10: 1.0000525 | K10: 2.6546735e+08 | L10: 35479202 | M10: 3.0094656e+08 | N10: 1.0000525 | O10: 2.2824551e+08 | Q10: 2.2824551e+08 | R10: 0.99931201 | S10: 95247306 | T10: 48600322 | U10: 1.4384763e+08 | V10: 1.0002186 | W10: 1.5361374e+08 | X10: -1177097.8 | Y10: 1.5243665e+08 | Z10: 1.0072387
B11: 人工成本 | C11: 0 | D11: 0 | E11: 0 | G11: 0 | H11: -7000 | I11: -7000 | K11: 0 | L11: 0 | M11: 0 | O11: 0 | Q11: 0 | R11: 0 | S11: 0 | T11: 0 | U11: 0 | V11: 0 | W11: 0 | X11: 0 | Y11: 0
B12: 硬件采购 | C12: 0 | D12: 0 | E12: 0 | G12: 0 | H12: 0 | I12: 0 | K12: 322879.15 | L12: 0 | M12: 322879.15 | O12: 2116130 | Q12: 2116130 | R12: 0.0010721406 | S12: 70774.36 | T12: -102212.37 | U12: -31438.01 | V12: -0.00021859855 | W12: 0 | X12: -1095517.2 | Y12: -1095517.2
B13: 其他 | C13: 0 | D13: 0 | E13: 0 | G13: 0 | H13: 0 | I13: 0 | K13: 0 | L13: -115688.6 | M13: -115688.6 | O13: 0 | P13: 0 | Q13: 0 | R13: -0.00038415129 | S13: 0 | T13: 0 | U13: 0 | V13: 0 | W13: 0 | X13: 0 | Y13: 0
A15: AIGC services | B15: 数字人智能服务产品 | C15: 1.1077918e+08 | D15: -55284146 | E15: =SUM(E16:E20) -> 55495031 | G15: 1.811597e+08 | H15: -53501019 | I15: =SUM(I16:I20) -> 1.2765868e+08 | K15: 1.1539481e+08 | L15: -5351726.5 | M15: =SUM(M16:M20) -> 1.1004309e+08 | O15: =SUM(O16:O20) -> 2.5093433e+08 | P15: =SUM(P16:P20) -> 0 | Q15: =SUM(Q16:Q20) -> 2.5093433e+08 | S15: 56968190 | T15: -16498488 | U15: =SUM(U16:U20) -> 40469702 | W15: 65660287 | X15: 266655.09 | Y15: =SUM(Y16:Y20) -> 65926942
B16: 项目实施费用 | C16: 15790734 | D16: -2695000 | E16: 13095734 | F16: 0.2359803 | G16: 12737277 | H16: 1745061.9 | I16: 14482339 | J16: 0.11337891 | K16: 32369471 | L16: -3204207.7 | M16: 29165263 | N16: 0.11337891 | O16: 23583614 | Q16: 23583614 | R16: 0.43923503 | S16: 5267185.6 | T16: -196415.1 | U16: 5070770.5 | V16: 0.12529795 | W16: 16467307 | X16: 595504.65 | Y16: 17062812 | Z16: 0.25881394
B17: 云服务费用 | C17: 93706524 | D17: -53319937 | E17: 40386587 | F17: 0.7277514 | G17: 1.6068935e+08 | H17: -55170788 | I17: 1.0551856e+08 | J17: 0.82608058 | K17: 75655807 | L17: -2086863.6 | M17: 73568944 | N17: 0.82608058 | O17: 46225834 | Q17: 46225834 | R17: 0.21912348 | S17: 47350711 | T17: -17132997 | U17: 30217714 | V17: 0.74667498 | W17: 30366003 | X17: 0 | Y17: 30366003 | Z17: 0.46060081
B18: 硬件采购 | C18: 1269919.3 | D18: 730790.95 | E18: 2000710.2 | F18: 0.036052061 | G18: 7733079.9 | H18: -75292.57 | I18: 7657787.3 | J18: 0.060540508 | K18: 7369536.1 | L18: -28407.06 | M18: 7341129.1 | N18: 0.060540508 | O18: 41762086 | Q18: 41762086 | R18: 0.17317123 | S18: 4214557.2 | T18: 0.010707965 | U18: 4214557.2 | V18: 0.10414105 | W18: 18826977 | X18: -328849.56 | Y18: 18498128 | Z18: 0.28058526
B19: 其他 | C19: 12000 | D19: 0 | E19: 12000 | F19: 0.00021623558 | G19: 0 | H19: 0 | I19: 0 | J19: 0 | K19: 0 | L19: -32248.08 | M19: -32248.08 | N19: 0 | Q19: 0 | R19: 0 | S19: 0 | T19: 966660.12 | U19: 966660.12 | V19: 0.02388602 | W19: 0 | X19: 0 | Y19: 0 | Z19: 0
B20: 软硬件产品 | O20: 1.3936279e+08 | Q20: 1.3936279e+08 | R20: 0.16847026
A22: AI application layer products | B22: 数字人产品SaaS | C22: 7981170.2 | D22: 0 | E22: =SUM(E24:E28) -> 7981170.2 | G22: 48404515 | H22: -39615094 | I22: =SUM(I24:I28) -> 8789420.8 | K22: 8563836.7 | L22: 0 | M22: =SUM(M24:M28) -> 8563836.7 | O22: =SUM(O24:O29) -> 8139870.2 | P22: =SUM(P24:P29) -> 0 | Q22: =SUM(Q24:Q28) -> 8139870.2 | S22: 4380318.5 | T22: -97222.284 | U22: =SUM(U24:U28) -> 4283096.3 | W22: 4582074.3 | X22: 78726.05 | Y22: =SUM(Y24:Y28) -> 4660800.3
B23: 数字人产品一体机 | C23: 0 | D23: 0 | E23: 0 | G23: 0 | H23: 0 | I23: 0 | K23: 0 | L23: 0 | M23: 0 | O23: 0 | P23: 0 | Q23: 0 | S23: 0 | T23: 0 | U23: 0 | W23: 0 | X23: 0 | Y23: 0
B24: 人工成本 | C24: 4503114.1 | D24: 0 | E24: 4503114.1 | F24: 0.56421728 | G24: 3798654.8 | H24: 0 | I24: 3798654.8 | J24: 0.43218488 | K24: 0 | L24: 0 | M24: 0 | N24: 0.43218488 | O24: 0 | P24: 0 | Q24: 0 | R24: 0 | S24: 0 | T24: 0 | U24: 0 | V24: 0 | W24: 0 | X24: 0 | Y24: 0 | Z24: 0
B25: 云服务费用 | C25: 2840146.7 | D25: 0 | E25: 2840146.7 | F25: 0.35585592 | G25: 44463742 | H25: -39615094 | I25: 4848647.5 | J25: 0.55164585 | K25: 8563836.7 | L25: 0 | M25: 8563836.7 | N25: 0.55164585 | O25: 8139870.2 | P25: 0 | Q25: 8139870.2 | R25: 1 | S25: 4380318.5 | T25: -97222.284 | U25: 4283096.3 | V25: 1 | W25: 4582074.3 | X25: 78726.05 | Y25: 4660800.3 | Z25: 1
B26: 其他 | C26: 637909.4 | D26: 0 | E26: 637909.4 | F26: 0.079926801 | G26: 142118.58 | H26: 0 | I26: 142118.58 | J26: 0.016169277 | K26: 0 | L26: 0 | M26: 0 | N26: 0.016169277 | O26: 0 | P26: 0 | Q26: 0 | R26: 0 | S26: 0 | T26: 0 | U26: 0 | V26: 0 | W26: 0 | X26: 0 | Y26: 0 | Z26: 0
B27: 项目实施费用 | C27: 0 | D27: 0 | E27: 0 | F27: 0 | G27: 0 | H27: 0 | I27: 0 | J27: 0 | K27: 0 | L27: 0 | M27: 0 | N27: 0 | O27: 0 | P27: 0 | Q27: 0 | R27: 0 | S27: 0 | T27: 0 | U27: 0 | V27: 0 | W27: 0 | X27: 0 | Y27: 0 | Z27: 0
B28: 硬件采购 | O28: 0 | P28: 0 | W28: 0 | X28: 0 | Y28: 0 | Z28: 0
A30: AI voice services | B30: 智能协呼机器人SaaS | C30: 6241119.7 | D30: -64555.34 | E30: =SUM(E31:E32) -> 6176564.3 | G30: 1962686.3 | H30: 1273805.1 | I30: =SUM(I31:I32) -> 3236491.3 | K30: 5556.89 | L30: 0 | M30: =SUM(M31:M32) -> 5556.89 | O30: 0 | P30: 0 | Q30: =SUM(Q31:Q32) -> 0 | S30: 5556.89 | T30: 0 | U30: =SUM(U31:U32) -> 5556.89 | W30: 0 | X30: 0 | Y30: =SUM(Y31:Y32) -> 0
B31: 项目实施费用 | C31: 0 | D31: 0 | E31: 0 | F31: 0 | G31: 80875.47 | H31: 0 | I31: 80875.47 | J31: 0.024988626 | K31: 0 | L31: 0 | M31: 0 | N31: 0.024988626 | R31: 0 | S31: 0 | T31: 0 | U31: 0 | V31: 0 | W31: 0 | X31: 0 | Y31: 0 | Z31: N/A
A32: 线路费用 | B32: 其他 | C32: 6241119.7 | D32: -64555.34 | E32: 6176564.3 | F32: 1 | G32: 1881810.8 | H32: 1273805.1 | I32: 3155615.9 | J32: 0.97501137 | K32: 5556.89 | L32: 0 | M32: 5556.89 | N32: 0.97501137 | R32: 0 | S32: 5556.89 | T32: 0 | U32: 5556.89 | V32: 1 | W32: 0 | X32: 0 | Y32: 0 | Z32: N/A
A34: AI voice services | B34: 智能外呼服务 | C34: 46542283 | D34: -6487893.3 | E34: =SUM(E35:E39) -> 40054390 | G34: 14504003 | H34: -155587.66 | I34: =SUM(I35:I39) -> 14348416 | K34: 7286027.2 | L34: 2596674.7 | M34: =SUM(M35:M39) -> 9882701.9 | O34: =SUM(O35:O39) -> 2951914.7 | P34: =SUM(P35:P39) -> 0 | Q34: =SUM(Q35:Q39) -> 2951914.7 | S34: 1018665.8 | T34: 2596674.7 | U34: =SUM(U35:U39) -> 3615340.5 | W34: 833973.55 | X34: 135285 | Y34: =SUM(Y35:Y39) -> 1087336.2
B35: 项目实施费用 | C35: 11471668 | D35: 0 | E35: 11471668 | F35: 0.28640226 | G35: 14386512 | H35: -155587.66 | I35: 14230925 | J35: 0.99181156 | K35: 4645006 | L35: 0 | M35: 4645006 | N35: 0.99181156 | O35: 2951914.7 | Q35: 2951914.7 | R35: 1.0418396 | S35: 454210.64 | T35: 0 | U35: 454210.64 | V35: 0.12563426 | W35: 951820.28 | X35: 135285 | Y35: 1087105.2 | Z35: 1.1215844
B36: 云服务费用 | C36: 24192453 | D36: -3891218.6 | E36: 20301234 | F36: 0.50684167 | G36: 0 | H36: 0 | I36: 0 | J36: 0 | K36: 2076566 | L36: 0 | M36: 2076566 | N36: 0 | O36: 0 | Q36: 0 | R36: 0 | S36: 0 | T36: 0 | U36: 0 | V36: 0 | W36: 0 | X36: 0 | Y36: 0 | Z36: 0
B37: 硬件采购 | C37: 2697602.2 | D37: -2596674.7 | E37: 100927.44 | F37: 0.0025197598 | G37: 117491.15 | H37: 0 | I37: 117491.15 | J37: 0.0081884406 | K37: 52991.15 | L37: 2596674.7 | M37: 2649665.9 | N37: 0.0081884406 | O37: 0 | Q37: 0 | R37: 0 | S37: 52991.15 | T37: 2596674.7 | U37: 2649665.9 | V37: 0.73289525 | W37: 0 | X37: 0 | Y37: 0 | Z37: 0
B38: 人工成本 | C38: 5334744.8 | D38: 0 | E38: 5334744.8 | F38: 0.13318752 | G38: 0 | H38: 0 | I38: 0 | J38: 0 | K38: 505375.05 | L38: 0 | M38: 505375.05 | N38: 0 | O38: 0 | Q38: 0 | R38: 0 | S38: 505375.05 | T38: 0 | U38: 505375.05 | V38: 0.13978629 | W38: 0 | X38: 0 | Y38: 0 | Z38: 0
B39: 其他 | C39: 2845815.8 | D39: 0 | E39: 2845815.8 | F39: 0.071048786 | G39: 0 | H39: 0 | I39: 0 | J39: 0 | K39: 6088.93 | L39: 0 | M39: 6088.93 | N39: 0 | R39: -0.041839625 | S39: 6088.93 | T39: 0 | U39: 6088.93 | V39: 0.0016841927 | W39: -117846.73 | X39: 0 | Y39: 230.94 | Z39: -0.032596302
B40: 全自动内容生产 | E40: =SUM(E41:E43) -> 0 | I40: =SUM(I41:I43) -> 0 | M40: =SUM(M41:M43) -> 0 | O40: 23151796 | Q40: =SUM(Q41:Q43) -> 23151796 | U40: =SUM(U41:U43) -> 0 | Y40: =SUM(Y41:Y43) -> 0
B41: 项目实施费用 | O41: 4358367.6 | Q41: 4358367.6
B42: 云服务费用 | O42: 18717886 | Q42: 18717886
B43: 其他 | O43: 75542.68 | Q43: 75542.68
B45: 税金及附加 | C45: 6625204.4 | D45: -6625204.4 | G45: 35900825 | H45: -35900825 | K45: 40165321 | L45: -40165321 | M45: 0 | O45: 44572019 | P45: -44572019 | Q45: 0 | S45: 11180775 | T45: -11180775 | U45: 0 | W45: 20054459 | X45: -20054459 | Y45: 0
C46: 2.5266629e+08 | D46: -1.1571997e+08 | E46: =E9+E15+E22+E30+E34+E40+E45 -> 1.3694633e+08 | G46: 4.2604318e+08 | H46: -1.3874132e+08 | I46: =I9+I15+I22+I30+I34+I40 -> 2.8730186e+08 | K46: 4.3720579e+08 | L46: -7556860.1 | M46: =M9+M15+M22+M30+M34+M40 -> 4.2964893e+08 | O46: =O45+O40+O34+O22+O15+O9 -> 5.6011156e+08 | P46: =P45+P40+P34+P22+P15+P9 -> -44572019 | Q46: =Q9+Q15+Q22+Q30+Q34+Q40 -> 5.1553954e+08 | S46: 1.6887159e+08 | T46: 23318298 | U46: =U9+U15+U22+U30+U34+U40 -> 1.9218989e+08 | W46: 2.4474454e+08 | X46: -21846408 | Y46: =Y9+Y15+Y22+Y30+Y34+Y40 -> 2.2301621e+08
E47: =E46-'FY22-25 IFRS（合并）'!G5 -> -63994.13 | I47: =I46-'FY22-25 IFRS（合并）'!I5 -> -343189.27 | M47: =M46-'FY22-25 IFRS（合并）'!K5 -> -710292.53 | Q47: =Q46-'FY22-25 IFRS（合并）'!Q5 -> -1207721.1 | U47: =U46-'FY22-25 IFRS（合并）'!M5 -> -194936.36 | Y47: =Y46-'FY22-25 IFRS（合并）'!O5 -> 117846.73
U49: 请KP确认
E50: 2023 | M50: 2024 | U50: 2025
B51: Project fulfillment costs | E51: RMB’000 | F51: % | M51: RMB’000 | N51: % | U51: RMB’000 | V51: %
B52: Cost of cloud services | E52: 162070 | F52: =E52/$E$57 -> 0.56343757 | M52: 334621 | N52: =M52/$M$57 -> 0.77753922 | U52: =262118+135523 -> 397641 | V52: =U52/$U$57 -> 0.7695072
...

Sheet PL3
B3: 营业收入 | D3: 22年度 | F3: 23年度 | H3: 24年度 | J3: 25年度 | L3: 2024年1-6月 | N3: 2025年1-6月
D4: a | F4: b | H4: c | J4: c | L4: d1 | N4: d2
B5: Customised AI workforce solutions | D5: =SUM(D6:D8) -> -2.086161e+08 | F5: =SUM(F6:F8) -> -4.853631e+08 | H5: =SUM(H6:H8) -> -6.2944451e+08 | J5: =SUM(J6:J8) -> -7.2703378e+08 | L5: =SUM(L6:L8) -> -2.8004144e+08 | N5: =SUM(N6:N8) -> -3.1884501e+08
B6: ICT services | D6: -37081816 | F6: -1.947907e+08 | H6: -4.2215234e+08 | J6: -3.2335846e+08 | L6: -2.0269747e+08 | N6: -2.0980538e+08
B7: AIGC services | D7: -1.0278221e+08 | F7: -2.6526012e+08 | H7: -1.9050367e+08 | J7: -3.9981265e+08 | L7: -68796248 | N7: -1.070887e+08
B8: AI voice services | D8: -68752074 | F8: -25312277 | H8: -16788507 | J8: -3862674.1 | L8: -8547718 | N8: -1950936.2
B9: Standardized and productized AI workforce solutions | D9: -14196979 | F9: -45442759 | H9: -25993256 | J9: -10396657 | L9: -13070291 | N9: -6963475.6
B10: 全自动内容生产 | J10: -51387720
B11: 合计 | D11: =SUM(D6:D9) -> -2.2281308e+08 | F11: =SUM(F6:F9) -> -5.3080586e+08 | H11: =SUM(H6:H9) -> -6.5543777e+08 | J11: =SUM(J6:J10) -> -7.8881816e+08 | L11: =SUM(L6:L9) -> -2.9311173e+08 | N11: =SUM(N6:N9) -> -3.2580849e+08
D12: 0 | F12: 0 | H12: 0 | J12: 0 | L12: 0 | N12: 0
B13: 营业成本
B14: Customised AI workforce solutions | D14: =SUM(D15:D17) -> 1.2896516e+08 | F14: =SUM(F15:F17) -> 2.7851244e+08 | H14: =SUM(H15:H17) -> 4.2057972e+08 | J14: =SUM(J15:J17) -> 4.8424788e+08 | L14: =SUM(L15:L17) -> 1.8740141e+08 | N14: =SUM(N15:N17) -> 2.1823733e+08
B15: ICT services | D15: 27239174 | F15: 1.3326885e+08 | H15: 3.0115375e+08 | J15: 2.3399155e+08 | L15: 1.439184e+08 | N15: 1.5134113e+08
B16: AIGC services | D16: 55495031 | F16: 1.2765868e+08 | H16: 1.1255568e+08 | J16: 2.474397e+08 | L16: 40367489 | N16: 65926942
B17: AI voice services | D17: 46230954 | F17: 17584907 | H17: 6870293.4 | J17: 2816629.7 | L17: 3115522.3 | N17: 969258.55
B18: Standardized and productized AI workforce solutions | D18: 7981170.2 | F18: 8789420.8 | H18: 9069211.8 | J18: 8139870.2 | L18: 4788471.3 | N18: 4660800.3
B19: 全自动内容生产 | J19: 23151796
B20: 小计 | D20: 1.3694633e+08 | F20: 2.8730186e+08 | H20: 4.2964893e+08 | J20: =SUM(J15:J19) -> 5.1553954e+08 | L20: 1.9218989e+08 | N20: 2.2289813e+08
B22: 税金及附加 | D22: 63994.13 | F22: 343189.27 | H22: 710292.49 | L22: 194936.36 | N22: 230.93
B24: 合计 | D24: 1.3701032e+08 | F24: 2.8764505e+08 | H24: 4.3035922e+08 | L24: 1.9238482e+08 | N24: 2.2289836e+08
D25: 0 | F25: 0 | H25: 0 | J25: 0 | L25: 0 | N25: 0
B28: 毛利率 | D28: 22年度 | F28: 23年度 | H28: 24年度 | J28: 25年度 | L28: 2024年1-6月 | N28: 2025年1-6月
B29: - Customized AI workforce solutions | D29: 0.38180631 | F29: 0.43363898 | H29: 0.36649337 | J29: =1-J14/(-J5) -> 0.33394034 | L29: 0.36708304 | N29: 0.37759621
B30: - Standardized and productized AI workforce solutions | D30: =(D9+D18)/D9 -> 0.43782616 | F30: =(F9+F18)/F9 -> 0.80658259 | H30: =(H9+H18)/H9 -> 0.65109367 | J30: =(J9+J18)/J9 -> 0.2170685 | L30: =(L9+L18)/L9 -> 0.63363698 | N30: =(N9+N18)/N9 -> 0.33067902
B31: 全自动内容生产 | J31: =(J10+J19)/J10 -> 0.54946831

Sheet PL4
C2: 其他收益 - 政府补助
C4: 按性质分类 | D4: 2022年 | F4: 2023年 | H4: 2024年 | J4: 202406 | L4: 202506
C5: 稳岗补贴 | D5: -20623.94 | F5: -29086 | H5: -9807 | J5: 0 | L5: 0
C6: 政府补助 | D6: -16604524 | F6: -12430572 | H6: -10000122 | J6: -6562001.4 | L6: -1057609.8
C7: 装修补贴 | D7: -965307.2 | F7: -1053062.4 | H7: -175510.4 | J7: -175510.4 | L7: 0
C8: 合计 | D8: =SUM(D5:D7) -> -17590455 | F8: =SUM(F5:F7) -> -13512720 | H8: =SUM(H5:H7) -> -10185440 | J8: =SUM(J5:J7) -> -6737511.8 | L8: =SUM(L5:L7) -> -1057609.8
C10: 其他收益的政府补助主要包括稳岗补贴、政府补助以及装修补贴。主要以政府补助为主，具体如下： （1）2022年集团的政府补助主要是南京硅基获得的中国（南京）软件谷管理委员会研发费用补贴人民币330万元、房租补贴人民币463万元和南京市雨花台区发展和改革委员会2022年省级现代服务业发展专项资金160万元以及绵阳硅基对绵阳汇鑫发展集团有限公司的销售收入442万元，实际为政府补助。其中，研发费用补贴为政府鼓励企业加大研发投入，对研发投入比达到10%的国家高新技术企业及科技创业家企业，补贴研发费用；房租补贴为软件谷对于入驻公司的房租补贴；发展专项资金主要系政府对集成电路设计企业首轮流片补贴等项目给予支持。 （2）2023年收到的政府补贴主要是硅基昆山获得的昆山经济技术开发区补助款人民币500万元、南京硅基获得的中国（南京）软件谷管理委员会房租补贴人民币243万元和中国（南京）软件谷管理委员会费用产发（2023年度27号文兑现）补助人民币144万元、绵阳硅基获得的绵阳政府招商引资项目的补贴资金人民币200万元。 （3）2024年收到的政府补助主要是昆山经济技术开发区管理委员会对昆山公司完成工商注册的落地奖励300万元和南京硅基获得的南京市雨花台区发展和改革委员会市级工业和信息化专项资金300万元。 （4）2025年上半年收到的政府补助主要系硅基昆山收到昆山市市级机关事务管理中心省文化专项资金补助人民币100万元。
C12: 请补充政府补助清单明细（金额大于PBC）
C14: 其他收益 - 增值税
C16: 按性质分类 | D16: 2022年 | F16: 2023年 | H16: 2024年 | J16: 202406 | L16: 202506
C17: 即征即退增值税 | D17: 0 | F17: -267878.21 | H17: -75791.33 | J17: -72472 | L17: -35249.49
C18: 增值税加计抵减 | D18: -270010.42 | F18: -1814340 | H18: -448406.66 | J18: -448406.66 | L18: 0
C19: 合计 | D19: =SUM(D17:D18) -> -270010.42 | F19: =SUM(F17:F18) -> -2082218.2 | H19: =SUM(H17:H18) -> -524197.99 | J19: =SUM(J17:J18) -> -520878.66 | L19: =SUM(L17:L18) -> -35249.49
C26: 其他收益 - 其他
C28: 按性质分类 | D28: 2022年 | F28: 2023年 | H28: 2024年 | J28: 202406 | L28: 202506
C29: 个税返还 | D29: -111360.2 | F29: -130780.51 | H29: -136418.51 | J29: -138028.92 | L29: -78625.8
C30: 合计 | D30: =SUM(D29:D29) -> -111360.2 | F30: =SUM(F29:F29) -> -130780.51 | H30: =SUM(H29:H29) -> -136418.51 | J30: =SUM(J29:J29) -> -138028.92 | L30: =SUM(L29:L29) -> -78625.8

Sheet PL5
B3: 其他净(收益)/损失 | D3: 22年度 | F3: 23年度 | H3: 24年度 | J3: 2024年1-6月 | L3: 2025年1-6月
D4: a | F4: b | H4: c | J4: d1 | L4: d2
B6: 诉讼费 | D6: 117800 | F6: 0 | H6: 320492.54 | J6: 320492.54
B7: 押金 | D7: 0 | F7: 250 | H7: 551320.44 | J7: 455060.58 | L7: 0
B8: 固定资产处置收益 | D8: 0 | F8: -65069.34 | H8: -17159.68 | J8: -17159.68 | L8: 0
B9: 其他 | D9: 6878.46 | F9: 26937.78 | H9: -176274.06 | J9: -98491.85 | L9: -167407.18
B11: 合计 | D11: =SUM(D6:D9) -> 124678.46 | F11: =SUM(F6:F9) -> -37881.56 | H11: =SUM(H6:H9) -> 678379.24 | J11: =SUM(J6:J9) -> 659901.59 | L11: =SUM(L6:L9) -> -167407.18
D12: =D11-'FY22-25 IFRS（合并）'!G8 -> 0 | F12: =F11-'FY22-25 IFRS（合并）'!I8 -> -4.6566129e-10 | H12: =H11-'FY22-25 IFRS（合并）'!K8 -> 0 | J12: =J11-'FY22-25 IFRS（合并）'!M8 -> -0.01 | L12: =L11-'FY22-25 IFRS（合并）'!O8 -> 0
B15: 请补充

Sheet 三费>>>
A1: Blue: Hard code vale
A2: Black: Calculation
A3: Green: Linked from another tab
A4: Red: Linked from the same tab
B7: Selling and Marketing Expenses
D8: Year ended December 31 | H8: Six months ended June 30 | O8: Year ended December 31 | R8: Six months ended June 30
D9: 2022 | E9: 2023 | F9: 2024 | G9: 2025 | H9: 2024 | I9: 2025 | O9: 2022 | P9: 2023 | Q9: 2024 | R9: 2024 | S9: 2025
B10: Employee benefit expenses | D10: 23303.949 | E10: 30540.088 | F10: 30891.563 | G10: 19613 | H10: 16260.771 | I10: 9812.3171 | L10: 研发/销售人员招聘 | M10: Employee benefit expenses | O10: =SUM(O11:O13) -> 97326.876 | P10: =SUM(P11:P13) -> 100459.09 | Q10: =SUM(Q11:Q13) -> 86633.257 | R10: =SUM(R11:R13) -> 45076.535 | S10: =SUM(S11:S13) -> 30409.624
C11: ESOP | D11: =[1]ESOP!K25/1000 -> 401.50492 | E11: =[1]ESOP!L25/1000 -> 917.10076 | F11: =[1]ESOP!N25/1000 -> 11298.321 | G11: 11279.704 | H11: =[1]ESOP!M25/1000 -> 5648.0603 | I11: =[1]ESOP!O25/2/1000 -> 5639.8522 | N11: ESOP | O11: =D11+D25+D41 -> 6172.2267 | P11: =E11+E25+E41 -> 7834.985 | Q11: =F11+F25+F41 -> 21479.107 | R11: =H11+H25+H41 -> 10722.643 | S11: =I11+I25+I41 -> 10718.557
C12: Employee benefit expenses | D12: =D10-D11 -> 22902.444 | E12: =E10-E11 -> 29622.987 | F12: =F10-F11 -> 19593.242 | G12: =G10-G11 -> 8333.2957 | H12: =H10-H11 -> 10612.71 | I12: =I10-I11 -> 4172.4649 | N12: Employee benefit expenses | O12: =D12+D26+D42 -> 91154.649 | P12: =E12+E26+E42 -> 92624.103 | Q12: =F12+F26+F42 -> 65154.15 | R12: =H12+H26+H42 -> 34353.892 | S12: =I12+I26+I42 -> 19691.067
B13: Marketing service expenses | D13: 8156.7859 | E13: 14132.193 | F13: 28201.959 | G13: 21325 | H13: 17862.172 | I13: 6659.8749 | N13: Listing Expenses | O13: =D27 -> 0 | P13: =E27 -> 0 | Q13: =F27 -> 0 | R13: =H27 -> 0 | S13: =I27 -> 0
B14: Advertising and promotion expenses | D14: 1043.2823 | E14: 61066.882 | F14: 17783.624 | G14: 10940 | H14: 225.53772 | I14: 3256.9344 | L14: 宣传推广 | M14: Marketing service expenses | O14: =D13 -> 8156.7859 | P14: =E13 -> 14132.193 | Q14: =F13 -> 28201.959 | R14: =H13 -> 17862.172 | S14: =I13 -> 6659.8749
B15: Office, utilities and travelling expenses | D15: 4113.4577 | E15: 3346.1403 | F15: 3238.0681 | G15: 2398 | H15: 1817.6485 | I15: 1082.0211 | M15: Advertising and promotion expenses | O15: =D14 -> 1043.2823 | P15: =E14 -> 61066.882 | Q15: =F14 -> 17783.624 | R15: =H14 -> 225.53772 | S15: =I14 -> 3256.9344
B16: Others | D16: 1894.1463 | E16: 1177.6911 | F16: 2454.2896 | G16: 2140 | H16: 1190.7804 | I16: 982.99067 | M16: Office, utilities and travelling expenses | O16: =D15+D32 -> 10471.615 | P16: =E15+E32 -> 11324.085 | Q16: =F15+F32 -> 8857.6512 | R16: =H15+H32 -> 4624.6168 | S16: =I15+I32 -> 2912.5373
D17: =SUM(D10,D13:D16) -> 38511.621 | E17: =SUM(E10,E13:E16) -> 110262.99 | F17: =SUM(F10,F13:F16) -> 82569.503 | G17: =SUM(G10,G13:G16) -> 56416 | H17: =SUM(H10,H13:H16) -> 37356.909 | I17: =SUM(I10,I13:I16) -> 21794.138 | M17: Professional service fees | O17: =D29 -> 5143.5 | P17: =E29 -> 5375.3938 | Q17: =F29 -> 6098.4992 | R17: =H29 -> 3508.0697 | S17: =I29 -> 4452.1599
C18: 主表check | E18: -0.0064251239 | F18: -0.49660094 | G18: 0 | K18: 委外研发 | L18: 算力采购及租赁 | M18: Technical service fees | O18: =D43 -> 11783 | P18: =E43 -> 74395 | Q18: =F43 -> 108237 | R18: =H43 -> 61176 | S18: =I43 -> 52398
M19: Material expenses | O19: =D45 -> 8434 | P19: =E45 -> 0 | Q19: =F45 -> 0 | R19: =H45 -> 0 | S19: =I45 -> 0
M20: Depreciation and amortization | O20: =D28+D44 -> 13399.461 | P20: =E28+E44 -> 14800.712 | Q20: =F28+F44 -> 12825.954 | R20: =H28+H44 -> 6480.1077 | S20: =I28+I44 -> 3814.9621
B21: Administrative and Other Operating Expenses | M21: Others | O21: =D16+D33+D46 -> 5296.5014 | P21: =E16+E33+E46 -> 6245.0096 | Q21: =F16+F33+F46 -> 5272.3001 | R21: =H16+H33+H46 -> 3068.6882 | S21: =I16+I33+I46 -> 2720.5638
D22: Year ended December 31 | H22: Six months ended June 30 | O22: =SUM(O10,O14:O21) -> 161055.02 | P22: =SUM(P10,P14:P21) -> 287798.36 | Q22: =SUM(Q10,Q14:Q21) -> 273910.24 | R22: =SUM(R10,R14:R21) -> 142021.73 | S22: =SUM(S10,S14:S21) -> 106624.66
D23: 2022 | E23: 2023 | F23: 2024 | G23: 2025 | H23: 2024 | I23: 2025
B24: Employee benefit expenses | D24: 24817.927 | E24: 24063 | F24: 23097.695 | G24: 22287 | H24: 12222.764 | I24: 10490.307 | J24: 10490 | N24: 左右check | O24: =O22-D17-D34-D47 -> 0 | P24: =P22-E17-E34-E47 -> 0 | Q24: =Q22-F17-F34-F47 -> 0 | R24: =R22-H17-H34-H47 -> 0 | S24: =S22-I17-I34-I47 -> 0
C25: ESOP | D25: =[1]ESOP!K24/1000 -> 5630.5233 | E25: =[1]ESOP!L24/1000 -> 5820.3662 | F25: =[1]ESOP!N24/1000 -> 8507.4349 | G25: 8487 | H25: =[1]ESOP!M24/1000 -> 4238.2914 | I25: =[1]ESOP!O24/2/1000 -> 4243.6898
C26: Employee benefit expenses | D26: =D24-D25 -> 19187.404 | E26: =E24-E25 -> 18242.634 | F26: =F24-F25 -> 14590.26 | G26: =G24-G25 -> 13800 | H26: =H24-H25 -> 7984.4729 | I26: =I24-I25 -> 6246.6173 | N26: 原版本三费加总check | O26: =O22+#REF!+#REF!+#REF! -> #REF! | P26: =P22+#REF!+#REF!+#REF! -> #REF! | Q26: =Q22+#REF!+#REF!+#REF! -> #REF! | R26: =R22+#REF!+#REF!+#REF! -> #REF! | S26: =S22+#REF!+#REF!+#REF! -> #REF!
B28: Depreciation and amortization | D28: 8401.4612 | E28: 7635.7121 | F28: 4608.9542 | G28: 3204 | H28: 3215.1077 | I28: 1032.9621
B29: Professional service fees | D29: 5143.5 | E29: 5375.3938 | F29: 6098.4992 | G29: 23110 | H29: 3508.0697 | I29: 4452.1599 | O29: =O20-SUM(#REF!) -> #REF! | P29: =P20-SUM(#REF!) -> #REF! | Q29: =Q20-SUM(#REF!) -> #REF! | R29: =R20-SUM(#REF!) -> #REF! | S29: =S20-SUM(#REF!) -> #REF!
C30: Listing Expenses | F30: =#REF! -> #REF! | G30: 18328 | H30: =#REF! -> #REF! | I30: =#REF! -> #REF!
C31: Remaing Professional service fees | D31: =D29-D30 -> 5143.5 | E31: =E29-E30 -> 5375.3938 | F31: =F29-F30 -> #REF! | G31: =G29-G30 -> 4782 | H31: =H29-H30 -> #REF! | I31: =I29-I30 -> #REF!
B32: Office, utilities, traveling and entertainment expenses | D32: 6358.157 | E32: 7977.9443 | F32: 5619.5831 | G32: 5344 | H32: 2806.9683 | I32: 1830.5161
B33: Others | D33: 2389.3551 | E33: 2914.3184 | F33: 1787.0105 | G33: 1707 | H33: 813.90784 | I33: 485.5731
D34: =SUM(D24,D28:D29,D32:D33) -> 47110.4 | E34: =SUM(E24,E28:E29,E32:E33) -> 47966.369 | F34: =SUM(F24,F28:F29,F32:F33) -> 41211.742 | G34: =SUM(G24,G28:G29,G32:G33) -> 55652 | H34: =SUM(H24,H28:H29,H32:H33) -> 22566.818 | I34: =SUM(I24,I28:I29,I32:I33) -> 18291.518 | O34: 8401
C35: 主表check | E35: -0.63088 | F35: 0.74157 | G35: 0 | O35: 4998
D36: =D28+D44 -> 13399.461 | E36: =E28+E44 -> 14800.712 | F36: =F28+F44 -> 12825.954
B37: Research and Development Expenses
D38: Year ended December 31 | H38: Six months ended June 30
D39: 2022 | E39: 2023 | F39: 2024 | G39: 2025 | H39: 2024 | I39: 2025
B40: Employee benefit expenses | D40: 49205 | E40: 45856 | F40: 32644 | G40: 19281 | H40: 16593 | I40: 10107 | J40: =G40/$G$47 -> 0.1180479
C41: ESOP | D41: =[1]ESOP!K26/1000 -> 140.19848 | E41: =[1]ESOP!L26/1000 -> 1097.5181 | F41: =[1]ESOP!N26/1000 -> 1673.3519 | G41: 1670 | H41: =[1]ESOP!M26/1000 -> 836.29182 | I41: =[1]ESOP!O26/2/1000 -> 835.01486 | J41: =G41/$G$47 -> 0.010224573
C42: Employee benefit expenses | D42: =D40-D41 -> 49064.802 | E42: =E40-E41 -> 44758.482 | F42: =F40-F41 -> 30970.648 | G42: =G40-G41 -> 17611 | H42: =H40-H41 -> 15756.708 | I42: =I40-I41 -> 9271.9851 | J42: =G42/$G$47 -> 0.10782333
B43: Technical service fees | D43: 11783 | E43: 74395 | F43: 108237 | G43: 138556 | H43: 61176 | I43: 52398 | J43: =G43/$G$47 -> 0.84830897
...

Sheet PL6
C5: 销售费用 | D5: 2022.1-12 | F5: 2023.1-12 | H5: 2024.1-12 | J5: 2025.1-12 | L5: 2024.1-6 | N5: 2025.1-6
D7: a | F7: b | H7: c | J7: d | L7: d | N7: e
C8: 员工福利开支 | D8: 22902444 | F8: 29622987 | H8: 19593242 | J8: 8333118.8 | L8: 10612710 | N8: 4879471.9
C9: 渠道費用 | D9: 6683624.7 | F9: 12406844 | H9: 25867472 | J9: 10446067 | L9: 16299441 | N9: 11801574
C10: 推广及广告开支 | D10: 1043282.3 | F10: 61066882 | H10: 14566643 | J10: 10939820 | L10: 225537.72 | N10: 3256934.4
C11: 服务费及其他咨询费用 | D11: 1473161.2 | F11: 1555077.4 | H11: 2334487.1 | J11: 10878828 | L11: 1562730.8 | N11: 4718917.8
C12: 营销及差旅开支 | D12: 4113457.6 | F12: 3346140.3 | H12: 3238068.1 | J12: 2397880.4 | L12: 1817648.5 | N12: 1082021.1
C13: 股份支付开支 | D13: 0 | F13: 5016443 | H13: 5340900.4 | J13: 11279704 | L13: 2670194.9 | N13: 2664852.5
C14: 其他 | D14: 1894146.3 | F14: 2903039.9 | H14: 4788776.8 | J14: 2140554 | L14: 2753511.2 | N14: 1904490.2
C16: 合计 | D16: 38110116 | F16: 1.0986149e+08 | H16: 84743936 | J16: 56415972 | L16: 38445226 | N16: 22879865
C17: Check: | D17: =ROUND(D16-'FY22-25 IFRS（合并）'!G9,0) -> 0 | F17: =ROUND(F16-'FY22-25 IFRS（合并）'!I9,0) -> 0 | H17: =ROUND(H16-'FY22-25 IFRS（合并）'!K9,0) -> 0 | J17: =J16-'[1]FY22-25 IFRS（合并）'!$AB$9 -> 0 | L17: =ROUND(L16-'FY22-25 IFRS（合并）'!M9,0) -> 0 | N17: =ROUND(N16-'FY22-25 IFRS（合并）'!O9,0) -> 0
C53: 请补充按招股书口径分类的数字

Sheet PL8
F5: 2022年 | H5: 2023年 | J5: 2024年 | L5: 2025年 | N5: 2024年1-6月 | P5: 2025年1-6月
F6: PRC审定数 | H6: PRC审定数 | J6: PRC审定数 | L6: PRC审定数 | N6: PRC审定数 | P6: PRC审定数
C8: 职工薪酬 | F8: 49205157 | H8: 45855549 | J8: 32643748 | L8: 19281285 | N8: 16592855 | P8: 10106788
C9: -工资 | F9: 44029377 | H9: 38048425 | J9: 27357678 | L9: 17680439 | N9: 15107505 | P9: 9322187.9
C10: -奖金 | F10: 111725 | H10: 3499269.4 | J10: 867233.75 | L10: 22000 | P10: 0
C11: -社保 | F11: 3560368.4 | H11: 2954022.9 | J11: 3940144.1 | L11: 1115001.5 | N11: 1140505.4 | P11: 537330.28
C12: -公积金 | F12: 1503686.5 | H12: 1353831.1 | J12: 478691.7 | L12: 463844.24 | N12: 344845 | P12: 247270
C13: 技术服务费 | F13: 20219135 | H13: 74396938 | J13: 1.0996728e+08 | L13: 1.3855578e+08 | N13: 61177347 | P13: 52398290
C14: 研发设备折旧 | F14: 481872.89 | H14: 2823599.5 | J14: 2276078.1 | L14: 4091593 | N14: 1006542.8 | P14: 1475541.4
C15: 无形资产摊销 | F15: 419740.9 | H15: 244793.81 | J15: 115688.6 | L15: 0 | N15: 209823 | P15: 0
C16: 研发知识产权费 | F16: 514662.5 | H16: 959089.03 | J16: 1012929 | L16: 698864.28 | N16: 209830.42 | P16: 417471.04
C17: 研发公共交通费 | F17: 111764.24 | H17: 95874.4 | J17: 17990.6 | L17: 0 | N17: 17990.6 | P17: 0
C18: 软件开发费 | F18: 1728.91 | H18: 0 | J18: 0 | L18: 0 | N18: 0 | P18: 0
C19: 研发材料 | F19: 7566.99 | H19: 0 | J19: 0 | L19: 0 | N19: 0 | P19: 0
C20: 房租 | F20: 4095534.5 | H20: 4095534.5 | J20: 4095534.5 | L20: 704926.34 | N20: 2047767.2 | P20: 1305853.9
C21: 股票成本 | F21: 140198.48 | H21: 1097518.1 | J21: 0 | L21: 0 | N21: 836291.82 | P21: 835014.86
C22: 其他 | F22: 0 | H22: 0 | J22: 0 | L22: 0 | N22: 0 | P22: 0
... C24: 合计 | F24: 75433068 | H24: 1.295689e+08 | J24: 1.5012925e+08 | L24: 1.6333245e+08 | N24: 82098448 | P24: 66538960
C25: check | F25: =F24-'FY22-25 IFRS（合并）'!G11 -> -0.0032132268 | H25: =H24-'FY22-25 IFRS（合并）'!I11 -> 0 | J25: =J24-'FY22-25 IFRS（合并）'!K11 -> -0.00053980947 | L25: =L24-'[1]FY22-25 IFRS（合并）'!$AB$11 -> 0 | N25: =N24-'FY22-25 IFRS（合并）'!M11 -> -0.0013011694 | P25: =P24-'FY22-25 IFRS（合并）'!O11 -> 0
C56: 请补充按招股书口径分类的数字

Sheet PL9&BS4
C4: 合同资产 | E4: 44926 | G4: 45291 | I4: 45657 | K4: 46022 | M4: 45838
E5: a | G5: b | I5: c | K5: c | M5: d
C6: 原值 | E6: 507784.39 | G6: 5602907.9 | I6: 8141850.4 | K6: 21220336 | M6: 7488285.7
C7: 坏账准备 | E7: -20649.762 | G7: -227850.08 | I7: -330140.4 | K7: -849497.65 | M7: -302128.8
C9: 小计 | E9: =SUM(E6:E7) -> 487134.63 | G9: =SUM(G6:G7) -> 5375057.8 | I9: =SUM(I6:I7) -> 7811710 | K9: =SUM(K6:K8) -> 20370838 | M9: =SUM(M6:M7) -> 7186156.9
E10: =E9-'FY22-25 IFRS（合并）'!G38-'FY22-25 IFRS（合并）'!G47 -> -0.0022035593 | G10: =G9-'FY22-25 IFRS（合并）'!I38-'FY22-25 IFRS（合并）'!I47 -> -0.00089157 | I10: =I9-'FY22-25 IFRS（合并）'!K38-'FY22-25 IFRS（合并）'!K47 -> 0.0049911498 | K10: =K9-'FY22-25 IFRS（合并）'!Q38-'FY22-25 IFRS（合并）'!Q47 -> 115622.33 | M10: =M9-'FY22-25 IFRS（合并）'!O38-'FY22-25 IFRS（合并）'!O47 -> 0.0049647014
C13: 请更新合同资产金额

Sheet PL7
C4: 管理费用 | E4: 2022.1-12 | G4: 2023.1-12 | I4: 2024.1-12 | K4: 2025.1-12 | M4: 2024.1-6 | O4: 2025.1-6
E6: a | G6: b | I6: c | K6: d | M6: d | O6: e
C7: 员工福利开支 | E7: 19187404 | G7: 18242634 | I7: 14590260 | K7: 13799376 | M7: 7984472.9 | O7: 6246617.3
C8: 折旧与摊销 | E8: 8401461.2 | G8: 7635712.1 | I8: 4608954.2 | K8: 3203936.4 | M8: 3215107.7 | O8: 1032962.1
C9: 专业服务及其他咨询费 | E9: 5143500 | G9: 5375393.8 | I9: 6098499.2 | K9: 23109978 | M9: 3508069.7 | O9: 4452159.9
C10: 办公费 | E10: 5108258.5 | G10: 6273689.1 | I10: 4447102.3 | K10: 4335878 | M10: 2408344.5 | O10: 1521563.4
C11: 差旅及招待费 | E11: 1249898.5 | G11: 1704255.2 | I11: 1172480.8 | K11: 1008617.6 | M11: 398623.77 | O11: 308952.7
C12: 股份支付开支 | E12: 6032028.2 | G12: 6221871.1 | I12: 6333002.8 | K12: 8487379.5 | M12: 3149975.3 | O12: 3157962.5
C13: 其他 | E13: 2389355.1 | G13: 2914318.4 | I13: 1787010.5 | K13: 1706829 | M13: 813907.84 | O13: 485573.1
C15: 合计 | E15: 47511905 | G15: 48367874 | I15: 39037309 | K15: =SUM(K7:K13) -> 55651994 | M15: 21478502 | O15: 17205791
C16: Check： | E16: =ROUND(E15-'FY22-25 IFRS（合并）'!G10,0) -> 0 | G16: =ROUND(G15-'FY22-25 IFRS（合并）'!I10,0) -> 0 | I16: =ROUND(I15-'FY22-25 IFRS（合并）'!K10,0) -> 0 | K16: =ROUND(K15-'[1]FY22-25 IFRS（合并）'!$AB$10,0) -> 0 | M16: =ROUND(M15-'FY22-25 IFRS（合并）'!M10,0) -> 0 | O16: =ROUND(O15-'FY22-25 IFRS（合并）'!O10,0) -> 0
C52: 请补充按招股书口径分类的数字

Sheet PL10
C4: 财务收入 | E4: 2022年度 | G4: 2023年度 | I4: 2024年度 | K4: 2025年度 | M4: 2024年1-6月 | O4: 2025年1-6月
E5: a | G5: b | I5: c | K5: d | M5: d1 | O5: d2
C6: 利息收入 | E6: -9458184.8 | G6: -4606419.3 | I6: -2239349.8 | K6: -856870.88 | M6: -623760.44 | O6: -464884.35
C8: 合计 | E8: -9458184.8 | G8: -4606419.3 | I8: -2239349.8 | K8: -856870.88 | M8: -623760.44 | O8: -464884.35
C9: Check： | E9: =ROUND(E8-'FY22-25 IFRS（合并）'!G14,0) -> 0 | G9: =ROUND(G8-'FY22-25 IFRS（合并）'!I14,0) -> 0 | I9: =ROUND(I8-'FY22-25 IFRS（合并）'!K14,0) -> 0 | K9: =ROUND('[1]FY22-25 IFRS（合并）'!$AB$14-K8,0) -> 0 | M9: =ROUND(M8-'FY22-25 IFRS（合并）'!M14,0) -> 0 | O9: =ROUND(O8-'FY22-25 IFRS（合并）'!O14,0) -> 0
C11: 财务成本 | E11: 2022年度 | G11: 2023年度 | I11: 2024年度 | K11: 2025年度 | M11: 2024年1-6月 | O11: 2025年1-6月
E12: a | G12: b | I12: c | K12: d | M12: d1 | O12: d2
C13: 租赁利息 | E13: 759096.24 | G13: 435137.11 | I13: 239820.09 | K13: 143669.04 | M13: 158049.15 | O13: 99442.49
C14: 其他 | E14: 0 | G14: 0 | I14: 0 | K14: 0 | M14: 0 | O14: 0
C16: 合计 | E16: 759096.24 | G16: 435137.11 | I16: 239820.09 | K16: 143669.04 | M16: 158049.15 | O16: 99442.49
C17: Check： | E17: =ROUND(E16-'FY22-25 IFRS（合并）'!G15,0) -> 0 | G17: =ROUND(G16-'FY22-25 IFRS（合并）'!I15,0) -> 0 | I17: =ROUND(I16-'FY22-25 IFRS（合并）'!K15,0) -> 0 | K17: =K16-'FY22-25 IFRS（合并）'!Q15 -> 0 | M17: =ROUND(M16-'FY22-25 IFRS（合并）'!M15,0) -> 0 | O17: =ROUND(O16-'FY22-25 IFRS（合并）'!O15,0) -> 0

Sheet PL11
A3: 2 | B3: 长期股权投资Movement | F3: 211231余额 | G3: 本年注资Cash out | H3: 本年退资Cash in | I3: 本年确认损益 | J3: 221231余额 | L3: 221231余额 | M3: 本年注资Cash out | N3: 本年退资Cash in | O3: 本年确认损益 | P3: 231231余额 | R3: 231231余额 | S3: 本年注资Cash out | T3: 本年退资Cash in | U3: 本年确认损益 | V3: 241231余额 | X3: 231231余额 | Y3: 本年注资Cash out | Z3: 本年退资Cash in | AA3: 本年确认损益 | AB3: 240630余额 | AD3: 241231余额 | AE3: 本年注资Cash out | AF3: 本年退资Cash in | AG3: 本年确认损益 | AH3: 250630余额
B4: 母公司对子公司投资：
B5: 南京硅信智能科技有限公司 | F5: 2000000 | G5: 0 | H5: 0 | I5: 0 | J5: 2000000 | L5: 2000000 | M5: 0 | N5: 0 | O5: 0 | P5: 2000000 | R5: 2000000 | S5: 0 | T5: 0 | U5: 0 | V5: 2000000 | X5: 2000000 | Y5: 0 | Z5: 0 | AA5: 0 | AB5: 2000000 | AD5: 2000000 | AE5: 0 | AF5: 0 | AG5: 0 | AH5: 2000000
B6: 硅基（昆山）智能科技有限公司 | F6: 0 | G6: 0 | H6: 0 | I6: 0 | J6: 0 | L6: 0 | M6: 12000000 | N6: 0 | O6: 0 | P6: 12000000 | R6: 12000000 | S6: 88000000 | T6: 0 | U6: 0 | V6: 100000000 | X6: 12000000 | Y6: 88000000 | Z6: 0 | AA6: 0 | AB6: 100000000 | AD6: 100000000 | AE6: 0 | AF6: 0 | AG6: 0 | AH6: 100000000
B7: 嘉兴硅基智能科技有限公司 | X7: 0 | Y7: 200000000 | AB7: 200000000 | AD7: 0 | AE7: 200000000 | AH7: 200000000
F8: 2000000 | G8: 0 | H8: 0 | I8: 0 | J8: 2000000 | L8: 2000000 | M8: 12000000 | N8: 0 | O8: 0 | P8: 14000000 | R8: 14000000 | S8: 88000000 | T8: 0 | U8: 0 | V8: 102000000 | X8: 14000000 | Y8: 288000000 | Z8: 0 | AA8: 0 | AB8: 302000000 | AD8: 102000000 | AE8: 200000000 | AF8: 0 | AG8: 0 | AH8: 302000000
B9: JV：
