Workbook
Name \0: #REF!
Name \a: #REF!
Name \b: #REF!
Name \bbb: #REF!
Name \C: #REF!
Name \d: #REF!
Name \f: #N/A
Name \i: #REF!
Name \m: #REF!
Name \p: #REF!
Name \Q: #REF!
Name \R: #REF!
Name \s: #N/A
Name \z: #REF!
Name _: #REF!
Name _.30: #REF!
Name _.dbf: #REF!
Name _.xls: #REF!
Name _?: #REF!
Name _??????: #REF!
Name ____________txt1: #REF!
Name ____________txt2: #REF!
Name ____________txt3: #REF!
Name ____________txt4: #REF!
Name _______DAT1: #REF!
Name _______DAT10: #REF!
Name _______DAT11: #REF!
Name _______DAT12: #REF!
Name _______DAT13: #REF!
Name _______DAT14: #REF!
Name _______DAT15: #REF!
Name _______DAT2: #REF!
Name _______DAT3: #REF!
Name _______DAT4: #REF!
Name _______DAT5: #REF!
Name _______DAT6: #REF!
Name _______DAT7: #REF!
Name _______DAT8: #REF!
Name _______DAT9: #REF!
Name ______DAT1: #REF!
Name ______DAT10: #REF!
Name ______DAT11: #REF!
Name ______DAT12: #REF!
Name ______DAT13: #REF!
Name ______DAT14: #REF!
Name ______DAT15: #REF!
Name ______DAT2: #REF!
Name ______DAT3: #REF!
Name ______DAT4: #REF!
Name ______DAT5: #REF!
Name ______DAT6: #REF!
Name ______DAT7: #REF!
Name ______DAT8: #REF!
Name ______DAT9: #REF!
Name ______PA7: #REF!
Name ______PA8: #REF!
Name ______PD1: #REF!
Name ______PE12: #REF!
Name ______PE13: #REF!
Name ______PE6: #REF!

Sheet Cover
B9: Project GJ Financial Projections
B12: =TODAY() -> 46162
B14: PRELIMINARY AND CONFIDENTIAL DRAFT
D24: Color Code:
D25: Blue: Hard code value
D26: Black: Calculation
D27: Green: Linked from another tab
D28: Red: Linked from the same tab

Sheet Control
B2: Master Control
A4: x | B4: General Assumptions
C6: Beginning period | F6: date | H6: 45838
C8: Hours per day | F8: hours | H8: 24
C9: Monthes per year | F9: month | H9: 12
C10: Days per year | F10: day | H10: 365
C12: Sensitivity Analysis | F12: % | H12: 0 | I12: << Revenue Growth
C13: Sensitivity Analysis for GJ autopilot AIGC agents | F13: % | H13: 0 | I13: << Revenue Growth
A15: x | B15: IPO Assumptions
C17: IPO Case | H17: 1 | I17: 1=IPO; 0=no IPO
C18: Banking Facilities Case | H18: 0 | I18: 1=Optimistic; 0=Pessimistic
C19: IPO Date | H19: 6/30/2026
C20: Number of shares outstanding | H20: 17084745
C21: Offer % | H21: =H22/(H20+H22) -> 0.25 | I21: %
C22: Shares offered | H22: 5694915
C23: Norminal price | H23: 1 | I23: RMB
C25: Listing Expense | G25: 1HK$= | H25: =1/'listing expense'!F5 -> 0.87408 | I25: RMB
C26: Listing Expense (HK$ thousand) | H26: ='listing expense'!P51/1000 -> 117942.2
C27: Net proceeds to Company (HK$ thousand) | H27: ='listing expense'!P54/1000 -> 1320621.4
C28: Total Net Proceeds (HK$ thousand) | H28: ='listing expense'!P56/1000 -> 1279073.7
C29: Net proceeds to Company (RMB thousand) | H29: =H27*H25 -> 1154328.8
C30: Total Net Proceeds (RMB thousand) | H30: =H28*$H$25 -> 1118012.8
C32: IPO Use of Proceeds
E33: R&D | H33: =UOP!K10 -> 559006.38 | I33: RMB Thousand
E34: Computing Power Procurement & Leasing | H34: =UOP!K11 -> 156521.79 | I34: RMB Thousand
E35: R&D Talent Recruitment | H35: =UOP!K13 -> 111801.28 | I35: RMB Thousand
E36: Outsourced R&D | H36: =UOP!K14 -> 55900.638 | I36: RMB Thousand
E37: Business Expansion | H37: =UOP!K18 -> 279503.19 | I37: RMB Thousand
E38: Marketing & Brand Promotion | H38: =UOP!K19 -> 223602.55 | I38: RMB Thousand
E39: Sales Talent Recruitment | H39: =UOP!K20 -> 55900.638 | I39: RMB Thousand
E40: Strategic Partnerships & Acquisitions | H40: =UOP!K24 -> 167701.91 | I40: RMB Thousand
E41: Working Capitacl Supplement | H41: =UOP!K26 -> 111801.28 | I41: RMB Thousand
E42: Check
E44: Overall Check
E45: UOP
E46: IS
E47: WC
E48: BS
E49: Consolidated Financials
E50: Consolidated Financials
...

Sheet PFM Outupt>>>

Sheet IS simplified_0319
A1: Blue: Hard code vale | AU1: x
A2: Black: Calculation | AU2: x
A3: Green: Linked from another tab | AU3: x
A4: Red: Linked from the same tab | AU4: x
AU5: x
W6: Annual Forecast | AU6: x
K7: 2022 | L7: 2023 | M7: 2024 | N7: 2025 | O7: Apr 2026 | P7: Dec 2026 | Q7: 2026 | R7: =Q7+1 -> 2027 | W7: 45839 | X7: =EDATE(W7,1) -> 45870 | Y7: =EDATE(X7,1) -> 45901 | Z7: =EDATE(Y7,1) -> 45931 | AA7: =EDATE(Z7,1) -> 45962 | AB7: =EDATE(AA7,1) -> 45992 | AC7: =EDATE(AB7,1) -> 46023 | AD7: =EDATE(AC7,1) -> 46054 | AE7: =EDATE(AD7,1) -> 46082 | ... AT7: =EDATE(AS7,1) -> 46539 | AU7: x
K8: 12 mths | L8: 12 mths | M8: 12 mths | N8: 12 mths | O8: 4 mths | P8: 8 mths | Q8: 12 mths | R8: 6 mths | AU8: x
K9: Actual | L9: Actual | M9: Actual | N9: Actual | Q9: Forecast | R9: Forecast | W9: RMB’000 | X9: RMB’000 | Y9: RMB’000 | Z9: RMB’000 | AA9: RMB’000 | AB9: RMB’000 | AC9: RMB’000 | AD9: RMB’000 | AE9: RMB’000 | AF9: RMB’000 | AG9: RMB’000 | AH9: RMB’000 | AI9: RMB’000 | AJ9: RMB’000 | AK9: RMB’000 | AL9: RMB’000 | AM9: RMB’000 | AN9: RMB’000 | AO9: RMB’000 | AP9: RMB’000 | AQ9: RMB’000 | AR9: RMB’000 | AS9: RMB’000 | AT9: RMB’000 | AU9: x
A10: 3 | C10: Profit Forecast for the year ending December 31, 2026 | AU10: x
C11: (In RMB thousands) | AU11: x
C12: Revenue | K12: ='Consolidated Financials'!J10 -> 222813.08 | L12: ='Consolidated Financials'!K10 -> 530805.86 | M12: ='Consolidated Financials'!L10 -> 655437.77 | N12: ='Consolidated Financials'!M10 -> 788818.16 | O12: =SUM('Consolidated Financials'!U10:X10) -> 215686.73 | P12: =Q12-O12 -> 875633.25 | Q12: ='Consolidated Financials'!N10 -> 1091320 | R12: ='Consolidated Financials'!O10 -> 619476.7 | AU12: x
C13: Cost of sales | K13: ='Consolidated Financials'!J18 -> -137010 | L13: ='Consolidated Financials'!K18 -> -287645.05 | M13: ='Consolidated Financials'!L18 -> -430359.22 | N13: ='Consolidated Financials'!M18 -> -516747.26 | O13: =SUM('Consolidated Financials'!U18:X18) -> -139083.98 | P13: =Q13-O13 -> -563276.09 | Q13: ='Consolidated Financials'!N18 -> -702360.08 | R13: ='Consolidated Financials'!O18 -> -397437.85 | AU13: x
AU14: x
C15: Gross profit | K15: =SUM(K12,K13) -> 85803.08 | L15: =SUM(L12,L13) -> 243160.81 | M15: =SUM(M12,M13) -> 225078.54 | N15: =SUM(N12,N13) -> 272070.9 | O15: =SUM('Consolidated Financials'!U20:X20) -> 76602.748 | P15: =Q15-O15 -> 312357.16 | Q15: =SUM(Q12,Q13) -> 388959.9 | R15: =SUM(R12,R13) -> 222038.85 | AU15: x
AU16: x
C17: Other income | K17: ='Consolidated Financials'!J23 -> 17972 | L17: ='Consolidated Financials'!K23 -> 15976 | M17: ='Consolidated Financials'!L23 -> 10846 | N17: ='Consolidated Financials'!M23 -> 2554 | O17: =SUM('Consolidated Financials'!U23:X23) -> 155.88479 | P17: =Q17-O17 -> -29.4766 | Q17: ='Consolidated Financials'!N23 -> 126.40819 | R17: ='Consolidated Financials'!O23 -> 0 | AU17: x
C18: Other net (loss)/gain | K18: ='Consolidated Financials'!J24 -> -125 | L18: ='Consolidated Financials'!K24 -> 38 | M18: ='Consolidated Financials'!L24 -> -678 | N18: ='Consolidated Financials'!M24 -> 717 | O18: =SUM('Consolidated Financials'!U24:X24) -> -486.34861 | P18: =Q18-O18 -> 0 | Q18: ='Consolidated Financials'!N24 -> -486.34861 | R18: ='Consolidated Financials'!O24 -> 0 | AU18: x
C19: Selling and marketing expenses | K19: ='Consolidated Financials'!J25 -> -38511.621 | L19: ='Consolidated Financials'!K25 -> -110263 | M19: ='Consolidated Financials'!L25 -> -82570 | N19: ='Consolidated Financials'!M25 -> -55235 | O19: =SUM('Consolidated Financials'!U25:X25) -> -14827.4 | P19: =Q19-O19 -> -65776.125 | Q19: ='Consolidated Financials'!N25 -> -80603.525 | R19: ='Consolidated Financials'!O25 -> -51440.423 | AU19: x
C20: Administrative and other operating expenses | K20: ='Consolidated Financials'!J26 -> -47110.4 | L20: ='Consolidated Financials'!K26 -> -47966 | M20: ='Consolidated Financials'!L26 -> -41211 | N20: ='Consolidated Financials'!M26 -> -55634 | O20: =SUM('Consolidated Financials'!U26:X26) -> -14384 | P20: =Q20-O20 -> -47636.78 | Q20: ='Consolidated Financials'!N26 -> -62020.78 | R20: ='Consolidated Financials'!O26 -> -23058.414 | AU20: x
C21: Research and development expenses | K21: ='Consolidated Financials'!J27 -> -75433 | L21: ='Consolidated Financials'!K27 -> -129569 | M21: ='Consolidated Financials'!L27 -> -150129 | N21: ='Consolidated Financials'!M27 -> -163342 | O21: =SUM('Consolidated Financials'!U27:X27) -> -68939.855 | P21: =Q21-O21 -> -161136.38 | Q21: ='Consolidated Financials'!N27 -> -230076.24 | R21: ='Consolidated Financials'!O27 -> -152790.74 | AU21: x
C22: Impairment loss on trade and other receivables and contract assets | K22: ='Consolidated Financials'!J28 -> -3553 | L22: ='Consolidated Financials'!K28 -> -11750 | M22: -21170 | N22: ='Consolidated Financials'!M28 -> -27595 | O22: =SUM('Consolidated Financials'!U28:X28) -> -3427.7737 | P22: =Q22-O22 -> -23437.047 | Q22: ='Consolidated Financials'!N28 -> -26864.821 | R22: ='Consolidated Financials'!O28 -> -10970.471 | AU22: x
C23: Profit/(Loss) from operations | K23: =SUM(K17:K22,K15) -> -60957.941 | L23: =SUM(L17:L22,L15) -> -40373.194 | M23: =SUM(M17:M22,M15) -> -59833.456 | N23: =SUM(N17:N22,N15) -> -26464.105 | O23: =SUM(O17:O22,O15) -> -25306.744 | P23: =SUM(P17:P22,P15) -> 14341.346 | Q23: =SUM(Q17:Q22,Q15) -> -10965.398 | R23: =SUM(R17:R22,R15) -> -16221.205 | AU23: x
AU24: x
C25: Finance income | K25: ='Consolidated Financials'!J32 -> 9458 | L25: ='Consolidated Financials'!K32 -> 4606 | M25: ='Consolidated Financials'!L32 -> 2239 | N25: ='Consolidated Financials'!M32 -> 857 | O25: =SUM('Consolidated Financials'!U32:X32) -> 151.26373 | P25: =Q25-O25 -> 2568.5738 | Q25: ='Consolidated Financials'!N32 -> 2719.8375 | R25: ='Consolidated Financials'!O32 -> 1959.1037 | AU25: x
C26: Finance costs | K26: ='Consolidated Financials'!J33 -> -759 | L26: ='Consolidated Financials'!K33 -> -435 | M26: ='Consolidated Financials'!L33 -> -240 | N26: ='Consolidated Financials'!M33 -> -144 | O26: =SUM('Consolidated Financials'!U33:X33) -> -632.07287 | P26: =Q26-O26 -> 432.59772 | Q26: ='Consolidated Financials'!N33 -> -199.47515 | R26: ='Consolidated Financials'!O33 -> -193.09421 | AU26: x
C27: Share of loss of associates | K27: ='Consolidated Financials'!J34 -> 0 | L27: ='Consolidated Financials'!K34 -> -1104 | M27: ='Consolidated Financials'!L34 -> -27 | N27: ='Consolidated Financials'!M34 -> -164 | O27: =SUM('Consolidated Financials'!U34:X34) -> 0 | P27: =Q27-O27 -> 0 | Q27: ='Consolidated Financials'!N34 -> 0 | R27: ='Consolidated Financials'!O34 -> 0 | AU27: x
C28: Accretion of redeemable capital contributions | K28: ='Consolidated Financials'!J35 -> -58660 | L28: ='Consolidated Financials'!K35 -> -58660 | M28: ='Consolidated Financials'!L35 -> -53838 | N28: ='Consolidated Financials'!M35 -> 0 | O28: =SUM('Consolidated Financials'!U35:X35) -> 0 | P28: =Q28-O28 -> 0 | Q28: ='Consolidated Financials'!N35 -> 0 | R28: ='Consolidated Financials'!O35 -> 0 | AU28: x
C29: Profit/(Loss) before taxation | K29: =SUM(K25:K28,K23) -> -110918.94 | L29: =SUM(L25:L28,L23) -> -95966.194 | M29: =SUM(M25:M28,M23) -> -111699.46 | N29: =SUM(N25:N28,N23) -> -25915.105 | O29: =SUM(O25:O28,O23) -> -25787.553 | P29: =SUM(P25:P28,P23) -> 17342.518 | Q29: =SUM(Q25:Q28,Q23) -> -8445.0357 | R29: =SUM(R25:R28,R23) -> -14455.196 | AU29: x
AU30: x
C31: Income tax | K31: ='Consolidated Financials'!J39 -> -134 | L31: ='Consolidated Financials'!K39 -> 60 | M31: ='Consolidated Financials'!L39 -> 0 | N31: ='Consolidated Financials'!M39 -> 0 | O31: =SUM('Consolidated Financials'!U39:X39) -> 0 | P31: =Q31-O31 -> 0 | Q31: ='Consolidated Financials'!N39 -> 0 | R31: ='Consolidated Financials'!O39 -> 0 | AU31: x
AU32: x
C33: Profit/(Loss) for the year/period | K33: =K29+K31 -> -111052.94 | L33: =L29+L31 -> -95906.194 | M33: =M29+M31 -> -111699.46 | N33: =N29+N31 -> -25915.105 | O33: =O29+O31 -> -25787.553 | P33: =P29+P31 -> 17342.518 | Q33: =Q29+Q31 -> -8445.0357 | R33: =R29+R31 -> -14455.196 | AU33: x
C34: Attributable to: | AU34: x
AU35: x
C36: Equity shareholders of the Company | K36: =K33 -> -111052.94 | L36: =L33 -> -95906.194 | M36: =M33 -> -111699.46 | N36: =N33 -> -25915.105 | O36: =SUM('Consolidated Financials'!U45:X45) -> -25787.553 | P36: =Q36-O36 -> 17342.518 | Q36: =Q33 -> -8445.0357 | R36: =R33 -> -14455.196 | AU36: x
AU37: x
C38: Other comprehensive income for the year | AU38: x
AU39: x
C40: Exchange differences on translation of financial statements of a foreign subsidiary, net of nil tax | K40: ='Consolidated Financials'!J51 -> 0 | L40: ='Consolidated Financials'!K51 -> 0 | M40: ='Consolidated Financials'!L51 -> 0 | N40: ='Consolidated Financials'!M51 -> -475 | O40: =SUM('Consolidated Financials'!U51:X51) -> 73.03884 | P40: =Q40-O40 -> 0 | Q40: ='Consolidated Financials'!N51 -> 73.03884 | R40: ='Consolidated Financials'!O51 -> 0 | AU40: x
...

Sheet Cash Burn&CCC
A1: Blue: Hard code vale
A2: Black: Calculation
A3: Green: Linked from another tab
A4: Red: Linked from the same tab
C6: Cash burn rate
C7: RMB'000
C8: Cash burn rate | D8: 1.16
C10: Cash balance as of 31 Dec 2025 | D10: ='Consolidated Financials'!M135 -> 217756
C11: Average monthly net cash used in operating activities | D11: =$D$8*D31 -> -11830.786
C12: Average monthly capital expenditures | D12: =$D$8*D32 -> -13.05
C13: Average other scheduled cash payment | D13: =$D$8*D33 -> -241.5207
C14: Average Interest payment | D14: =$D$8*D34 -> -13.92
C15: Net IPO proceeds | D15: =Control!H30 -> 1118012.8
C18: Average cash outflow in 2023 | D18: =SUM(D19:D22) -> -5375.167 | F18: =D18/$D$48 -> 1.1325841
C19: Average monthly net cash used in operating activities | D19: ='Consolidated Financials'!K101/12 -> -4234.0003
C20: Average monthly purchase of property, plant and equipment | D20: ='Consolidated Financials'!K105/12 -> -620.91667
C21: Average monthly capital element of lease rental paid | D21: ='Consolidated Financials'!K120/12 -> -484
C22: Average monthly interest element of lease rental paid | D22: ='Consolidated Financials'!K121/12 -> -36.25
C24: Average cash outflow in 2024 | D24: =SUM(D25:D28) -> -7446.3333 | F24: =D24/$D$48 -> 1.5689929
C25: Average monthly net cash used in operating activities | D25: ='Consolidated Financials'!L101/12 -> -6851.3333
C26: Average monthly purchase of property, plant and equipment | D26: ='Consolidated Financials'!L105/12 -> -266.75
C27: Average monthly capital element of lease rental paid | D27: ='Consolidated Financials'!L120/12 -> -308.25
C28: Average monthly interest element of lease rental paid | D28: ='Consolidated Financials'!L121/12 -> -20
C30: Average cash outflow in 2025 | D30: =SUM(D31:D34) -> -10430.411 | F30: =D30/$D$48 -> 2.1977582
C31: Average monthly net cash used in operating activities | D31: ='Consolidated Financials'!M101/12 -> -10198.953
C32: Average monthly purchase of property, plant and equipment | D32: ='Consolidated Financials'!M105/12 -> -11.25
C33: Average monthly capital element of lease rental paid | D33: ='Consolidated Financials'!M120/12 -> -208.2075
C34: Average monthly interest element of lease rental paid | D34: ='Consolidated Financials'!M121/12 -> -12
C36: Average cash outflow from 1 Mar 2026 to 30 June 2027 | D36: =SUM(D37:D40) -> -7029.4081
C37: Average monthly net Cash used in operating activities (Litsting expense included) | D37: =SUM('Consolidated Financials'!W101:AL101)/16 -> -5390.0159
C38: Average monthly purchase of property, plant and equipment | D38: =SUM('Consolidated Financials'!W105:AL105)/16 -> -1238.8187
C39: Average monthly capital element of lease rental paid | D39: =SUM('Consolidated Financials'!W120:AL120)/16 -> -397.42548
C40: Average monthly interest element of lease rental paid | D40: =SUM('Consolidated Financials'!W121:AL121)/16 -> -3.1479703
C42: Average cash outflow from 1 Mar 2026 to 31 Dec 2026 | D42: =SUM(D43:D46) -> -3573.0606
C43: Average monthly net Cash used in operating activities (Litsting expense included) | D43: =SUM('Consolidated Financials'!W101:AF101)/10 -> -2520.7368
C44: Average monthly purchase of property, plant and equipment | D44: =SUM('Consolidated Financials'!W105:AF105)/10 -> -797.5947
C45: Average monthly capital element of lease rental paid | D45: =SUM('Consolidated Financials'!W120:AF120)/10 -> -269.00177
C46: Average monthly interest element of lease rental paid | D46: =SUM('Consolidated Financials'!W121:AF121)/10 -> 14.272668
C48: Average cash outflow from 1 Jan 2026 to 31 Dec 2026 | D48: =SUM(D49:D52) -> -4745.9319 | F48: =$D$48/D48 -> 1
C49: Average monthly net Cash used in operating activities (Litsting expense included) | D49: =SUM('Consolidated Financials'!U101:AF101)/12 -> -3748.811
...

Sheet Working Capital Output_0319
A1: Blue: Hard code vale
A2: Black: Calculation
A3: Green: Linked from another tab
A4: Red: Linked from the same tab
E7: 2022 | F7: =E7+1 -> 2023 | G7: =F7+1 -> 2024 | H7: =G7+1 -> 2025 | I7: =H7+1 -> 2026 | J7: 2027 H1 | O7: 46023 | P7: =EDATE(O7,1) -> 46054 | Q7: =EDATE(P7,1) -> 46082 | R7: =EDATE(Q7,1) -> 46113 | S7: =EDATE(R7,1) -> 46143 | T7: =EDATE(S7,1) -> 46174 | U7: =EDATE(T7,1) -> 46204 | V7: =EDATE(U7,1) -> 46235 | W7: =EDATE(V7,1) -> 46266 | ... Z7: =EDATE(Y7,1) -> 46357 | AA7: 2026 | AB7: =EDATE(Z7,1) -> 46388 | AC7: =EDATE(AB7,1) -> 46419 | AD7: =EDATE(AC7,1) -> 46447 | AE7: =EDATE(AD7,1) -> 46478 | AF7: =EDATE(AE7,1) -> 46508 | AG7: =EDATE(AF7,1) -> 46539 | AH7: 2027 H1
E8: Actual | F8: Actual | G8: Actual | H8: Actual | I8: Forecast | J8: Forecast | O8: Estimate | P8: Estimate | Q8: Estimate | R8: Estimate | S8: Forecast | T8: Forecast | U8: Forecast | V8: Forecast | W8: Forecast | X8: Forecast | Y8: Forecast | Z8: Forecast | AA8: Forecast | AB8: Forecast | AC8: Forecast | AD8: Forecast | AE8: Forecast | AF8: Forecast | AG8: Forecast | AH8: Forecast
E9: Actual | F9: Actual | G9: Actual
C10: Working Capital Forecast for the year ending December 31, 2026
C11: (In RMB thousands)
C12: Operating activities
C13: Profit (Loss) before taxation | E13: ='Consolidated Financials'!J67 -> -110918.94 | F13: ='Consolidated Financials'!K67 -> -95967 | G13: ='Consolidated Financials'!L67 -> -111699 | H13: ='Consolidated Financials'!M67 -> -25915 | I13: ='Consolidated Financials'!N67 -> -8445.0357 | J13: ='Consolidated Financials'!O67 -> -14455.196 | O13: ='Consolidated Financials'!U67 -> 9724.9118 | P13: ='Consolidated Financials'!V67 -> -15019.423 | Q13: ='Consolidated Financials'!W67 -> -10763.644 | R13: ='Consolidated Financials'!X67 -> -9729.3977 | S13: ='Consolidated Financials'!Y67 -> -3128.8664 | T13: ='Consolidated Financials'!Z67 -> -7962.4015 | U13: ='Consolidated Financials'!AA67 -> 4257.32 | V13: ='Consolidated Financials'!AB67 -> 4464.8044 | ... Z13: ='Consolidated Financials'!AF67 -> 5023.8129 | AA13: =SUM(O13:Z13) -> -8445.0357 | AB13: ='Consolidated Financials'!AG67 -> -3333.9765 | AC13: ='Consolidated Financials'!AH67 -> -2224.4783 | AD13: ='Consolidated Financials'!AI67 -> -3201.6609 | AE13: ='Consolidated Financials'!AJ67 -> -2229.719 | AF13: ='Consolidated Financials'!AK67 -> -2232.3394 | AG13: ='Consolidated Financials'!AL67 -> -1233.0216 | AH13: =SUM(AB13:AG13) -> -14455.196
C14: Adjustments for:
C15: Depreciation of property, plant and equipment | E15: ='Consolidated Financials'!J70 -> 6257 | F15: ='Consolidated Financials'!K70 -> 7446 | G15: ='Consolidated Financials'!L70 -> 7276 | H15: ='Consolidated Financials'!M70 -> 5231 | I15: ='Consolidated Financials'!N70 -> 2964.4784 | J15: ='Consolidated Financials'!O70 -> 3290.6838 | O15: ='Consolidated Financials'!U70 -> 301.5731 | P15: ='Consolidated Financials'!V70 -> 323.922 | Q15: ='Consolidated Financials'!W70 -> 301.3447 | R15: ='Consolidated Financials'!X70 -> 300.6981 | S15: ='Consolidated Financials'!Y70 -> 152.5795 | T15: ='Consolidated Financials'!Z70 -> 152.5795 | U15: ='Consolidated Financials'!AA70 -> 152.5795 | V15: ='Consolidated Financials'!AB70 -> 186.9998 | ... Z15: ='Consolidated Financials'!AF70 -> 324.681 | AA15: =SUM(O15:Z15) -> 2964.4784 | AB15: ='Consolidated Financials'!AG70 -> 419.37117 | AC15: ='Consolidated Financials'!AH70 -> 471.00162 | AD15: ='Consolidated Financials'!AI70 -> 522.63207 | AE15: ='Consolidated Financials'!AJ70 -> 574.26252 | AF15: ='Consolidated Financials'!AK70 -> 625.89297 | AG15: ='Consolidated Financials'!AL70 -> 677.52342 | AH15: =SUM(AB15:AG15) -> 3290.6838
C16: Depreciation of right-of-use assets | E16: ='Consolidated Financials'!J71 -> 7345 | F16: ='Consolidated Financials'!K71 -> 7398 | G16: ='Consolidated Financials'!L71 -> 5887 | H16: ='Consolidated Financials'!M71 -> 3654 | I16: ='Consolidated Financials'!N71 -> 3917.495 | J16: ='Consolidated Financials'!O71 -> 3738.8893 | O16: ='Consolidated Financials'!U71 -> 243.7 | P16: ='Consolidated Financials'!V71 -> 242.72691 | Q16: ='Consolidated Financials'!W71 -> 1158.4019 | R16: ='Consolidated Financials'!X71 -> 140.98527 | S16: ='Consolidated Financials'!Y71 -> 266.46012 | T16: ='Consolidated Financials'!Z71 -> 266.46012 | U16: ='Consolidated Financials'!AA71 -> 266.46012 | V16: ='Consolidated Financials'!AB71 -> 266.46012 | ... Z16: ='Consolidated Financials'!AF71 -> 266.46012 | AA16: =SUM(O16:Z16) -> 3917.495 | AB16: ='Consolidated Financials'!AG71 -> 623.14821 | AC16: ='Consolidated Financials'!AH71 -> 623.14821 | AD16: ='Consolidated Financials'!AI71 -> 623.14821 | AE16: ='Consolidated Financials'!AJ71 -> 623.14821 | AF16: ='Consolidated Financials'!AK71 -> 623.14821 | AG16: ='Consolidated Financials'!AL71 -> 623.14821 | AH16: =SUM(AB16:AG16) -> 3738.8893
C17: Amortisation of intangible assets | E17: ='Consolidated Financials'!J72 -> 747 | F17: ='Consolidated Financials'!K72 -> 553 | G17: ='Consolidated Financials'!L72 -> 220 | H17: ='Consolidated Financials'!M72 -> 74.56 | I17: ='Consolidated Financials'!N72 -> 74.56 | J17: ='Consolidated Financials'!O72 -> 37.28 | O17: ='Consolidated Financials'!U72 -> 6.4999 | P17: ='Consolidated Financials'!V72 -> 6.27 | Q17: ='Consolidated Financials'!W72 -> 6.251 | R17: ='Consolidated Financials'!X72 -> 6.268 | S17: ='Consolidated Financials'!Y72 -> 6.1588875 | T17: ='Consolidated Financials'!Z72 -> 6.1588875 | U17: ='Consolidated Financials'!AA72 -> 6.1588875 | V17: ='Consolidated Financials'!AB72 -> 6.1588875 | ... Z17: ='Consolidated Financials'!AF72 -> 6.1588875 | AA17: =SUM(O17:Z17) -> 74.56 | AB17: ='Consolidated Financials'!AG72 -> 6.2133333 | AC17: ='Consolidated Financials'!AH72 -> 6.2133333 | AD17: ='Consolidated Financials'!AI72 -> 6.2133333 | AE17: ='Consolidated Financials'!AJ72 -> 6.2133333 | AF17: ='Consolidated Financials'!AK72 -> 6.2133333 | AG17: ='Consolidated Financials'!AL72 -> 6.2133333 | AH17: =SUM(AB17:AG17) -> 37.28
C18: Impairment loss on trade and other receivables and contract assets | E18: ='Consolidated Financials'!J73 -> 3553 | F18: ='Consolidated Financials'!K73 -> 11749.996 | G18: ='Consolidated Financials'!L73 -> 21170 | H18: ='Consolidated Financials'!M73 -> 27595 | I18: ='Consolidated Financials'!N73 -> 26864.821 | J18: ='Consolidated Financials'!O73 -> 10970.471 | O18: ='Consolidated Financials'!U73 -> 4813.1893 | P18: ='Consolidated Financials'!V73 -> -1121.2699 | Q18: ='Consolidated Financials'!W73 -> 2171.1621 | R18: ='Consolidated Financials'!X73 -> -2435.3079 | S18: ='Consolidated Financials'!Y73 -> 1035.5685 | T18: ='Consolidated Financials'!Z73 -> 2962.919 | U18: ='Consolidated Financials'!AA73 -> 3205.7096 | V18: ='Consolidated Financials'!AB73 -> 3103.7754 | ... Z18: ='Consolidated Financials'!AF73 -> 3433.7995 | AA18: =SUM(O18:Z18) -> 26864.821 | AB18: ='Consolidated Financials'!AG73 -> 2026.5909 | AC18: ='Consolidated Financials'!AH73 -> 1713.9302 | AD18: ='Consolidated Financials'!AI73 -> 1987.9184 | AE18: ='Consolidated Financials'!AJ73 -> 1713.9302 | AF18: ='Consolidated Financials'!AK73 -> 1713.9302 | AG18: ='Consolidated Financials'!AL73 -> 1814.1713 | AH18: =SUM(AB18:AG18) -> 10970.471
C19: Government grants | E19: ='Consolidated Financials'!J77 -> -4629 | F19: ='Consolidated Financials'!K77 -> -2430 | G19: ='Consolidated Financials'!L77 -> -2552 | H19: ='Consolidated Financials'!M77 -> 0 | I19: ='Consolidated Financials'!N77 -> 0 | J19: ='Consolidated Financials'!O77 -> 0 | O19: ='Consolidated Financials'!U77 -> 0 | P19: ='Consolidated Financials'!V77 -> 0 | Q19: ='Consolidated Financials'!W77 -> 0 | R19: ='Consolidated Financials'!X77 -> 0 | S19: ='Consolidated Financials'!Y77 -> 0 | T19: ='Consolidated Financials'!Z77 -> 0 | U19: ='Consolidated Financials'!AA77 -> 0 | V19: ='Consolidated Financials'!AB77 -> 0 | ... Z19: ='Consolidated Financials'!AF77 -> 0 | AA19: =SUM(O19:Z19) -> 0 | AB19: ='Consolidated Financials'!AG77 -> 0 | AC19: ='Consolidated Financials'!AH77 -> 0 | AD19: ='Consolidated Financials'!AI77 -> 0 | AE19: ='Consolidated Financials'!AJ77 -> 0 | AF19: ='Consolidated Financials'!AK77 -> 0 | AG19: ='Consolidated Financials'!AL77 -> 0 | AH19: =SUM(AB19:AG19) -> 0
C20: Finance income | E20: ='Consolidated Financials'!J78 -> -9458 | F20: ='Consolidated Financials'!K78 -> -4606 | G20: ='Consolidated Financials'!L78 -> -2239 | H20: ='Consolidated Financials'!M78 -> -857 | I20: ='Consolidated Financials'!N78 -> -2719.8375 | J20: ='Consolidated Financials'!O78 -> -1959.1037 | O20: ='Consolidated Financials'!U78 -> -0.000913536 | P20: ='Consolidated Financials'!V78 -> -0.17778724 | Q20: ='Consolidated Financials'!W78 -> -150.58093 | R20: ='Consolidated Financials'!X78 -> -0.50410647 | S20: ='Consolidated Financials'!Y78 -> -81.092033 | T20: ='Consolidated Financials'!Z78 -> -360.59522 | U20: ='Consolidated Financials'!AA78 -> -358.84833 | V20: ='Consolidated Financials'!AB78 -> -357.10143 | ... Z20: ='Consolidated Financials'!AF78 -> -350.11385 | AA20: =SUM(O20:Z20) -> -2719.8375 | AB20: ='Consolidated Financials'!AG78 -> -333.06814 | AC20: ='Consolidated Financials'!AH78 -> -330.4478 | AD20: ='Consolidated Financials'!AI78 -> -327.82746 | AE20: ='Consolidated Financials'!AJ78 -> -325.20712 | AF20: ='Consolidated Financials'!AK78 -> -322.58677 | AG20: ='Consolidated Financials'!AL78 -> -319.96643 | AH20: =SUM(AB20:AG20) -> -1959.1037
C21: Finance costs | E21: ='Consolidated Financials'!J79 -> 759 | F21: ='Consolidated Financials'!K79 -> 435 | G21: ='Consolidated Financials'!L79 -> 240 | H21: ='Consolidated Financials'!M79 -> 144 | I21: ='Consolidated Financials'!N79 -> 199.47515 | J21: ='Consolidated Financials'!O79 -> 193.09421 | O21: ='Consolidated Financials'!U79 -> 133.213 | P21: ='Consolidated Financials'!V79 -> 208.98883 | Q21: ='Consolidated Financials'!W79 -> 167.66132 | R21: ='Consolidated Financials'!X79 -> 122.20971 | S21: ='Consolidated Financials'!Y79 -> -19.114378 | T21: ='Consolidated Financials'!Z79 -> -54.689142 | U21: ='Consolidated Financials'!AA79 -> -59.170536 | V21: ='Consolidated Financials'!AB79 -> -57.28905 | ... Z21: ='Consolidated Financials'!AF79 -> -63.380586 | AA21: =SUM(O21:Z21) -> 199.47515 | AB21: ='Consolidated Financials'!AG79 -> 35.67057 | AC21: ='Consolidated Financials'!AH79 -> 30.167346 | AD21: ='Consolidated Financials'!AI79 -> 34.989884 | AE21: ='Consolidated Financials'!AJ79 -> 30.167346 | AF21: ='Consolidated Financials'!AK79 -> 30.167346 | AG21: ='Consolidated Financials'!AL79 -> 31.931715 | AH21: =SUM(AB21:AG21) -> 193.09421
C22: Accretion of redemption liabilities | E22: ='Consolidated Financials'!J80 -> 58660 | F22: ='Consolidated Financials'!K80 -> 58660 | G22: ='Consolidated Financials'!L80 -> 53838 | H22: ='Consolidated Financials'!M80 -> 0 | I22: ='Consolidated Financials'!N80 -> 0 | J22: ='Consolidated Financials'!O80 -> 0 | O22: ='Consolidated Financials'!U80 -> 0 | P22: ='Consolidated Financials'!V80 -> 0 | Q22: ='Consolidated Financials'!W80 -> 0 | R22: ='Consolidated Financials'!X80 -> 0 | S22: ='Consolidated Financials'!Y80 -> 0 | T22: ='Consolidated Financials'!Z80 -> 0 | U22: ='Consolidated Financials'!AA80 -> 0 | V22: ='Consolidated Financials'!AB80 -> 0 | ... Z22: ='Consolidated Financials'!AF80 -> 0 | AA22: =SUM(O22:Z22) -> 0 | AB22: ='Consolidated Financials'!AG80 -> 0 | AC22: ='Consolidated Financials'!AH80 -> 0 | AD22: ='Consolidated Financials'!AI80 -> 0 | AE22: ='Consolidated Financials'!AJ80 -> 0 | AF22: ='Consolidated Financials'!AK80 -> 0 | AG22: ='Consolidated Financials'!AL80 -> 0 | AH22: =SUM(AB22:AG22) -> 0
C23: Equity-settled share-based payment expenses | E23: ='Consolidated Financials'!J81 -> 6172 | F23: ='Consolidated Financials'!K81 -> 7835 | G23: ='Consolidated Financials'!L81 -> 21479 | H23: ='Consolidated Financials'!M81 -> 21437 | I23: ='Consolidated Financials'!N81 -> 13710.25 | J23: ='Consolidated Financials'!O81 -> 1228.7184 | O23: ='Consolidated Financials'!U81 -> 1142.5208 | P23: ='Consolidated Financials'!V81 -> 1142.5208 | Q23: ='Consolidated Financials'!W81 -> 1142.5208 | R23: ='Consolidated Financials'!X81 -> 1142.5208 | S23: ='Consolidated Financials'!Y81 -> 1142.5208 | T23: ='Consolidated Financials'!Z81 -> 1142.5208 | U23: ='Consolidated Financials'!AA81 -> 1142.5208 | V23: ='Consolidated Financials'!AB81 -> 1142.5208 | ... Z23: ='Consolidated Financials'!AF81 -> 1142.5208 | AA23: =SUM(O23:Z23) -> 13710.25 | AB23: ='Consolidated Financials'!AG81 -> 204.7864 | AC23: ='Consolidated Financials'!AH81 -> 204.7864 | AD23: ='Consolidated Financials'!AI81 -> 204.7864 | AE23: ='Consolidated Financials'!AJ81 -> 204.7864 | AF23: ='Consolidated Financials'!AK81 -> 204.7864 | AG23: ='Consolidated Financials'!AL81 -> 204.7864 | AH23: =SUM(AB23:AG23) -> 1228.7184
C24: Net gain on disposal of property, plant and equipment | E24: ='Consolidated Financials'!J82 -> 0 | F24: ='Consolidated Financials'!K82 -> -48 | G24: ='Consolidated Financials'!L82 -> -15 | H24: ='Consolidated Financials'!M82 -> 0 | I24: ='Consolidated Financials'!N82 -> 0 | J24: ='Consolidated Financials'!O82 -> 0 | O24: ='Consolidated Financials'!U82 -> 0 | P24: ='Consolidated Financials'!V82 -> 0 | Q24: ='Consolidated Financials'!W82 -> 0 | R24: ='Consolidated Financials'!X82 -> 0 | S24: ='Consolidated Financials'!Y82 -> 0 | T24: ='Consolidated Financials'!Z82 -> 0 | U24: ='Consolidated Financials'!AA82 -> 0 | V24: ='Consolidated Financials'!AB82 -> 0 | ... Z24: ='Consolidated Financials'!AF82 -> 0 | AA24: =SUM(O24:Z24) -> 0 | AB24: ='Consolidated Financials'!AG82 -> 0 | AC24: ='Consolidated Financials'!AH82 -> 0 | AD24: ='Consolidated Financials'!AI82 -> 0 | AE24: ='Consolidated Financials'!AJ82 -> 0 | AF24: ='Consolidated Financials'!AK82 -> 0 | AG24: ='Consolidated Financials'!AL82 -> 0 | AH24: =SUM(AB24:AG24) -> 0
C25: Share of loss of associates | E25: ='Consolidated Financials'!J83 -> 0 | F25: ='Consolidated Financials'!K83 -> 1104 | G25: ='Consolidated Financials'!L83 -> 27 | H25: ='Consolidated Financials'!M83 -> 164 | I25: ='Consolidated Financials'!N83 -> 0 | J25: ='Consolidated Financials'!O83 -> 0 | O25: ='Consolidated Financials'!U83 -> 0 | P25: ='Consolidated Financials'!V83 -> 0 | Q25: ='Consolidated Financials'!W83 -> 0 | R25: ='Consolidated Financials'!X83 -> 0 | S25: ='Consolidated Financials'!Y83 -> 0 | T25: ='Consolidated Financials'!Z83 -> 0 | U25: ='Consolidated Financials'!AA83 -> 0 | V25: ='Consolidated Financials'!AB83 -> 0 | ... Z25: ='Consolidated Financials'!AF83 -> 0 | AA25: =SUM(O25:Z25) -> 0 | AB25: ='Consolidated Financials'!AG83 -> 0 | AC25: ='Consolidated Financials'!AH83 -> 0 | AD25: ='Consolidated Financials'!AI83 -> 0 | AE25: ='Consolidated Financials'!AJ83 -> 0 | AF25: ='Consolidated Financials'!AK83 -> 0 | AG25: ='Consolidated Financials'!AL83 -> 0 | AH25: =SUM(AB25:AG25) -> 0
C26: Net foreign exchange loss/(gain) | E26: ='Consolidated Financials'!J84 -> 0 | F26: ='Consolidated Financials'!K84 -> 0 | G26: ='Consolidated Financials'!L84 -> 0 | H26: ='Consolidated Financials'!M84 -> 0 | I26: ='Consolidated Financials'!N84 -> 0 | J26: ='Consolidated Financials'!O84 -> 0 | O26: ='Consolidated Financials'!U84 -> 0 | P26: ='Consolidated Financials'!V84 -> 0 | Q26: ='Consolidated Financials'!W84 -> 0 | R26: ='Consolidated Financials'!X84 -> 0 | S26: ='Consolidated Financials'!Y84 -> 0 | T26: ='Consolidated Financials'!Z84 -> 0 | U26: ='Consolidated Financials'!AA84 -> 0 | V26: ='Consolidated Financials'!AB84 -> 0 | ... Z26: ='Consolidated Financials'!AF84 -> 0 | AA26: =SUM(O26:Z26) -> 0 | AB26: ='Consolidated Financials'!AG84 -> 0 | AC26: ='Consolidated Financials'!AH84 -> 0 | AD26: ='Consolidated Financials'!AI84 -> 0 | AE26: ='Consolidated Financials'!AJ84 -> 0 | AF26: ='Consolidated Financials'!AK84 -> 0 | AG26: ='Consolidated Financials'!AL84 -> 0 | AH26: =SUM(AB26:AG26) -> 0
C27: Net gain on disposal of an associate | E27: ='Consolidated Financials'!J85 -> 0 | F27: ='Consolidated Financials'!K85 -> 0 | G27: ='Consolidated Financials'!L85 -> 0 | H27: ='Consolidated Financials'!M85 -> -801 | I27: ='Consolidated Financials'!N85 -> 0 | J27: ='Consolidated Financials'!O85 -> 0 | O27: ='Consolidated Financials'!U85 -> 0 | P27: ='Consolidated Financials'!V85 -> 0 | Q27: ='Consolidated Financials'!W85 -> 0 | R27: ='Consolidated Financials'!X85 -> 0 | S27: ='Consolidated Financials'!Y85 -> 0 | T27: ='Consolidated Financials'!Z85 -> 0 | U27: ='Consolidated Financials'!AA85 -> 0 | V27: ='Consolidated Financials'!AB85 -> 0 | ... Z27: ='Consolidated Financials'!AF85 -> 0 | AA27: =SUM(O27:Z27) -> 0 | AB27: ='Consolidated Financials'!AG85 -> 0 | AC27: ='Consolidated Financials'!AH85 -> 0 | AD27: ='Consolidated Financials'!AI85 -> 0 | AE27: ='Consolidated Financials'!AJ85 -> 0 | AF27: ='Consolidated Financials'!AK85 -> 0 | AG27: ='Consolidated Financials'!AL85 -> 0 | AH27: =SUM(AB27:AG27) -> 0
C29: Changes in working capital:
C30: Decrease/(increase) in inventories | E30: ='Consolidated Financials'!J88 -> 1185 | F30: ='Consolidated Financials'!K88 -> -14696 | G30: ='Consolidated Financials'!L88 -> -27374 | H30: ='Consolidated Financials'!M88 -> -36840 | I30: ='Consolidated Financials'!N88 -> -3223.0313 | J30: ='Consolidated Financials'!O88 -> -18068.237 | O30: ='Consolidated Financials'!U88 -> 25913.608 | P30: ='Consolidated Financials'!V88 -> 9571.5609 | Q30: ='Consolidated Financials'!W88 -> 792.67309 | R30: ='Consolidated Financials'!X88 -> -27789.275 | S30: ='Consolidated Financials'!Y88 -> -517.47824 | T30: ='Consolidated Financials'!Z88 -> -1480.584 | U30: ='Consolidated Financials'!AA88 -> -1601.9075 | V30: ='Consolidated Financials'!AB88 -> -1550.9705 | ... Z30: ='Consolidated Financials'!AF88 -> -1715.885 | AA30: =SUM(O30:Z30) -> -3223.0313 | AB30: ='Consolidated Financials'!AG88 -> -3337.7713 | AC30: ='Consolidated Financials'!AH88 -> -2822.8229 | AD30: ='Consolidated Financials'!AI88 -> -3274.0781 | AE30: ='Consolidated Financials'!AJ88 -> -2822.8229 | AF30: ='Consolidated Financials'!AK88 -> -2822.8229 | AG30: ='Consolidated Financials'!AL88 -> -2987.9188 | AH30: =SUM(AB30:AG30) -> -18068.237
C31: (Increase)/decrease in trade receivables | E31: ='Consolidated Financials'!J89 -> -31960 | F31: ='Consolidated Financials'!K89 -> -101153 | G31: ='Consolidated Financials'!L89 -> -106824 | H31: ='Consolidated Financials'!M89 -> -76224 | I31: ='Consolidated Financials'!N89 -> -126665.46 | J31: ='Consolidated Financials'!O89 -> 15839.282 | O31: ='Consolidated Financials'!U89 -> -20685.835 | P31: ='Consolidated Financials'!V89 -> 6926.905 | Q31: ='Consolidated Financials'!W89 -> 31415.93 | R31: ='Consolidated Financials'!X89 -> 37629 | S31: ='Consolidated Financials'!Y89 -> -8039.5456 | T31: ='Consolidated Financials'!Z89 -> -23002.363 | U31: ='Consolidated Financials'!AA89 -> -24887.246 | V31: ='Consolidated Financials'!AB89 -> -24095.889 | ... Z31: ='Consolidated Financials'!AF89 -> -26658.001 | AA31: =SUM(O31:Z31) -> -126665.46 | AB31: ='Consolidated Financials'!AG89 -> 2926.0132 | AC31: ='Consolidated Financials'!AH89 -> 2474.5905 | AD31: ='Consolidated Financials'!AI89 -> 2870.1774 | AE31: ='Consolidated Financials'!AJ89 -> 2474.5905 | AF31: ='Consolidated Financials'!AK89 -> 2474.5905 | AG31: ='Consolidated Financials'!AL89 -> 2619.3196 | AH31: =SUM(AB31:AG31) -> 15839.282
C32: (Increase) /decrease in contract assets | E32: ='Consolidated Financials'!J90 -> -508 | F32: ='Consolidated Financials'!K90 -> -5095 | G32: ='Consolidated Financials'!L90 -> -2540 | H32: ='Consolidated Financials'!M90 -> -12977 | I32: ='Consolidated Financials'!N90 -> -21826.4 | J32: ='Consolidated Financials'!O90 -> -12389.534 | O32: ='Consolidated Financials'!U90 -> -500 | P32: ='Consolidated Financials'!V90 -> -28.73 | Q32: ='Consolidated Financials'!W90 -> -972.79931 | R32: ='Consolidated Financials'!X90 -> 10691.815 | S32: ='Consolidated Financials'!Y90 -> -1370.4757 | T32: ='Consolidated Financials'!Z90 -> -3921.1393 | U32: ='Consolidated Financials'!AA90 -> -4242.4493 | V32: ='Consolidated Financials'!AB90 -> -4107.5492 | ... Z32: ='Consolidated Financials'!AF90 -> -4544.3044 | AA32: =SUM(O32:Z32) -> -21826.4 | AB32: ='Consolidated Financials'!AG90 -> -2288.7364 | AC32: ='Consolidated Financials'!AH90 -> -1935.6321 | AD32: ='Consolidated Financials'!AI90 -> -2245.0615 | AE32: ='Consolidated Financials'!AJ90 -> -1935.6321 | AF32: ='Consolidated Financials'!AK90 -> -1935.6321 | AG32: ='Consolidated Financials'!AL90 -> -2048.8397 | AH32: =SUM(AB32:AG32) -> -12389.534
C33: (Increase)/decrease in prepayments, deposits and other receivables | E33: ='Consolidated Financials'!J91 -> -51558 | F33: ='Consolidated Financials'!K91 -> -12736 | G33: ='Consolidated Financials'!L91 -> 31502 | H33: ='Consolidated Financials'!M91 -> -33467 | I33: ='Consolidated Financials'!N91 -> -22414.879 | J33: ='Consolidated Financials'!O91 -> 22179.336 | O33: ='Consolidated Financials'!U91 -> -15507.151 | P33: ='Consolidated Financials'!V91 -> 29805.871 | Q33: ='Consolidated Financials'!W91 -> -21957.924 | R33: ='Consolidated Financials'!X91 -> 4090.3563 | S33: ='Consolidated Financials'!Y91 -> -422.08052 | T33: ='Consolidated Financials'!Z91 -> -1207.6366 | U33: ='Consolidated Financials'!AA91 -> -3263.1163 | V33: ='Consolidated Financials'!AB91 -> -3058.5261 | ... Z33: ='Consolidated Financials'!AF91 -> -2540.8643 | AA33: =SUM(O33:Z33) -> -22414.879 | AB33: ='Consolidated Financials'!AG91 -> 3631.6018 | AC33: ='Consolidated Financials'!AH91 -> 3014.0362 | AD33: ='Consolidated Financials'!AI91 -> 4014.0967 | AE33: ='Consolidated Financials'!AJ91 -> 3503.1667 | AF33: ='Consolidated Financials'!AK91 -> 3747.732 | AG33: ='Consolidated Financials'!AL91 -> 4268.7022 | AH33: =SUM(AB33:AG33) -> 22179.336
C34: (Increase)/decrease in restricted bank deposits | E34: ='Consolidated Financials'!J92 -> -3 | F34: ='Consolidated Financials'!K92 -> 3 | G34: ='Consolidated Financials'!L92 -> -1412 | H34: ='Consolidated Financials'!M92 -> 1412 | I34: ='Consolidated Financials'!N92 -> 0 | J34: ='Consolidated Financials'!O92 -> 0 | O34: ='Consolidated Financials'!U92 -> 0 | P34: ='Consolidated Financials'!V92 -> 0 | Q34: ='Consolidated Financials'!W92 -> 0 | R34: ='Consolidated Financials'!X92 -> 0 | S34: ='Consolidated Financials'!Y92 -> 0 | T34: ='Consolidated Financials'!Z92 -> 0 | U34: ='Consolidated Financials'!AA92 -> 0 | V34: ='Consolidated Financials'!AB92 -> 0 | ... Z34: ='Consolidated Financials'!AF92 -> 0 | AA34: =SUM(O34:Z34) -> 0 | AB34: ='Consolidated Financials'!AG92 -> 0 | AC34: ='Consolidated Financials'!AH92 -> 0 | AD34: ='Consolidated Financials'!AI92 -> 0 | AE34: ='Consolidated Financials'!AJ92 -> 0 | AF34: ='Consolidated Financials'!AK92 -> 0 | AG34: ='Consolidated Financials'!AL92 -> 0 | AH34: =SUM(AB34:AG34) -> 0
C35: Increase/(decrease) in trade payables | E35: ='Consolidated Financials'!J93 -> 16794 | F35: ='Consolidated Financials'!K93 -> 58921 | G35: ='Consolidated Financials'!L93 -> 19276 | H35: ='Consolidated Financials'!M93 -> -13202 | I35: ='Consolidated Financials'!N93 -> 91364.224 | J35: ='Consolidated Financials'!O93 -> -52330.232 | O35: ='Consolidated Financials'!U93 -> 595.781 | P35: ='Consolidated Financials'!V93 -> -2637.7343 | Q35: ='Consolidated Financials'!W93 -> -15204.942 | R35: ='Consolidated Financials'!X93 -> -22322.788 | S35: ='Consolidated Financials'!Y93 -> 5785.3292 | T35: ='Consolidated Financials'!Z93 -> 16552.707 | U35: ='Consolidated Financials'!AA93 -> 17909.086 | V35: ='Consolidated Financials'!AB93 -> 17339.618 | ... Z35: ='Consolidated Financials'!AF93 -> 19183.337 | AA35: =SUM(O35:Z35) -> 91364.224 | AB35: ='Consolidated Financials'!AG93 -> -9667.0389 | AC35: ='Consolidated Financials'!AH93 -> -8175.6166 | AD35: ='Consolidated Financials'!AI93 -> -9482.5671 | AE35: ='Consolidated Financials'!AJ93 -> -8175.6166 | AF35: ='Consolidated Financials'!AK93 -> -8175.6166 | AG35: ='Consolidated Financials'!AL93 -> -8653.7764 | AH35: =SUM(AB35:AG35) -> -52330.232
C36: Increase/ (decrease) in other payables and accruals | E36: ='Consolidated Financials'!J94 -> -2129 | F36: ='Consolidated Financials'!K94 -> -6881 | G36: ='Consolidated Financials'!L94 -> 7960 | H36: ='Consolidated Financials'!M94 -> -7153 | I36: ='Consolidated Financials'!N94 -> -4742.9266 | J36: ='Consolidated Financials'!O94 -> -3139.8139 | O36: ='Consolidated Financials'!U94 -> -4996.3609 | P36: ='Consolidated Financials'!V94 -> -207.01058 | Q36: ='Consolidated Financials'!W94 -> -1284.6804 | R36: ='Consolidated Financials'!X94 -> 109.20179 | S36: ='Consolidated Financials'!Y94 -> 72.283464 | T36: ='Consolidated Financials'!Z94 -> 206.81398 | U36: ='Consolidated Financials'!AA94 -> 223.76095 | V36: ='Consolidated Financials'!AB94 -> 216.64586 | ... Z36: ='Consolidated Financials'!AF94 -> 239.68179 | AA36: =SUM(O36:Z36) -> -4742.9266 | AB36: ='Consolidated Financials'!AG94 -> -580.02233 | AC36: ='Consolidated Financials'!AH94 -> -490.537 | AD36: ='Consolidated Financials'!AI94 -> -568.95403 | AE36: ='Consolidated Financials'!AJ94 -> -490.537 | AF36: ='Consolidated Financials'!AK94 -> -490.537 | AG36: ='Consolidated Financials'!AL94 -> -519.22659 | AH36: =SUM(AB36:AG36) -> -3139.8139
C37: Increase/(decrease) in deferred income | E37: ='Consolidated Financials'!J95 -> 1229 | F37: ='Consolidated Financials'!K95 -> -1053 | G37: ='Consolidated Financials'!L95 -> -176 | H37: ='Consolidated Financials'!M95 -> 0 | I37: ='Consolidated Financials'!N95 -> 0 | J37: ='Consolidated Financials'!O95 -> 0 | O37: ='Consolidated Financials'!U95 -> 0 | P37: ='Consolidated Financials'!V95 -> 0 | Q37: ='Consolidated Financials'!W95 -> 0 | R37: ='Consolidated Financials'!X95 -> 0 | S37: ='Consolidated Financials'!Y95 -> 0 | T37: ='Consolidated Financials'!Z95 -> 0 | U37: ='Consolidated Financials'!AA95 -> 0 | V37: ='Consolidated Financials'!AB95 -> 0 | ... Z37: ='Consolidated Financials'!AF95 -> 0 | AA37: =SUM(O37:Z37) -> 0 | AB37: ='Consolidated Financials'!AG95 -> 0 | AC37: ='Consolidated Financials'!AH95 -> 0 | AD37: ='Consolidated Financials'!AI95 -> 0 | AE37: ='Consolidated Financials'!AJ95 -> 0 | AF37: ='Consolidated Financials'!AK95 -> 0 | AG37: ='Consolidated Financials'!AL95 -> 0 | AH37: =SUM(AB37:AG37) -> 0
C38: Increase/ (decrease) in contract liabilities | E38: ='Consolidated Financials'!J96 -> 465 | F38: ='Consolidated Financials'!K96 -> 39692 | G38: ='Consolidated Financials'!L96 -> 3740 | H38: ='Consolidated Financials'!M96 -> 25337 | I38: ='Consolidated Financials'!N96 -> 5956.5391 | J38: ='Consolidated Financials'!O96 -> -16168.525 | O38: ='Consolidated Financials'!U96 -> -3317.614 | P38: ='Consolidated Financials'!V96 -> -46860.82 | Q38: ='Consolidated Financials'!W96 -> 1746.9936 | R38: ='Consolidated Financials'!X96 -> -807.21352 | S38: ='Consolidated Financials'!Y96 -> 2170.7076 | T38: ='Consolidated Financials'!Z96 -> 6982.5058 | U38: ='Consolidated Financials'!AA96 -> 7588.6536 | V38: ='Consolidated Financials'!AB96 -> 7334.1661 | ... Z38: ='Consolidated Financials'!AF96 -> 8158.0997 | AA38: =SUM(O38:Z38) -> 5956.5391 | AB38: ='Consolidated Financials'!AG96 -> -2986.8348 | AC38: ='Consolidated Financials'!AH96 -> -2526.0285 | AD38: ='Consolidated Financials'!AI96 -> -2929.8383 | AE38: ='Consolidated Financials'!AJ96 -> -2526.0285 | AF38: ='Consolidated Financials'!AK96 -> -2526.0285 | AG38: ='Consolidated Financials'!AL96 -> -2673.766 | AH38: =SUM(AB38:AG38) -> -16168.525
C40: Cash generated from / (used in) operating activities | E40: =SUM(E13,E15:E27,E30:E38) -> -107997.94 | F40: =SUM(F13,F15:F27,F30:F38) -> -50868.004 | G40: =SUM(G13,G15:G27,G30:G38) -> -82216 | H40: =SUM(H13,H15:H27,H30:H38) -> -122387.44 | I40: =SUM(I13,I15:I27,I30:I38) -> -44985.732 | J40: =SUM(J13,J15:J27,J30:J38) -> -61032.887 | O40: =SUM(O13,O15:O27,O30:O38) -> -2131.9647 | P40: =SUM(P13,P15:P27,P30:P38) -> -17646.4 | Q40: =SUM(Q13,Q15:Q27,Q30:Q38) -> -11431.633 | R40: =SUM(R13,R15:R27,R30:R38) -> -8851.4319 | S40: =SUM(S13,S15:S27,S30:S38) -> -2947.0447 | T40: =SUM(T13,T15:T27,T30:T38) -> -9716.7435 | U40: =SUM(U13,U15:U27,U30:U38) -> 339.51116 | V40: =SUM(V13,V15:V27,V30:V38) -> 833.82412 | ... Z40: =SUM(Z13,Z15:Z27,Z30:Z38) -> 1906.0023 | AA40: =SUM(O40:Z40) -> -44985.732 | AB40: =SUM(AB13,AB15:AB27,AB30:AB38) -> -12654.053 | AC40: =SUM(AC13,AC15:AC27,AC30:AC38) -> -9967.6895 | AD40: =SUM(AD13,AD15:AD27,AD30:AD38) -> -11766.025 | AE40: =SUM(AE13,AE15:AE27,AE30:AE38) -> -9375.298 | AF40: =SUM(AF13,AF15:AF27,AF30:AF38) -> -9079.1023 | AG40: =SUM(AG13,AG15:AG27,AG30:AG38) -> -8190.7194 | AH40: =SUM(AB40:AG40) -> -61032.887
C41: Tax (paid)/refunded | E41: ='Consolidated Financials'!J99 -> -134 | F41: ='Consolidated Financials'!K99 -> 60 | G41: ='Consolidated Financials'!L99 -> 0 | H41: ='Consolidated Financials'!M99 -> 0 | I41: ='Consolidated Financials'!N99 -> 0 | J41: ='Consolidated Financials'!O99 -> 0 | O41: ='Consolidated Financials'!U99 -> 0 | P41: ='Consolidated Financials'!V99 -> 0 | Q41: ='Consolidated Financials'!W99 -> 0 | R41: ='Consolidated Financials'!X99 -> 0 | S41: ='Consolidated Financials'!Y99 -> 0 | T41: ='Consolidated Financials'!Z99 -> 0 | U41: ='Consolidated Financials'!AA99 -> 0 | V41: ='Consolidated Financials'!AB99 -> 0 | ... Z41: ='Consolidated Financials'!AF99 -> 0 | AA41: =SUM(O41:Z41) -> 0 | AB41: ='Consolidated Financials'!AG99 -> 0 | AC41: ='Consolidated Financials'!AH99 -> 0 | AD41: ='Consolidated Financials'!AI99 -> 0 | AE41: ='Consolidated Financials'!AJ99 -> 0 | AF41: ='Consolidated Financials'!AK99 -> 0 | AG41: ='Consolidated Financials'!AL99 -> 0 | AH41: =SUM(AB41:AG41) -> 0
C43: Net cash generated from / (used in) operating activities | E43: =SUM(E40,E41) -> -108131.94 | F43: =SUM(F40,F41) -> -50808.004 | G43: =SUM(G40,G41) -> -82216 | H43: =SUM(H40,H41) -> -122387.44 | I43: =SUM(I40,I41) -> -44985.732 | J43: =SUM(J40,J41) -> -61032.887 | O43: =SUM(O40,O41) -> -2131.9647 | P43: =SUM(P40,P41) -> -17646.4 | Q43: =SUM(Q40,Q41) -> -11431.633 | R43: =SUM(R40,R41) -> -8851.4319 | S43: =SUM(S40,S41) -> -2947.0447 | T43: =SUM(T40,T41) -> -9716.7435 | U43: =SUM(U40,U41) -> 339.51116 | V43: =SUM(V40,V41) -> 833.82412 | ... Z43: =SUM(Z40,Z41) -> 1906.0023 | AA43: =SUM(O43:Z43) -> -44985.732 | AB43: =SUM(AB40,AB41) -> -12654.053 | AC43: =SUM(AC40,AC41) -> -9967.6895 | AD43: =SUM(AD40,AD41) -> -11766.025 | AE43: =SUM(AE40,AE41) -> -9375.298 | AF43: =SUM(AF40,AF41) -> -9079.1023 | AG43: =SUM(AG40,AG41) -> -8190.7194 | AH43: =SUM(AB43:AG43) -> -61032.887
C45: Investing activities
C47: Payment for the acquisition of property, plant and equipment | E47: ='Consolidated Financials'!J105 -> -7172 | F47: ='Consolidated Financials'!K105 -> -7451 | G47: ='Consolidated Financials'!L105 -> -3201 | H47: ='Consolidated Financials'!M105 -> -135 | I47: ='Consolidated Financials'!N105 -> -7975.947 | J47: ='Consolidated Financials'!O105 -> -11845.152 | O47: ='Consolidated Financials'!U105 -> 0 | P47: ='Consolidated Financials'!V105 -> 0 | Q47: ='Consolidated Financials'!W105 -> 0 | R47: ='Consolidated Financials'!X105 -> 0 | S47: ='Consolidated Financials'!Y105 -> -6.6214811 | T47: ='Consolidated Financials'!Z105 -> -18.945065 | U47: ='Consolidated Financials'!AA105 -> -1324.8457 | V47: ='Consolidated Financials'!AB105 -> -1324.1939 | ... Z47: ='Consolidated Financials'!AF105 -> -1326.3041 | AA47: =SUM(O47:Z47) -> -7975.947 | AB47: ='Consolidated Financials'!AG105 -> -1976.1073 | AC47: ='Consolidated Financials'!AH105 -> -1973.0857 | AD47: ='Consolidated Financials'!AI105 -> -1975.7336 | AE47: ='Consolidated Financials'!AJ105 -> -1973.0857 | AF47: ='Consolidated Financials'!AK105 -> -1973.0857 | AG47: ='Consolidated Financials'!AL105 -> -1974.0545 | AH47: =SUM(AB47:AG47) -> -11845.152
...

Sheet Sensitivity analysis
G3: 测算前，整体Growth Rate 必须为0
C4: 只改变整体的Growth rate | G4: 整体Growth rate为0，只改变新业务Growth rate
D5: 2026 | H5: 2026
C6: Revenue | D6: ='Consolidated Financials'!N10 -> 1091320 | G6: Revenue | H6: ='Consolidated Financials'!N10 -> 1091320
C7: Gross profit | D7: ='Consolidated Financials'!N20 -> 388959.9 | G7: Gross profit | H7: ='Consolidated Financials'!N20 -> 388959.9
C8: Net profit | D8: ='Consolidated Financials'!N41 -> -8445.0357 | G8: Net profit | H8: ='Consolidated Financials'!N41 -> -8445.0357
C9: Adjusted net profit | D9: ='Consolidated Financials'!N63 -> 22113.11 | G9: Adjusted net profit | H9: ='Consolidated Financials'!N63 -> 22113.11
C10: Cash and cash equivalent | D10: ='Consolidated Financials'!N135 -> 1317926.5 | G10: Cash and cash equivalent | H10: ='Consolidated Financials'!N135 -> 1317926.5
B13: hardcode | F13: hardcode
C14: Scenario 1 (20% decrease in revenue*) | G14: Scenario 1 (40% decrease in revenue*)
C15: Revenue | D15: 916193.33 | G15: Revenue | H15: 994967.78
C16: Gross profit | D16: 326488.47 | G16: Gross profit | H16: 345601.41
C17: Net profit | D17: -28053.132 | G17: Net profit | H17: -33376.403
C18: Adjusted net profit | D18: 2505.0136 | G18: Adjusted net profit | H18: -2818.2576
C19: Cash and cash equivalent | D19: 1377470.1 | G19: Cash and cash equivalent | H19: 1323115.3
C21: Scenario 2 (10% decrease in revenue*) | G21: Scenario 2 (30% decrease in revenue*)
C22: Revenue | D22: 1003756.7 | G22: Revenue | H22: 1019055.8
C23: Gross profit | D23: 357724.19 | G23: Gross profit | H23: 356441.04
C24: Net profit | D24: -18249.084 | G24: Net profit | H24: -28557.299
C25: Adjusted net profit | D25: 12309.062 | G25: Adjusted net profit | H25: 2000.8469
C26: Cash and cash equivalent | D26: 1347698.3 | G26: Cash and cash equivalent | H26: 1314343.3
C28: Scenario 3 (base case) | G28: Scenario 3 (20% decrease in revenue*)
C29: Revenue | D29: 1091320 | G29: Revenue | H29: 1043143.9
C30: Gross profit | D30: 388959.9 | G30: Gross profit | H30: 367280.66
C31: Net profit | D31: -8445.0357 | G31: Net profit | H31: -23738.194
C32: Adjusted net profit | D32: 22113.11 | G32: Adjusted net profit | H32: 6819.9513
C33: Cash and cash equivalent | D33: 1317926.5 | G33: Cash and cash equivalent | H33: 1305571.3
C35: Scenario 4 (10% increase in revenue*) | G35: Scenario 4 (10% decrease in revenue*)
C36: Revenue | D36: 1178883.3 | G36: Revenue | H36: 1067231.9
C37: Gross profit | D37: 420195.62 | G37: Gross profit | H37: 378120.28
C38: Net profit | D38: 483.37924 | G38: Net profit | H38: -18919.09
C39: Adjusted net profit | D39: 31041.525 | G39: Adjusted net profit | H39: 11639.056
C40: Cash and cash equivalent | D40: 1287279 | G40: Cash and cash equivalent | H40: 1296799.3
C42: Scenario 5 (20% increase in revenue*) | G42: Scenario 5 (base case)
C43: Revenue | D43: 1266446.6 | G43: Revenue | H43: 1091320 | K43: =H43-D29 -> 0
C44: Gross profit | D44: 451431.34 | G44: Gross profit | H44: 388959.9 | K44: =H44-D30 -> 0
C45: Net profit | D45: 9411.7942 | G45: Net profit | H45: -8445.0357 | K45: =H45-D31 -> 0
C46: Adjusted net profit | D46: 39969.94 | G46: Adjusted net profit | H46: 22113.11 | K46: =H46-D32 -> 0
C47: Cash and cash equivalent | D47: 1256631.6 | G47: Cash and cash equivalent | H47: 1317926.5 | K47: =H47-D33 -> 0

Sheet listing expense
A1: Nanjing Silicon Intelligence Technology Group Co., Ltd. (the "Company") | D1: A1版本（LPD 2025.10.24） | F1: LPD 2026.5.13
A2: E16. Listing expenses | C2: 汇率 | E2: 汇率 | I2: Domestic Shares | L2: 17084745 | P2: =P4/('Consolidated Financials'!N10*1000) -> 4.4757032
C3: 港币 | D3: 1 | E3: 港币 | F3: 1 | I3: Global Offering (25%) | L3: 5694900 | M3: =L3/(L3+L2) -> 0.24999951 | T3: Market Cap
C4: 美元兌港币 | D4: 7.7716 | E4: 美元兌港币 | F4: 7.8289 | G4: =6.9025*F5 -> 7.8968744 | I4: Over-allotment Option (15%) | L4: 854220 | N4: =N5/$F$5 -> 4.4055592e+09 | P4: =P5/$F$5 -> 4.8844243e+09 | R4: =R5/$F$5 -> 5.3632895e+09 | T4: =T10*$L$7/$F$5 -> 4.5707645e+09 | V4: =V10*$L$7/$F$5 -> 5.0675867e+09 | X4: =X10*$L$7/$F$5 -> 5.5644089e+09
C5: 人民币兌港币 | D5: =1/0.91266 -> 1.0956983 | E5: 人民币兌港币 | F5: =1/0.87408 -> 1.14406 | I5: Global Offering with OAO | L5: =SUM(L3:L4) -> 6549120 | N5: =N10*$L$6 -> 5.0402243e+09 | P5: =P10*$L$6 -> 5.5880747e+09 | R5: =R10*$L$6 -> 6.1359252e+09
F6: <to update as per LPD> | I6: Total without OAO | L6: =L2+L3 -> 22779645 | Z6: Global Offering WITHOUT Over-allotment Option exercised | AL6: Global Offering WITH Over-allotment Option exercised | AY6: Global Offering WITHOUT Over-allotment Option exercised | BE6: Global Offering WITH Over-allotment Option exercised | BK6: 管理帐人民币倒推
F7: 2026.5.13 | I7: Total with OAO | L7: =L2+L5 -> 23633865 | N7: Global Offering WITHOUT Over-allotment Option exercised | T7: Global Offering WITH Over-allotment Option exercised | BO7: 25% Equity;75% Expense | BW7: 25% Equity;75% Expense
D8: =7.0928*1.0957 -> 7.771581 | N8: Offer Price | T8: Offer Price | AC8: Low | AF8: Mid | AI8: High | AO8: Low | AR8: Mid | AU8: High | AY8: TRP | BB8: Post-TRP | BE8: TRP | BH8: Post-TRP | BK8: HKD | BS8: RMB
I9: Exchange rate | L9: Contract amount in HKD | N9: Low | P9: Mid | R9: High | T9: Low | V9: Mid | X9: High | AC9: =N10 -> 221.26 | AF9: =AVERAGE(AC9,AI9) -> 245.31 | AI9: =R10 -> 269.36 | AO9: 1.64 | AR9: 1.8 | AU9: 1.96 | AY9: Mid point | BB9: Mid point | BE9: Mid point | BH9: Mid point | BK9: 2024 | BN9: 2025 | BQ9: Remaining | BS9: 2024 | BV9: 2025 | BY9: Remaining | CF9: LPD
A10: No. | C10: Name of professional parties | D10: Particulars | E10: Oct | F10: Nov | G10: Contract currency | H10: Contract amount | I10: Currency / HKD | J10: Oct | K10: Nov | L10: HK$ | N10: 221.26 | P10: 245.31 | R10: 269.36 | T10: =N10 -> 221.26 | V10: =P10 -> 245.31 | X10: =R10 -> 269.36 | Z10: Equity | AA10: Expenses | AC10: Equity | AD10: Expenses | AF10: Equity | AG10: Expenses | AI10: Equity | AJ10: Expenses | AL10: Equity | AM10: Expenses | AO10: Equity | AP10: Expenses | AR10: Equity | AS10: Expenses | AU10: Equity | AV10: Expenses | AY10: Equity | AZ10: Expenses | BB10: Equity | BC10: Expenses | BE10: Equity | BF10: Expenses | BH10: Equity | BI10: Expenses | BK10: Total (HK$) | BL10: Equity (HK$) | BM10: Expenses (HK$) | BN10: Total (HK$) | BO10: Equity (HK$) | BP10: Expenses (HK$) | BQ10: Equity (HK$) | BR10: Expenses (HK$) | BS10: Total (RMB) | BT10: Equity (RMB) | BU10: Expenses (RMB) | BV10: Total (RMB) | BW10: Equity (RMB) | BX10: Expenses (RMB) | BY10: Equity (RMB) | BZ10: Expenses (RMB) | CC10: 已支付金额 | CD10: Contract currency | CE10: Remaining (Contract currency) | CF10: Remaining (HKD) | CG10: Remaining (RMB)
A11: 1 | B11: 招银国际融资有限公司 | C11: CMB International Capital Limited | D11: Joint Sponsor and Underwriters | F11: 600000 | G11: USD | H11: 1500000 | I11: =IF(G11="HKD",$F$3,IF(G11="USD",$F$4,IF(G11="RMB",$F$5,""))) -> 7.8289 | J11: =I11*E11 -> 0 | K11: =I11*F11 -> 4697340 | L11: =I11*H11 -> 11743350 | N11: =L11 -> 11743350 | P11: =L11 -> 11743350 | R11: =L11 -> 11743350 | T11: =L11 -> 11743350 | V11: =L11 -> 11743350 | X11: =L11 -> 11743350 | Z11: 0.25 | AA11: =1-Z11 -> 0.75 | AC11: =Z11*N11 -> 2935837.5 | AD11: =AA11*N11 -> 8807512.5 | AF11: =Z11*P11 -> 2935837.5 | AG11: =AA11*P11 -> 8807512.5 | AI11: =Z11*R11 -> 2935837.5 | AJ11: =AA11*R11 -> 8807512.5 | AL11: =Z11 -> 0.25 | AM11: =1-AL11 -> 0.75 | AO11: =AL11*T11 -> 2935837.5 | AP11: =AM11*T11 -> 8807512.5 | AR11: =AL11*V11 -> 2935837.5 | AS11: =AM11*V11 -> 8807512.5 | AU11: =AL11*X11 -> 2935837.5 | AV11: =AM11*X11 -> 8807512.5 | AY11: 0 | AZ11: 0 | BB11: =AF11-AY11 -> 2935837.5 | BC11: =AG11-AZ11 -> 8807512.5 | BE11: 0 | BF11: 0 | BH11: =AR11-BE11 -> 2935837.5 | BI11: =AS11-BF11 -> 8807512.5 | BL11: 100% Expense | BN11: =IF(BV11>0,IF(G11="HKD",H11,BV11*$F$5),0) -> 10333178 | BO11: =IF(BW11>0,IF(G11="HKD",AF11,BW11*$F$5),0) -> 2583294.5 | BP11: =IF(BX11>0,IF(G11="HKD",AG11,BX11*$F$5),0) -> 7749883.6 | BT11: 100% Expense | BV11: 9032024.4 | BW11: 2258006.1 | BX11: 6774018.3 | CC11: 1000000 | CD11: =G11 -> USD | CE11: =H11-CC11 -> 500000 | CF11: =CE11*I11 -> 3914450 | CG11: =CF11/$F$5 -> 3421542.5
A12: 2 | B12: 星展亚洲融资有限公司 | C12: DBS Asia Capital Limited | D12: Joint Sponsor and Underwriters | F12: 100000 | G12: USD | H12: 300000 | I12: =IF(G12="HKD",$F$3,IF(G12="USD",$F$4,IF(G12="RMB",$F$5,""))) -> 7.8289 | J12: =I12*E12 -> 0 | K12: =I12*F12 -> 782890 | L12: =I12*H12 -> 2348670 | N12: =L12 -> 2348670 | P12: =L12 -> 2348670 | R12: =L12 -> 2348670 | T12: =L12 -> 2348670 | V12: =L12 -> 2348670 | X12: =L12 -> 2348670 | Z12: 0.25 | AA12: =1-Z12 -> 0.75 | AC12: =Z12*N12 -> 587167.5 | AD12: =AA12*N12 -> 1761502.5 | AF12: =Z12*P12 -> 587167.5 | AG12: =AA12*P12 -> 1761502.5 | AI12: =Z12*R12 -> 587167.5 | AJ12: =AA12*R12 -> 1761502.5 | AL12: =Z12 -> 0.25 | AM12: =1-AL12 -> 0.75 | AO12: =AL12*T12 -> 587167.5 | AP12: =AM12*T12 -> 1761502.5 | AR12: =AL12*V12 -> 587167.5 | AS12: =AM12*V12 -> 1761502.5 | AU12: =AL12*X12 -> 587167.5 | AV12: =AM12*X12 -> 1761502.5 | AY12: 0 | AZ12: 0 | BB12: =AF12-AY12 -> 587167.5 | BC12: =AG12-AZ12 -> 1761502.5 | BE12: 0 | BF12: 0 | BH12: =AR12-BE12 -> 587167.5 | BI12: =AS12-BF12 -> 1761502.5 | BN12: =IF(BV12>0,IF(G12="HKD",H12,BV12*$F$5),0) -> 905777.75 | BO12: =IF(BW12>0,IF(G12="HKD",AF12,BW12*$F$5),0) -> 226444.44 | BP12: =IF(BX12>0,IF(G12="HKD",AG12,BX12*$F$5),0) -> 679333.32 | BV12: 791722.22 | BW12: 197930.55 | BX12: 593791.67 | CC12: 100000 | CD12: =G12 -> USD | CE12: =H12-CC12 -> 200000 | CF12: =CE12*I12 -> 1565780 | CG12: =CF12/$F$5 -> 1368617
A13: 3 | B13: 天元律師事務所 | C13: Tian Yuan Law Firm LLP | D13: Legal Advisors to the Company As to Hong Kong laws | F13: 360000 | G13: USD | H13: 900000 | I13: =IF(G13="HKD",$F$3,IF(G13="USD",$F$4,IF(G13="RMB",$F$5,""))) -> 7.8289 | J13: =I13*E13 -> 0 | K13: =I13*F13 -> 2818404 | L13: =I13*H13 -> 7046010 | N13: =L13 -> 7046010 | P13: =L13 -> 7046010 | R13: =L13 -> 7046010 | T13: =L13 -> 7046010 | V13: =L13 -> 7046010 | X13: =L13 -> 7046010 | Z13: 0.25 | AA13: =1-Z13 -> 0.75 | AC13: =Z13*N13 -> 1761502.5 | AD13: =AA13*N13 -> 5284507.5 | AF13: =Z13*P13 -> 1761502.5 | AG13: =AA13*P13 -> 5284507.5 | AI13: =Z13*R13 -> 1761502.5 | AJ13: =AA13*R13 -> 5284507.5 | AL13: =Z13 -> 0.25 | AM13: =1-AL13 -> 0.75 | AO13: =AL13*T13 -> 1761502.5 | AP13: =AM13*T13 -> 5284507.5 | AR13: =AL13*V13 -> 1761502.5 | AS13: =AM13*V13 -> 5284507.5 | AU13: =AL13*X13 -> 1761502.5 | AV13: =AM13*X13 -> 5284507.5 | AY13: 0 | AZ13: 0 | BB13: =AF13-AY13 -> 1761502.5 | BC13: =AG13-AZ13 -> 5284507.5 | BE13: 0 | BF13: 0 | BH13: =AR13-BE13 -> 1761502.5 | BI13: =AS13-BF13 -> 5284507.5 | BN13: =IF(BV13>0,IF(G13="HKD",H13,BV13*$F$5),0) -> 4558622.1 | BO13: =IF(BW13>0,IF(G13="HKD",AF13,BW13*$F$5),0) -> 1139655.5 | BP13: =IF(BX13>0,IF(G13="HKD",AG13,BX13*$F$5),0) -> 3418966.6 | BV13: 3984600.4 | BW13: 996150.1 | BX13: 2988450.3 | CC13: 540000 | CD13: =G13 -> USD | CE13: =H13-CC13 -> 360000 | CF13: =CE13*I13 -> 2818404 | CG13: =CF13/$F$5 -> 2463510.6
