Workbook

Sheet Sheet1
A1: Currency | B1: HKD | C1: USD | E1: CRNCY_ADJ_MKT_CAP | F1: Crncy Adj Mkt Cap | G1: Px Last | H1: Net Assets | I1: Net Assets | J1: Sales Rev Turn | K1: Sales Rev Turn | L1: Net Income | M1: Net Income | N1: Gross_Margin_Adjusted | O1: EBITDA_MARGIN_ADJUSTED | P1: Prof Margin | Q1: Sales_Growth | R1: Net Inc Growth | S1: TOT_DEBT_TO_TOT_EQY | T1: TOT_DEBT_TO_COM_EQY | U1: NET_DEBT_TO_SHRHLDR_EQTY | V1: TOT_DEBT_TO_TOT_ASSET | W1: RETURN_ON_ASSET | Z1: RETURN_COM_EQY | AD1: Pe Ratio | AJ1: BEST_EV_TO_BEST_EBITDA | AM1: Px To Book Ratio | AT1: EQY_DVD_YLD_IND | AU1: BEST_DIV_YLD | CZ1: CIE_DES
AC2: TTM PE = | AD2: IF(AB7<0,"N/A",$E7/AB7) | AF2: TTM PS = | AG2: $E7/AA7
A3: Company Name | B3: 公司名 | C3: Stock Code | E3: Operating Data | AD3: Valuation | AW3: Forecast CAGR | AZ3: Key financials (USD'b) | CW3: Volatility
D4: Listing date | E4: Market Capitalization (HKD 'm) | F4: Market Capitalization (USD 'm) | G4: Price (Traded Currency) | H4: Net Assets (HKD 'm) | I4: Net Assets (USD 'm) | J4: Revenue (HKD 'm) | K4: Revenue (USD 'm) | L4: Net Profit (HKD 'm) | M4: Net Profit (USD 'm) | N4: GP Margin (%) | O4: EBITDA Margin (%) | P4: NP Margin (%) | Q4: Revenue Growth (%) | R4: NP Growth (%) | S4: Debt to equity | T4: Debt to common equity | U4: Net debt To Shareholders Equity | V4: Total Debt to Total Assets | W4: ROA | X4: EV (HKD'm) | Y4: EV (USD'm) | Z4: ROE | AA4: TTM Sales Profit (HKD 'm) | AB4: TTM Net Profit (HKD 'm) | AC4: TTM EBITDA (HKD 'm) | AD4: PE Ratio (x) | AG4: PS Ratio (x) | AJ4: EV/EBITDA (x) | AM4: PB Ratio (x) | AQ4: ROE (%) | AT4: Dividend Yield (x) | AW4: Revenue | AX4: EBITDA | AY4: Net profit | AZ4: cash flow from operations (USD'b) | BF4: Free cash flow (USD'b) | BL4: Revenue | BR4: EBITDA | BX4: Net profit | CD4: Dividend | CH4: Dividend yield | CL4: 5D Avg ADTV (HKD'm) | CM4: 10D Avg ADTV (HKD'm) | CN4: 20D Avg ADTV (HKD'm) | CO4: 1M Avg ADTV (HKD'm) | CP4: 3M Avg ADTV (HKD'm) | CQ4: 6M Avg ADTV (HKD'm) | CR4: 1M Return | CS4: 3M Return | CT4: 6M Return | CU4: 1Y Return | CV4: YTD Return | CW4: 30-day volatility (%) | CX4: 90-day volatility (%) | CY4: 180-day volatility (%)
AD5: 2025A | AE5: 2026F | AF5: 2027F | AG5: 2025A | AH5: 2026F | AI5: 2027F | AJ5: TTM | AK5: 2026F | AL5: 2027F | AM5: TTM | AN5: 2026F | AO5: 2027F | AP5: 2027F | AQ5: TTM | AR5: 2026F | AS5: 2027F | AT5: TTM | AU5: 2026F | AV5: 2027F | AW5: 2026 vs 2024 | AZ5: CY2022A | BA5: CY2023A | BB5: CY2024A | BC5: CY2025F | BD5: CY2026F | BE5: CY2027F | BF5: CY2022A | BG5: CY2023A | BH5: CY2024A | BI5: CY2025F | BJ5: CY2026F | BK5: CY2027F | BL5: CY2022A | BM5: CY2023A | BN5: CY2024A | BO5: CY2025F | BP5: CY2026F | BQ5: CY2027F | BR5: CY2022A | BS5: CY2023A | BT5: CY2024A | BU5: CY2025F | BV5: CY2026F | BW5: CY2027F | BX5: CY2022A | BY5: CY2023A | BZ5: CY2024A | CA5: CY2025F | CB5: CY2026F | CC5: CY2027F | CD5: CY2024A | CE5: CY2025F | CF5: CY2026F | CG5: CY2027F | CH5: CY2024A | CI5: CY2025F | CJ5: CY2026F | CK5: CY2027F
A7: =_xll.BDP($C7,"security name") -> #NAME? | B7: =_xll.BDP($C7,"NAME_CHINESE_SIMPLIFIED") -> #NAME? | C7: pdsl in Equity | D7: =_xll.BDP($C7,"LISTING_DATE") -> #NAME? | E7: =_xll.BDP($C7,E$1,"EQY_FUND_CRNCY="&$B$1) -> #NAME? | F7: =_xll.BDP($C7,F$1,"EQY_FUND_CRNCY="&$C$1) -> #NAME? | G7: =_xll.BDP($C7,G$1) -> #NAME? | H7: =_xll.BDP($C7,H$1,"EQY_FUND_CRNCY="&$B$1) -> #NAME? | I7: =_xll.BDP($C7,I$1,"EQY_FUND_CRNCY="&$C$1) -> #NAME? | J7: =_xll.BDP($C7,J$1,"EQY_FUND_CRNCY="&$B$1) -> #NAME? | K7: =_xll.BDP($C7,K$1,"EQY_FUND_CRNCY="&$C$1) -> #NAME? | L7: =_xll.BDP($C7,L$1,"EQY_FUND_CRNCY="&$B$1) -> #NAME? | M7: =_xll.BDP($C7,M$1,"EQY_FUND_CRNCY="&$C$1) -> #NAME? | N7: =_xll.BDP($C7,N$1)/100 -> #NAME? | O7: =_xll.BDP($C7,O$1)/100 -> #NAME? | P7: =_xll.BDP($C7,P$1)/100 -> #NAME? | Q7: =_xll.BDP($C7,Q$1)/100 -> #NAME? | R7: =_xll.BDP($C7,R$1)/100 -> #NAME? | S7: =_xll.BDP($C7,S$1)/100 -> #NAME? | T7: =_xll.BDP($C7,T$1)/100 -> #NAME? | U7: =_xll.BDP($C7,U$1)/100 -> #NAME? | ... W7: =_xll.BDP($C7,W$1)/100 -> #NAME? | X7: {=_xll.BDP($C7,"CRNCY_ADJ_CURR_EV", "EQY_FUND_CRNCY=HKD")} -> #NAME? | Y7: {=_xll.BDP($C7,"CRNCY_ADJ_CURR_EV", "EQY_FUND_CRNCY=USD")} -> #NAME? | Z7: =_xll.BDP($C7,Z$1)/100 -> #NAME? | AA7: =_xll.BDP($C7,"TRAIL_12M_NET_SALES","EQY_FUND_CRNCY=HKD") -> #NAME? | AB7: =_xll.BDP($C7,"TRAIL_12M_NET_INC","EQY_FUND_CRNCY=HKD") -> #NAME? | AC7: =_xll.BDP($C7,"TRAIL_12M_EBITDA","EQY_FUND_CRNCY=HKD") -> #NAME? | AD7: {=_xll.BQL($C7, "PE_RATIO(FPT=BA, FPR=2025, FYE=C1231, AE=E)")} -> #NAME? | AE7: {=_xll.BQL($C7, "PE_RATIO(FPT=BA, FPR=2026, FYE=C1231, AE=E)")} -> #NAME? | AF7: {=_xll.BQL($C7, "PE_RATIO(FPT=BA, FPR=2027, FYE=C1231, AE=E)")} -> #NAME? | AG7: {=_xll.BQL($C7, "PX_TO_SALES_RATIO(FPT=BA, FPR=2025, FYE=C1231, AE=E)")} -> #NAME? | AH7: {=_xll.BQL($C7, "PX_TO_SALES_RATIO(FPT=BA, FPR=2026, FYE=C1231, AE=E)")} -> #NAME? | AI7: {=_xll.BQL($C7, "PX_TO_SALES_RATIO(FPT=BA, FPR=2027, FYE=C1231, AE=E)")} -> #NAME? | AJ7: =IF(AC7<0,"N/A",$X7/AC7) -> #NAME? | AK7: {=IF(_xll.BQL($C7, "CURR_ENTP_VAL(FPT=A,FPO=0)/EBITDA(FPT=BA, FPR=2026, FYE=C1231, AE=E)")<0,"N/A",_xll.BQL($C7, "CURR_ENTP_VAL(FPT=A,FPO=0)/EBITDA(FPT=BA, FPR=2026, FYE=C1231, AE=E)"))} -> #NAME? | AL7: {=IF(_xll.BQL($C7, "CURR_ENTP_VAL(FPT=A,FPO=0)/EBITDA(FPT=BA, FPR=2027, FYE=C1231, AE=E)")<0,"N/A",_xll.BQL($C7, "CURR_ENTP_VAL(FPT=A,FPO=0)/EBITDA(FPT=BA, FPR=2027, FYE=C1231, AE=E)"))} -> #NAME? | AM7: =_xll.BDP($C7,AM$1) -> #NAME? | AN7: {=_xll.BQL($C7, "PX_TO_BOOK_RATIO(FPT=BA, FPR=2026, FYE=C1231, AE=E)")} -> #NAME? | AO7: {=_xll.BQL($C7, "PX_TO_BOOK_RATIO(FPT=BA, FPR=2027, FYE=C1231, AE=E)")} -> #NAME? | AP7: =_xll.BDP($C7,"BEST Px bps ratio","BEST fperiod override","27Y") -> #NAME? | AQ7: =Z7 -> #NAME? | AR7: =_xll.BDP($C7,"BEST_ROE","BEST fperiod override","26Y")/100 -> #NAME? | AS7: =_xll.BDP($C7,"BEST_ROE","BEST fperiod override","27Y")/100 -> #NAME? | AT7: =_xll.BDP($C7,AT$1) -> #NAME? | AU7: =_xll.BDP($C7,$AU$1,"BEST fperiod override","26Y") -> #NAME? | AV7: =_xll.BDP($C7,$AU$1,"BEST fperiod override","27Y") -> #NAME? | AW7: =(BP7/BN7)^(1/2)-1 -> #NAME? | AX7: =(BV7/BT7)^(1/2)-1 -> #NAME? | AY7: =(CB7/BZ7)^(1/2)-1 -> #NAME? | AZ7: {=_xll.BQL($C7, "CF_CASH_FROM_OPER(FPT=BA, FPR=2022, FYE=C1231, AE=A)", "currency=USD")/1000000000} -> #NAME? | BA7: {=_xll.BQL($C7, "CF_CASH_FROM_OPER(FPT=BA, FPR=2023, FYE=C1231, AE=A)", "currency=USD")/1000000000} -> #NAME? | BB7: {=_xll.BQL($C7, "CF_CASH_FROM_OPER(FPT=BA, FPR=2024, FYE=C1231, AE=A)", "currency=USD")/1000000000} -> #NAME? | BC7: {=_xll.BQL($C7, "CF_CASH_FROM_OPER(FPT=BA, FPR=2025, FYE=C1231, AE=E)", "currency=USD")/1000000000} -> #NAME? | BD7: {=_xll.BQL($C7, "CF_CASH_FROM_OPER(FPT=BA, FPR=2026, FYE=C1231, AE=E)", "currency=USD")/1000000000} -> #NAME? | BE7: {=_xll.BQL($C7, "CF_CASH_FROM_OPER(FPT=BA, FPR=2027, FYE=C1231, AE=E)", "currency=USD")/1000000000} -> #NAME? | BF7: {=_xll.BQL($C7, "CF_FREE_CASH_FLOW(FPT=BA, FPR=2022, FYE=C1231, AE=A)", "currency=USD")/1000000000} -> #NAME? | BG7: {=_xll.BQL($C7, "CF_FREE_CASH_FLOW(FPT=BA, FPR=2023, FYE=C1231, AE=A)", "currency=USD")/1000000000} -> #NAME? | BH7: {=_xll.BQL($C7, "CF_FREE_CASH_FLOW(FPT=BA, FPR=2024, FYE=C1231, AE=A)", "currency=USD")/1000000000} -> #NAME? | BI7: {=_xll.BQL($C7, "CF_FREE_CASH_FLOW(FPT=BA, FPR=2025, FYE=C1231, AE=E)", "currency=USD")/1000000000} -> #NAME? | BJ7: {=_xll.BQL($C7, "CF_FREE_CASH_FLOW(FPT=BA, FPR=2026, FYE=C1231, AE=E)", "currency=USD")/1000000000} -> #NAME? | BK7: {=_xll.BQL($C7, "CF_FREE_CASH_FLOW(FPT=BA, FPR=2027, FYE=C1231, AE=E)", "currency=USD")/1000000000} -> #NAME? | BL7: {=_xll.BQL($C7, "SALES_REV_TURN(FPT=BA, FPR=2022, FYE=C1231, AE=A)", "currency=USD")/1000000000} -> #NAME? | BM7: {=_xll.BQL($C7, "SALES_REV_TURN(FPT=BA, FPR=2023, FYE=C1231, AE=A)", "currency=USD")/1000000000} -> #NAME? | BN7: {=_xll.BQL($C7, "SALES_REV_TURN(FPT=BA, FPR=2024, FYE=C1231, AE=A)", "currency=USD")/1000000000} -> #NAME? | BO7: {=_xll.BQL($C7, "SALES_REV_TURN(FPT=BA, FPR=2025, FYE=C1231, AE=E)", "currency=USD")/1000000000} -> #NAME? | BP7: {=_xll.BQL($C7, "SALES_REV_TURN(FPT=BA, FPR=2026, FYE=C1231, AE=E)", "currency=USD")/1000000000} -> #NAME? | BQ7: {=_xll.BQL($C7, "SALES_REV_TURN(FPT=BA, FPR=2027, FYE=C1231, AE=E)", "currency=USD")/1000000000} -> #NAME? | BR7: {=_xll.BQL($C7, "EBITDA(FPT=BA, FPR=2022, FYE=C1231, AE=A)", "currency=USD")/1000000000} -> #NAME? | BS7: {=_xll.BQL($C7, "EBITDA(FPT=BA, FPR=2023, FYE=C1231, AE=A)", "currency=USD")/1000000000} -> #NAME? | BT7: {=_xll.BQL($C7, "EBITDA(FPT=BA, FPR=2024, FYE=C1231, AE=A)", "currency=USD")/1000000000} -> #NAME? | BU7: {=_xll.BQL($C7, "EBITDA(FPT=BA, FPR=2025, FYE=C1231, AE=E)", "currency=USD")/1000000000} -> #NAME? | BV7: {=_xll.BQL($C7, "EBITDA(FPT=BA, FPR=2026, FYE=C1231, AE=E)", "currency=USD")/1000000000} -> #NAME? | BW7: {=_xll.BQL($C7, "EBITDA(FPT=BA, FPR=2027, FYE=C1231, AE=E)", "currency=USD")/1000000000} -> #NAME? | BX7: {=_xll.BQL($C7, "NET_INCOME(FPT=BA, FPR=2022, FYE=C1231, AE=A)", "currency=USD")/1000000000} -> #NAME? | BY7: {=_xll.BQL($C7, "NET_INCOME(FPT=BA, FPR=2023, FYE=C1231, AE=A)", "currency=USD")/1000000000} -> #NAME? | BZ7: {=_xll.BQL($C7, "NET_INCOME(FPT=BA, FPR=2024, FYE=C1231, AE=A)", "currency=USD")/1000000000} -> #NAME? | CA7: {=_xll.BQL($C7, "NET_INCOME(FPT=BA, FPR=2025, FYE=C1231, AE=E)", "currency=USD")/1000000000} -> #NAME? | CB7: {=_xll.BQL($C7, "NET_INCOME(FPT=BA, FPR=2026, FYE=C1231, AE=E)", "currency=USD")/1000000000} -> #NAME? | CC7: {=_xll.BQL($C7, "NET_INCOME(FPT=BA, FPR=2027, FYE=C1231, AE=E)", "currency=USD")/1000000000} -> #NAME? | CD7: {=-_xll.BQL($C7, "CF_DVD_PAID(FPT=BA, FPR=2024, FYE=C1231, AE=A)", "currency=USD")/1000000000} -> #NAME? | CE7: {=-_xll.BQL($C7, "CF_DVD_PAID(FPT=BA, FPR=2025, FYE=C1231, AE=E)", "currency=USD")/1000000000} -> #NAME? | CF7: {=-_xll.BQL($C7, "CF_DVD_PAID(FPT=BA, FPR=2026, FYE=C1231, AE=E)", "currency=USD")/1000000000} -> #NAME? | CG7: {=-_xll.BQL($C7, "CF_DVD_PAID(FPT=BA, FPR=2027, FYE=C1231, AE=E)", "currency=USD")/1000000000} -> #NAME? | CH7: =CD7/$F7 -> #NAME? | CI7: =CE7/$F7 -> #NAME? | CJ7: =CF7/$F7 -> #NAME? | CK7: =CG7/$F7 -> #NAME? | CL7: {=_xll.BDP($C7,"INTERVAL_AVG", "MARKET_DATA_OVERRIDE=turnover", "CALC_INTERVAL=5D","CRNCY=HKD")/1000000} -> #NAME? | CM7: {=_xll.BDP($C7,"INTERVAL_AVG", "MARKET_DATA_OVERRIDE=turnover", "CALC_INTERVAL=10D","CRNCY=HKD")/1000000} -> #NAME? | CN7: {=_xll.BDP($C7,"INTERVAL_AVG", "MARKET_DATA_OVERRIDE=turnover", "CALC_INTERVAL=20D","CRNCY=HKD")/1000000} -> #NAME? | CO7: {=_xll.BDP($C7,"INTERVAL_AVG", "MARKET_DATA_OVERRIDE=turnover", "CALC_INTERVAL=1m","CRNCY=HKD")/1000000} -> #NAME? | CP7: {=_xll.BDP($C7,"INTERVAL_AVG", "MARKET_DATA_OVERRIDE=turnover", "CALC_INTERVAL=3M","CRNCY=HKD")/1000000} -> #NAME? | CQ7: {=_xll.BDP($C7,"INTERVAL_AVG", "MARKET_DATA_OVERRIDE=turnover", "CALC_INTERVAL=6M","CRNCY=HKD")/1000000} -> #NAME? | CR7: =_xll.BDP($C7,"chg pct 1m")/100 -> #NAME? | CS7: =_xll.BDP($C7,"chg pct 3m")/100 -> #NAME? | CT7: =_xll.BDP($C7,"chg pct 6m")/100 -> #NAME? | CU7: =_xll.BDP($C7,"chg pct 1yr")/100 -> #NAME? | CV7: =_xll.BDP($C7,"chg pct ytd")/100 -> #NAME? | CW7: {=_xll.BQL($C7, "volatility(calc_interval=range(-1M, 0D))")} -> #NAME? | CX7: {=_xll.BQL($C7, "volatility(calc_interval=range(-3M, 0D))")} -> #NAME? | CY7: {=_xll.BQL($C7, "volatility(calc_interval=range(-6M, 0D))")} -> #NAME? | CZ7: =_xll.BDP($C7,CZ$1) -> #NAME?
A8: =_xll.BDP($C8,"security name") -> #NAME? | B8: =_xll.BDP($C8,"NAME_CHINESE_SIMPLIFIED") -> #NAME? | C8: wmt us Equity | D8: =_xll.BDP($C8,"LISTING_DATE") -> #NAME? | E8: =_xll.BDP($C8,E$1,"EQY_FUND_CRNCY="&$B$1) -> #NAME? | F8: =_xll.BDP($C8,F$1,"EQY_FUND_CRNCY="&$C$1) -> #NAME? | G8: =_xll.BDP($C8,G$1) -> #NAME? | H8: =_xll.BDP($C8,H$1,"EQY_FUND_CRNCY="&$B$1) -> #NAME? | I8: =_xll.BDP($C8,I$1,"EQY_FUND_CRNCY="&$C$1) -> #NAME? | J8: =_xll.BDP($C8,J$1,"EQY_FUND_CRNCY="&$B$1) -> #NAME? | K8: =_xll.BDP($C8,K$1,"EQY_FUND_CRNCY="&$C$1) -> #NAME? | L8: =_xll.BDP($C8,L$1,"EQY_FUND_CRNCY="&$B$1) -> #NAME? | M8: =_xll.BDP($C8,M$1,"EQY_FUND_CRNCY="&$C$1) -> #NAME? | N8: =_xll.BDP($C8,N$1)/100 -> #NAME? | O8: =_xll.BDP($C8,O$1)/100 -> #NAME? | P8: =_xll.BDP($C8,P$1)/100 -> #NAME? | Q8: =_xll.BDP($C8,Q$1)/100 -> #NAME? | R8: =_xll.BDP($C8,R$1)/100 -> #NAME? | S8: =_xll.BDP($C8,S$1)/100 -> #NAME? | T8: =_xll.BDP($C8,T$1)/100 -> #NAME? | U8: =_xll.BDP($C8,U$1)/100 -> #NAME? | ... W8: =_xll.BDP($C8,W$1)/100 -> #NAME? | X8: {=_xll.BDP($C8,"CRNCY_ADJ_CURR_EV", "EQY_FUND_CRNCY=HKD")} -> #NAME? | Y8: {=_xll.BDP($C8,"CRNCY_ADJ_CURR_EV", "EQY_FUND_CRNCY=USD")} -> #NAME? | Z8: =_xll.BDP($C8,Z$1)/100 -> #NAME? | AA8: =_xll.BDP($C8,"TRAIL_12M_NET_SALES","EQY_FUND_CRNCY=HKD") -> #NAME? | AB8: =_xll.BDP($C8,"TRAIL_12M_NET_INC","EQY_FUND_CRNCY=HKD") -> #NAME? | AC8: =_xll.BDP($C8,"TRAIL_12M_EBITDA","EQY_FUND_CRNCY=HKD") -> #NAME? | AD8: {=_xll.BQL($C8, "PE_RATIO(FPT=BA, FPR=2025, FYE=C1231, AE=E)")} -> #NAME? | AE8: {=_xll.BQL($C8, "PE_RATIO(FPT=BA, FPR=2026, FYE=C1231, AE=E)")} -> #NAME? | AF8: {=_xll.BQL($C8, "PE_RATIO(FPT=BA, FPR=2027, FYE=C1231, AE=E)")} -> #NAME? | AG8: {=_xll.BQL($C8, "PX_TO_SALES_RATIO(FPT=BA, FPR=2025, FYE=C1231, AE=E)")} -> #NAME? | AH8: {=_xll.BQL($C8, "PX_TO_SALES_RATIO(FPT=BA, FPR=2026, FYE=C1231, AE=E)")} -> #NAME? | AI8: {=_xll.BQL($C8, "PX_TO_SALES_RATIO(FPT=BA, FPR=2027, FYE=C1231, AE=E)")} -> #NAME? | AJ8: =IF(AC8<0,"N/A",$X8/AC8) -> #NAME? | AK8: {=IF(_xll.BQL($C8, "CURR_ENTP_VAL(FPT=A,FPO=0)/EBITDA(FPT=BA, FPR=2026, FYE=C1231, AE=E)")<0,"N/A",_xll.BQL($C8, "CURR_ENTP_VAL(FPT=A,FPO=0)/EBITDA(FPT=BA, FPR=2026, FYE=C1231, AE=E)"))} -> #NAME? | AL8: {=IF(_xll.BQL($C8, "CURR_ENTP_VAL(FPT=A,FPO=0)/EBITDA(FPT=BA, FPR=2027, FYE=C1231, AE=E)")<0,"N/A",_xll.BQL($C8, "CURR_ENTP_VAL(FPT=A,FPO=0)/EBITDA(FPT=BA, FPR=2027, FYE=C1231, AE=E)"))} -> #NAME? | AM8: =_xll.BDP($C8,AM$1) -> #NAME? | AN8: {=_xll.BQL($C8, "PX_TO_BOOK_RATIO(FPT=BA, FPR=2026, FYE=C1231, AE=E)")} -> #NAME? | AO8: {=_xll.BQL($C8, "PX_TO_BOOK_RATIO(FPT=BA, FPR=2027, FYE=C1231, AE=E)")} -> #NAME? | AP8: =_xll.BDP($C8,"BEST Px bps ratio","BEST fperiod override","27Y") -> #NAME? | AQ8: =Z8 -> #NAME? | AR8: =_xll.BDP($C8,"BEST_ROE","BEST fperiod override","26Y")/100 -> #NAME? | AS8: =_xll.BDP($C8,"BEST_ROE","BEST fperiod override","27Y")/100 -> #NAME? | AT8: =_xll.BDP($C8,AT$1) -> #NAME? | AU8: =_xll.BDP($C8,$AU$1,"BEST fperiod override","26Y") -> #NAME? | AV8: =_xll.BDP($C8,$AU$1,"BEST fperiod override","27Y") -> #NAME? | AW8: =(BP8/BN8)^(1/2)-1 -> #NAME? | AX8: =(BV8/BT8)^(1/2)-1 -> #NAME? | AY8: =(CB8/BZ8)^(1/2)-1 -> #NAME? | AZ8: {=_xll.BQL($C8, "CF_CASH_FROM_OPER(FPT=BA, FPR=2022, FYE=C1231, AE=A)", "currency=USD")/1000000000} -> #NAME? | BA8: {=_xll.BQL($C8, "CF_CASH_FROM_OPER(FPT=BA, FPR=2023, FYE=C1231, AE=A)", "currency=USD")/1000000000} -> #NAME? | BB8: {=_xll.BQL($C8, "CF_CASH_FROM_OPER(FPT=BA, FPR=2024, FYE=C1231, AE=A)", "currency=USD")/1000000000} -> #NAME? | BC8: {=_xll.BQL($C8, "CF_CASH_FROM_OPER(FPT=BA, FPR=2025, FYE=C1231, AE=E)", "currency=USD")/1000000000} -> #NAME? | BD8: {=_xll.BQL($C8, "CF_CASH_FROM_OPER(FPT=BA, FPR=2026, FYE=C1231, AE=E)", "currency=USD")/1000000000} -> #NAME? | BE8: {=_xll.BQL($C8, "CF_CASH_FROM_OPER(FPT=BA, FPR=2027, FYE=C1231, AE=E)", "currency=USD")/1000000000} -> #NAME? | BF8: {=_xll.BQL($C8, "CF_FREE_CASH_FLOW(FPT=BA, FPR=2022, FYE=C1231, AE=A)", "currency=USD")/1000000000} -> #NAME? | BG8: {=_xll.BQL($C8, "CF_FREE_CASH_FLOW(FPT=BA, FPR=2023, FYE=C1231, AE=A)", "currency=USD")/1000000000} -> #NAME? | BH8: {=_xll.BQL($C8, "CF_FREE_CASH_FLOW(FPT=BA, FPR=2024, FYE=C1231, AE=A)", "currency=USD")/1000000000} -> #NAME? | BI8: {=_xll.BQL($C8, "CF_FREE_CASH_FLOW(FPT=BA, FPR=2025, FYE=C1231, AE=E)", "currency=USD")/1000000000} -> #NAME? | BJ8: {=_xll.BQL($C8, "CF_FREE_CASH_FLOW(FPT=BA, FPR=2026, FYE=C1231, AE=E)", "currency=USD")/1000000000} -> #NAME? | BK8: {=_xll.BQL($C8, "CF_FREE_CASH_FLOW(FPT=BA, FPR=2027, FYE=C1231, AE=E)", "currency=USD")/1000000000} -> #NAME? | BL8: {=_xll.BQL($C8, "SALES_REV_TURN(FPT=BA, FPR=2022, FYE=C1231, AE=A)", "currency=USD")/1000000000} -> #NAME? | BM8: {=_xll.BQL($C8, "SALES_REV_TURN(FPT=BA, FPR=2023, FYE=C1231, AE=A)", "currency=USD")/1000000000} -> #NAME? | BN8: {=_xll.BQL($C8, "SALES_REV_TURN(FPT=BA, FPR=2024, FYE=C1231, AE=A)", "currency=USD")/1000000000} -> #NAME? | BO8: {=_xll.BQL($C8, "SALES_REV_TURN(FPT=BA, FPR=2025, FYE=C1231, AE=E)", "currency=USD")/1000000000} -> #NAME? | BP8: {=_xll.BQL($C8, "SALES_REV_TURN(FPT=BA, FPR=2026, FYE=C1231, AE=E)", "currency=USD")/1000000000} -> #NAME? | BQ8: {=_xll.BQL($C8, "SALES_REV_TURN(FPT=BA, FPR=2027, FYE=C1231, AE=E)", "currency=USD")/1000000000} -> #NAME? | BR8: {=_xll.BQL($C8, "EBITDA(FPT=BA, FPR=2022, FYE=C1231, AE=A)", "currency=USD")/1000000000} -> #NAME? | BS8: {=_xll.BQL($C8, "EBITDA(FPT=BA, FPR=2023, FYE=C1231, AE=A)", "currency=USD")/1000000000} -> #NAME? | BT8: {=_xll.BQL($C8, "EBITDA(FPT=BA, FPR=2024, FYE=C1231, AE=A)", "currency=USD")/1000000000} -> #NAME? | BU8: {=_xll.BQL($C8, "EBITDA(FPT=BA, FPR=2025, FYE=C1231, AE=E)", "currency=USD")/1000000000} -> #NAME? | BV8: {=_xll.BQL($C8, "EBITDA(FPT=BA, FPR=2026, FYE=C1231, AE=E)", "currency=USD")/1000000000} -> #NAME? | BW8: {=_xll.BQL($C8, "EBITDA(FPT=BA, FPR=2027, FYE=C1231, AE=E)", "currency=USD")/1000000000} -> #NAME? | BX8: {=_xll.BQL($C8, "NET_INCOME(FPT=BA, FPR=2022, FYE=C1231, AE=A)", "currency=USD")/1000000000} -> #NAME? | BY8: {=_xll.BQL($C8, "NET_INCOME(FPT=BA, FPR=2023, FYE=C1231, AE=A)", "currency=USD")/1000000000} -> #NAME? | BZ8: {=_xll.BQL($C8, "NET_INCOME(FPT=BA, FPR=2024, FYE=C1231, AE=A)", "currency=USD")/1000000000} -> #NAME? | CA8: {=_xll.BQL($C8, "NET_INCOME(FPT=BA, FPR=2025, FYE=C1231, AE=E)", "currency=USD")/1000000000} -> #NAME? | CB8: {=_xll.BQL($C8, "NET_INCOME(FPT=BA, FPR=2026, FYE=C1231, AE=E)", "currency=USD")/1000000000} -> #NAME? | CC8: {=_xll.BQL($C8, "NET_INCOME(FPT=BA, FPR=2027, FYE=C1231, AE=E)", "currency=USD")/1000000000} -> #NAME? | CD8: {=-_xll.BQL($C8, "CF_DVD_PAID(FPT=BA, FPR=2024, FYE=C1231, AE=A)", "currency=USD")/1000000000} -> #NAME? | CE8: {=-_xll.BQL($C8, "CF_DVD_PAID(FPT=BA, FPR=2025, FYE=C1231, AE=E)", "currency=USD")/1000000000} -> #NAME? | CF8: {=-_xll.BQL($C8, "CF_DVD_PAID(FPT=BA, FPR=2026, FYE=C1231, AE=E)", "currency=USD")/1000000000} -> #NAME? | CG8: {=-_xll.BQL($C8, "CF_DVD_PAID(FPT=BA, FPR=2027, FYE=C1231, AE=E)", "currency=USD")/1000000000} -> #NAME? | CH8: =CD8/$F8 -> #NAME? | CI8: =CE8/$F8 -> #NAME? | CJ8: =CF8/$F8 -> #NAME? | CK8: =CG8/$F8 -> #NAME? | CL8: {=_xll.BDP($C8,"INTERVAL_AVG", "MARKET_DATA_OVERRIDE=turnover", "CALC_INTERVAL=5D","CRNCY=HKD")/1000000} -> #NAME? | CM8: {=_xll.BDP($C8,"INTERVAL_AVG", "MARKET_DATA_OVERRIDE=turnover", "CALC_INTERVAL=10D","CRNCY=HKD")/1000000} -> #NAME? | CN8: {=_xll.BDP($C8,"INTERVAL_AVG", "MARKET_DATA_OVERRIDE=turnover", "CALC_INTERVAL=20D","CRNCY=HKD")/1000000} -> #NAME? | CO8: {=_xll.BDP($C8,"INTERVAL_AVG", "MARKET_DATA_OVERRIDE=turnover", "CALC_INTERVAL=1m","CRNCY=HKD")/1000000} -> #NAME? | CP8: {=_xll.BDP($C8,"INTERVAL_AVG", "MARKET_DATA_OVERRIDE=turnover", "CALC_INTERVAL=3M","CRNCY=HKD")/1000000} -> #NAME? | CQ8: {=_xll.BDP($C8,"INTERVAL_AVG", "MARKET_DATA_OVERRIDE=turnover", "CALC_INTERVAL=6M","CRNCY=HKD")/1000000} -> #NAME? | CR8: =_xll.BDP($C8,"chg pct 1m")/100 -> #NAME? | CS8: =_xll.BDP($C8,"chg pct 3m")/100 -> #NAME? | CT8: =_xll.BDP($C8,"chg pct 6m")/100 -> #NAME? | CU8: =_xll.BDP($C8,"chg pct 1yr")/100 -> #NAME? | CV8: =_xll.BDP($C8,"chg pct ytd")/100 -> #NAME? | CW8: {=_xll.BQL($C8, "volatility(calc_interval=range(-1M, 0D))")} -> #NAME? | CX8: {=_xll.BQL($C8, "volatility(calc_interval=range(-3M, 0D))")} -> #NAME? | CY8: {=_xll.BQL($C8, "volatility(calc_interval=range(-6M, 0D))")} -> #NAME? | CZ8: =_xll.BDP($C8,CZ$1) -> #NAME?
A9: =_xll.BDP($C9,"security name") -> #NAME? | B9: =_xll.BDP($C9,"NAME_CHINESE_SIMPLIFIED") -> #NAME? | C9: aeo us Equity | D9: =_xll.BDP($C9,"LISTING_DATE") -> #NAME? | E9: =_xll.BDP($C9,E$1,"EQY_FUND_CRNCY="&$B$1) -> #NAME? | F9: =_xll.BDP($C9,F$1,"EQY_FUND_CRNCY="&$C$1) -> #NAME? | G9: =_xll.BDP($C9,G$1) -> #NAME? | H9: =_xll.BDP($C9,H$1,"EQY_FUND_CRNCY="&$B$1) -> #NAME? | I9: =_xll.BDP($C9,I$1,"EQY_FUND_CRNCY="&$C$1) -> #NAME? | J9: =_xll.BDP($C9,J$1,"EQY_FUND_CRNCY="&$B$1) -> #NAME? | K9: =_xll.BDP($C9,K$1,"EQY_FUND_CRNCY="&$C$1) -> #NAME? | L9: =_xll.BDP($C9,L$1,"EQY_FUND_CRNCY="&$B$1) -> #NAME? | M9: =_xll.BDP($C9,M$1,"EQY_FUND_CRNCY="&$C$1) -> #NAME? | N9: =_xll.BDP($C9,N$1)/100 -> #NAME? | O9: =_xll.BDP($C9,O$1)/100 -> #NAME? | P9: =_xll.BDP($C9,P$1)/100 -> #NAME? | Q9: =_xll.BDP($C9,Q$1)/100 -> #NAME? | R9: =_xll.BDP($C9,R$1)/100 -> #NAME? | S9: =_xll.BDP($C9,S$1)/100 -> #NAME? | T9: =_xll.BDP($C9,T$1)/100 -> #NAME? | U9: =_xll.BDP($C9,U$1)/100 -> #NAME? | ... W9: =_xll.BDP($C9,W$1)/100 -> #NAME? | X9: {=_xll.BDP($C9,"CRNCY_ADJ_CURR_EV", "EQY_FUND_CRNCY=HKD")} -> #NAME? | Y9: {=_xll.BDP($C9,"CRNCY_ADJ_CURR_EV", "EQY_FUND_CRNCY=USD")} -> #NAME? | Z9: =_xll.BDP($C9,Z$1)/100 -> #NAME? | AA9: =_xll.BDP($C9,"TRAIL_12M_NET_SALES","EQY_FUND_CRNCY=HKD") -> #NAME? | AB9: =_xll.BDP($C9,"TRAIL_12M_NET_INC","EQY_FUND_CRNCY=HKD") -> #NAME? | AC9: =_xll.BDP($C9,"TRAIL_12M_EBITDA","EQY_FUND_CRNCY=HKD") -> #NAME? | AD9: {=_xll.BQL($C9, "PE_RATIO(FPT=BA, FPR=2025, FYE=C1231, AE=E)")} -> #NAME? | AE9: {=_xll.BQL($C9, "PE_RATIO(FPT=BA, FPR=2026, FYE=C1231, AE=E)")} -> #NAME? | AF9: {=_xll.BQL($C9, "PE_RATIO(FPT=BA, FPR=2027, FYE=C1231, AE=E)")} -> #NAME? | AG9: {=_xll.BQL($C9, "PX_TO_SALES_RATIO(FPT=BA, FPR=2025, FYE=C1231, AE=E)")} -> #NAME? | AH9: {=_xll.BQL($C9, "PX_TO_SALES_RATIO(FPT=BA, FPR=2026, FYE=C1231, AE=E)")} -> #NAME? | AI9: {=_xll.BQL($C9, "PX_TO_SALES_RATIO(FPT=BA, FPR=2027, FYE=C1231, AE=E)")} -> #NAME? | AJ9: =IF(AC9<0,"N/A",$X9/AC9) -> #NAME? | AK9: {=IF(_xll.BQL($C9, "CURR_ENTP_VAL(FPT=A,FPO=0)/EBITDA(FPT=BA, FPR=2026, FYE=C1231, AE=E)")<0,"N/A",_xll.BQL($C9, "CURR_ENTP_VAL(FPT=A,FPO=0)/EBITDA(FPT=BA, FPR=2026, FYE=C1231, AE=E)"))} -> #NAME? | AL9: {=IF(_xll.BQL($C9, "CURR_ENTP_VAL(FPT=A,FPO=0)/EBITDA(FPT=BA, FPR=2027, FYE=C1231, AE=E)")<0,"N/A",_xll.BQL($C9, "CURR_ENTP_VAL(FPT=A,FPO=0)/EBITDA(FPT=BA, FPR=2027, FYE=C1231, AE=E)"))} -> #NAME? | AM9: =_xll.BDP($C9,AM$1) -> #NAME? | AN9: {=_xll.BQL($C9, "PX_TO_BOOK_RATIO(FPT=BA, FPR=2026, FYE=C1231, AE=E)")} -> #NAME? | AO9: {=_xll.BQL($C9, "PX_TO_BOOK_RATIO(FPT=BA, FPR=2027, FYE=C1231, AE=E)")} -> #NAME? | AP9: =_xll.BDP($C9,"BEST Px bps ratio","BEST fperiod override","27Y") -> #NAME? | AQ9: =Z9 -> #NAME? | AR9: =_xll.BDP($C9,"BEST_ROE","BEST fperiod override","26Y")/100 -> #NAME? | AS9: =_xll.BDP($C9,"BEST_ROE","BEST fperiod override","27Y")/100 -> #NAME? | AT9: =_xll.BDP($C9,AT$1) -> #NAME? | AU9: =_xll.BDP($C9,$AU$1,"BEST fperiod override","26Y") -> #NAME? | AV9: =_xll.BDP($C9,$AU$1,"BEST fperiod override","27Y") -> #NAME? | AW9: =(BP9/BN9)^(1/2)-1 -> #NAME? | AX9: =(BV9/BT9)^(1/2)-1 -> #NAME? | AY9: =(CB9/BZ9)^(1/2)-1 -> #NAME? | AZ9: {=_xll.BQL($C9, "CF_CASH_FROM_OPER(FPT=BA, FPR=2022, FYE=C1231, AE=A)", "currency=USD")/1000000000} -> #NAME? | BA9: {=_xll.BQL($C9, "CF_CASH_FROM_OPER(FPT=BA, FPR=2023, FYE=C1231, AE=A)", "currency=USD")/1000000000} -> #NAME? | BB9: {=_xll.BQL($C9, "CF_CASH_FROM_OPER(FPT=BA, FPR=2024, FYE=C1231, AE=A)", "currency=USD")/1000000000} -> #NAME? | BC9: {=_xll.BQL($C9, "CF_CASH_FROM_OPER(FPT=BA, FPR=2025, FYE=C1231, AE=E)", "currency=USD")/1000000000} -> #NAME? | BD9: {=_xll.BQL($C9, "CF_CASH_FROM_OPER(FPT=BA, FPR=2026, FYE=C1231, AE=E)", "currency=USD")/1000000000} -> #NAME? | BE9: {=_xll.BQL($C9, "CF_CASH_FROM_OPER(FPT=BA, FPR=2027, FYE=C1231, AE=E)", "currency=USD")/1000000000} -> #NAME? | BF9: {=_xll.BQL($C9, "CF_FREE_CASH_FLOW(FPT=BA, FPR=2022, FYE=C1231, AE=A)", "currency=USD")/1000000000} -> #NAME? | BG9: {=_xll.BQL($C9, "CF_FREE_CASH_FLOW(FPT=BA, FPR=2023, FYE=C1231, AE=A)", "currency=USD")/1000000000} -> #NAME? | BH9: {=_xll.BQL($C9, "CF_FREE_CASH_FLOW(FPT=BA, FPR=2024, FYE=C1231, AE=A)", "currency=USD")/1000000000} -> #NAME? | BI9: {=_xll.BQL($C9, "CF_FREE_CASH_FLOW(FPT=BA, FPR=2025, FYE=C1231, AE=E)", "currency=USD")/1000000000} -> #NAME? | BJ9: {=_xll.BQL($C9, "CF_FREE_CASH_FLOW(FPT=BA, FPR=2026, FYE=C1231, AE=E)", "currency=USD")/1000000000} -> #NAME? | BK9: {=_xll.BQL($C9, "CF_FREE_CASH_FLOW(FPT=BA, FPR=2027, FYE=C1231, AE=E)", "currency=USD")/1000000000} -> #NAME? | BL9: {=_xll.BQL($C9, "SALES_REV_TURN(FPT=BA, FPR=2022, FYE=C1231, AE=A)", "currency=USD")/1000000000} -> #NAME? | BM9: {=_xll.BQL($C9, "SALES_REV_TURN(FPT=BA, FPR=2023, FYE=C1231, AE=A)", "currency=USD")/1000000000} -> #NAME? | BN9: {=_xll.BQL($C9, "SALES_REV_TURN(FPT=BA, FPR=2024, FYE=C1231, AE=A)", "currency=USD")/1000000000} -> #NAME? | BO9: {=_xll.BQL($C9, "SALES_REV_TURN(FPT=BA, FPR=2025, FYE=C1231, AE=E)", "currency=USD")/1000000000} -> #NAME? | BP9: {=_xll.BQL($C9, "SALES_REV_TURN(FPT=BA, FPR=2026, FYE=C1231, AE=E)", "currency=USD")/1000000000} -> #NAME? | BQ9: {=_xll.BQL($C9, "SALES_REV_TURN(FPT=BA, FPR=2027, FYE=C1231, AE=E)", "currency=USD")/1000000000} -> #NAME? | BR9: {=_xll.BQL($C9, "EBITDA(FPT=BA, FPR=2022, FYE=C1231, AE=A)", "currency=USD")/1000000000} -> #NAME? | BS9: {=_xll.BQL($C9, "EBITDA(FPT=BA, FPR=2023, FYE=C1231, AE=A)", "currency=USD")/1000000000} -> #NAME? | BT9: {=_xll.BQL($C9, "EBITDA(FPT=BA, FPR=2024, FYE=C1231, AE=A)", "currency=USD")/1000000000} -> #NAME? | BU9: {=_xll.BQL($C9, "EBITDA(FPT=BA, FPR=2025, FYE=C1231, AE=E)", "currency=USD")/1000000000} -> #NAME? | BV9: {=_xll.BQL($C9, "EBITDA(FPT=BA, FPR=2026, FYE=C1231, AE=E)", "currency=USD")/1000000000} -> #NAME? | BW9: {=_xll.BQL($C9, "EBITDA(FPT=BA, FPR=2027, FYE=C1231, AE=E)", "currency=USD")/1000000000} -> #NAME? | BX9: {=_xll.BQL($C9, "NET_INCOME(FPT=BA, FPR=2022, FYE=C1231, AE=A)", "currency=USD")/1000000000} -> #NAME? | BY9: {=_xll.BQL($C9, "NET_INCOME(FPT=BA, FPR=2023, FYE=C1231, AE=A)", "currency=USD")/1000000000} -> #NAME? | BZ9: {=_xll.BQL($C9, "NET_INCOME(FPT=BA, FPR=2024, FYE=C1231, AE=A)", "currency=USD")/1000000000} -> #NAME? | CA9: {=_xll.BQL($C9, "NET_INCOME(FPT=BA, FPR=2025, FYE=C1231, AE=E)", "currency=USD")/1000000000} -> #NAME? | CB9: {=_xll.BQL($C9, "NET_INCOME(FPT=BA, FPR=2026, FYE=C1231, AE=E)", "currency=USD")/1000000000} -> #NAME? | CC9: {=_xll.BQL($C9, "NET_INCOME(FPT=BA, FPR=2027, FYE=C1231, AE=E)", "currency=USD")/1000000000} -> #NAME? | CD9: {=-_xll.BQL($C9, "CF_DVD_PAID(FPT=BA, FPR=2024, FYE=C1231, AE=A)", "currency=USD")/1000000000} -> #NAME? | CE9: {=-_xll.BQL($C9, "CF_DVD_PAID(FPT=BA, FPR=2025, FYE=C1231, AE=E)", "currency=USD")/1000000000} -> #NAME? | CF9: {=-_xll.BQL($C9, "CF_DVD_PAID(FPT=BA, FPR=2026, FYE=C1231, AE=E)", "currency=USD")/1000000000} -> #NAME? | CG9: {=-_xll.BQL($C9, "CF_DVD_PAID(FPT=BA, FPR=2027, FYE=C1231, AE=E)", "currency=USD")/1000000000} -> #NAME? | CH9: =CD9/$F9 -> #NAME? | CI9: =CE9/$F9 -> #NAME? | CJ9: =CF9/$F9 -> #NAME? | CK9: =CG9/$F9 -> #NAME? | CL9: {=_xll.BDP($C9,"INTERVAL_AVG", "MARKET_DATA_OVERRIDE=turnover", "CALC_INTERVAL=5D","CRNCY=HKD")/1000000} -> #NAME? | CM9: {=_xll.BDP($C9,"INTERVAL_AVG", "MARKET_DATA_OVERRIDE=turnover", "CALC_INTERVAL=10D","CRNCY=HKD")/1000000} -> #NAME? | CN9: {=_xll.BDP($C9,"INTERVAL_AVG", "MARKET_DATA_OVERRIDE=turnover", "CALC_INTERVAL=20D","CRNCY=HKD")/1000000} -> #NAME? | CO9: {=_xll.BDP($C9,"INTERVAL_AVG", "MARKET_DATA_OVERRIDE=turnover", "CALC_INTERVAL=1m","CRNCY=HKD")/1000000} -> #NAME? | CP9: {=_xll.BDP($C9,"INTERVAL_AVG", "MARKET_DATA_OVERRIDE=turnover", "CALC_INTERVAL=3M","CRNCY=HKD")/1000000} -> #NAME? | CQ9: {=_xll.BDP($C9,"INTERVAL_AVG", "MARKET_DATA_OVERRIDE=turnover", "CALC_INTERVAL=6M","CRNCY=HKD")/1000000} -> #NAME? | CR9: =_xll.BDP($C9,"chg pct 1m")/100 -> #NAME? | CS9: =_xll.BDP($C9,"chg pct 3m")/100 -> #NAME? | CT9: =_xll.BDP($C9,"chg pct 6m")/100 -> #NAME? | CU9: =_xll.BDP($C9,"chg pct 1yr")/100 -> #NAME? | CV9: =_xll.BDP($C9,"chg pct ytd")/100 -> #NAME? | CW9: {=_xll.BQL($C9, "volatility(calc_interval=range(-1M, 0D))")} -> #NAME? | CX9: {=_xll.BQL($C9, "volatility(calc_interval=range(-3M, 0D))")} -> #NAME? | CY9: {=_xll.BQL($C9, "volatility(calc_interval=range(-6M, 0D))")} -> #NAME? | CZ9: =_xll.BDP($C9,CZ$1) -> #NAME?
A10: =_xll.BDP($C10,"security name") -> #NAME? | B10: =_xll.BDP($C10,"NAME_CHINESE_SIMPLIFIED") -> #NAME? | C10: cost us Equity | D10: =_xll.BDP($C10,"LISTING_DATE") -> #NAME? | E10: =_xll.BDP($C10,E$1,"EQY_FUND_CRNCY="&$B$1) -> #NAME? | F10: =_xll.BDP($C10,F$1,"EQY_FUND_CRNCY="&$C$1) -> #NAME? | G10: =_xll.BDP($C10,G$1) -> #NAME? | H10: =_xll.BDP($C10,H$1,"EQY_FUND_CRNCY="&$B$1) -> #NAME? | I10: =_xll.BDP($C10,I$1,"EQY_FUND_CRNCY="&$C$1) -> #NAME? | J10: =_xll.BDP($C10,J$1,"EQY_FUND_CRNCY="&$B$1) -> #NAME? | K10: =_xll.BDP($C10,K$1,"EQY_FUND_CRNCY="&$C$1) -> #NAME? | L10: =_xll.BDP($C10,L$1,"EQY_FUND_CRNCY="&$B$1) -> #NAME? | M10: =_xll.BDP($C10,M$1,"EQY_FUND_CRNCY="&$C$1) -> #NAME? | N10: =_xll.BDP($C10,N$1)/100 -> #NAME? | O10: =_xll.BDP($C10,O$1)/100 -> #NAME? | P10: =_xll.BDP($C10,P$1)/100 -> #NAME? | Q10: =_xll.BDP($C10,Q$1)/100 -> #NAME? | R10: =_xll.BDP($C10,R$1)/100 -> #NAME? | S10: =_xll.BDP($C10,S$1)/100 -> #NAME? | T10: =_xll.BDP($C10,T$1)/100 -> #NAME? | U10: =_xll.BDP($C10,U$1)/100 -> #NAME? | ... W10: =_xll.BDP($C10,W$1)/100 -> #NAME? | X10: {=_xll.BDP($C10,"CRNCY_ADJ_CURR_EV", "EQY_FUND_CRNCY=HKD")} -> #NAME? | Y10: {=_xll.BDP($C10,"CRNCY_ADJ_CURR_EV", "EQY_FUND_CRNCY=USD")} -> #NAME? | Z10: =_xll.BDP($C10,Z$1)/100 -> #NAME? | AA10: =_xll.BDP($C10,"TRAIL_12M_NET_SALES","EQY_FUND_CRNCY=HKD") -> #NAME? | AB10: =_xll.BDP($C10,"TRAIL_12M_NET_INC","EQY_FUND_CRNCY=HKD") -> #NAME? | AC10: =_xll.BDP($C10,"TRAIL_12M_EBITDA","EQY_FUND_CRNCY=HKD") -> #NAME? | AD10: {=_xll.BQL($C10, "PE_RATIO(FPT=BA, FPR=2025, FYE=C1231, AE=E)")} -> #NAME? | AE10: {=_xll.BQL($C10, "PE_RATIO(FPT=BA, FPR=2026, FYE=C1231, AE=E)")} -> #NAME? | AF10: {=_xll.BQL($C10, "PE_RATIO(FPT=BA, FPR=2027, FYE=C1231, AE=E)")} -> #NAME? | AG10: {=_xll.BQL($C10, "PX_TO_SALES_RATIO(FPT=BA, FPR=2025, FYE=C1231, AE=E)")} -> #NAME? | AH10: {=_xll.BQL($C10, "PX_TO_SALES_RATIO(FPT=BA, FPR=2026, FYE=C1231, AE=E)")} -> #NAME? | AI10: {=_xll.BQL($C10, "PX_TO_SALES_RATIO(FPT=BA, FPR=2027, FYE=C1231, AE=E)")} -> #NAME? | AJ10: =IF(AC10<0,"N/A",$X10/AC10) -> #NAME? | AK10: {=IF(_xll.BQL($C10, "CURR_ENTP_VAL(FPT=A,FPO=0)/EBITDA(FPT=BA, FPR=2026, FYE=C1231, AE=E)")<0,"N/A",_xll.BQL($C10, "CURR_ENTP_VAL(FPT=A,FPO=0)/EBITDA(FPT=BA, FPR=2026, FYE=C1231, AE=E)"))} -> #NAME? | AL10: {=IF(_xll.BQL($C10, "CURR_ENTP_VAL(FPT=A,FPO=0)/EBITDA(FPT=BA, FPR=2027, FYE=C1231, AE=E)")<0,"N/A",_xll.BQL($C10, "CURR_ENTP_VAL(FPT=A,FPO=0)/EBITDA(FPT=BA, FPR=2027, FYE=C1231, AE=E)"))} -> #NAME? | AM10: =_xll.BDP($C10,AM$1) -> #NAME? | AN10: {=_xll.BQL($C10, "PX_TO_BOOK_RATIO(FPT=BA, FPR=2026, FYE=C1231, AE=E)")} -> #NAME? | AO10: {=_xll.BQL($C10, "PX_TO_BOOK_RATIO(FPT=BA, FPR=2027, FYE=C1231, AE=E)")} -> #NAME? | AP10: =_xll.BDP($C10,"BEST Px bps ratio","BEST fperiod override","27Y") -> #NAME? | AQ10: =Z10 -> #NAME? | AR10: =_xll.BDP($C10,"BEST_ROE","BEST fperiod override","26Y")/100 -> #NAME? | AS10: =_xll.BDP($C10,"BEST_ROE","BEST fperiod override","27Y")/100 -> #NAME? | AT10: =_xll.BDP($C10,AT$1) -> #NAME? | AU10: =_xll.BDP($C10,$AU$1,"BEST fperiod override","26Y") -> #NAME? | AV10: =_xll.BDP($C10,$AU$1,"BEST fperiod override","27Y") -> #NAME? | AW10: =(BP10/BN10)^(1/2)-1 -> #NAME? | AX10: =(BV10/BT10)^(1/2)-1 -> #NAME? | AY10: =(CB10/BZ10)^(1/2)-1 -> #NAME? | AZ10: {=_xll.BQL($C10, "CF_CASH_FROM_OPER(FPT=BA, FPR=2022, FYE=C1231, AE=A)", "currency=USD")/1000000000} -> #NAME? | BA10: {=_xll.BQL($C10, "CF_CASH_FROM_OPER(FPT=BA, FPR=2023, FYE=C1231, AE=A)", "currency=USD")/1000000000} -> #NAME? | BB10: {=_xll.BQL($C10, "CF_CASH_FROM_OPER(FPT=BA, FPR=2024, FYE=C1231, AE=A)", "currency=USD")/1000000000} -> #NAME? | BC10: {=_xll.BQL($C10, "CF_CASH_FROM_OPER(FPT=BA, FPR=2025, FYE=C1231, AE=E)", "currency=USD")/1000000000} -> #NAME? | BD10: {=_xll.BQL($C10, "CF_CASH_FROM_OPER(FPT=BA, FPR=2026, FYE=C1231, AE=E)", "currency=USD")/1000000000} -> #NAME? | BE10: {=_xll.BQL($C10, "CF_CASH_FROM_OPER(FPT=BA, FPR=2027, FYE=C1231, AE=E)", "currency=USD")/1000000000} -> #NAME? | BF10: {=_xll.BQL($C10, "CF_FREE_CASH_FLOW(FPT=BA, FPR=2022, FYE=C1231, AE=A)", "currency=USD")/1000000000} -> #NAME? | BG10: {=_xll.BQL($C10, "CF_FREE_CASH_FLOW(FPT=BA, FPR=2023, FYE=C1231, AE=A)", "currency=USD")/1000000000} -> #NAME? | BH10: {=_xll.BQL($C10, "CF_FREE_CASH_FLOW(FPT=BA, FPR=2024, FYE=C1231, AE=A)", "currency=USD")/1000000000} -> #NAME? | BI10: {=_xll.BQL($C10, "CF_FREE_CASH_FLOW(FPT=BA, FPR=2025, FYE=C1231, AE=E)", "currency=USD")/1000000000} -> #NAME? | BJ10: {=_xll.BQL($C10, "CF_FREE_CASH_FLOW(FPT=BA, FPR=2026, FYE=C1231, AE=E)", "currency=USD")/1000000000} -> #NAME? | BK10: {=_xll.BQL($C10, "CF_FREE_CASH_FLOW(FPT=BA, FPR=2027, FYE=C1231, AE=E)", "currency=USD")/1000000000} -> #NAME? | BL10: {=_xll.BQL($C10, "SALES_REV_TURN(FPT=BA, FPR=2022, FYE=C1231, AE=A)", "currency=USD")/1000000000} -> #NAME? | BM10: {=_xll.BQL($C10, "SALES_REV_TURN(FPT=BA, FPR=2023, FYE=C1231, AE=A)", "currency=USD")/1000000000} -> #NAME? | BN10: {=_xll.BQL($C10, "SALES_REV_TURN(FPT=BA, FPR=2024, FYE=C1231, AE=A)", "currency=USD")/1000000000} -> #NAME? | BO10: {=_xll.BQL($C10, "SALES_REV_TURN(FPT=BA, FPR=2025, FYE=C1231, AE=E)", "currency=USD")/1000000000} -> #NAME? | BP10: {=_xll.BQL($C10, "SALES_REV_TURN(FPT=BA, FPR=2026, FYE=C1231, AE=E)", "currency=USD")/1000000000} -> #NAME? | BQ10: {=_xll.BQL($C10, "SALES_REV_TURN(FPT=BA, FPR=2027, FYE=C1231, AE=E)", "currency=USD")/1000000000} -> #NAME? | BR10: {=_xll.BQL($C10, "EBITDA(FPT=BA, FPR=2022, FYE=C1231, AE=A)", "currency=USD")/1000000000} -> #NAME? | BS10: {=_xll.BQL($C10, "EBITDA(FPT=BA, FPR=2023, FYE=C1231, AE=A)", "currency=USD")/1000000000} -> #NAME? | BT10: {=_xll.BQL($C10, "EBITDA(FPT=BA, FPR=2024, FYE=C1231, AE=A)", "currency=USD")/1000000000} -> #NAME? | BU10: {=_xll.BQL($C10, "EBITDA(FPT=BA, FPR=2025, FYE=C1231, AE=E)", "currency=USD")/1000000000} -> #NAME? | BV10: {=_xll.BQL($C10, "EBITDA(FPT=BA, FPR=2026, FYE=C1231, AE=E)", "currency=USD")/1000000000} -> #NAME? | BW10: {=_xll.BQL($C10, "EBITDA(FPT=BA, FPR=2027, FYE=C1231, AE=E)", "currency=USD")/1000000000} -> #NAME? | BX10: {=_xll.BQL($C10, "NET_INCOME(FPT=BA, FPR=2022, FYE=C1231, AE=A)", "currency=USD")/1000000000} -> #NAME? | BY10: {=_xll.BQL($C10, "NET_INCOME(FPT=BA, FPR=2023, FYE=C1231, AE=A)", "currency=USD")/1000000000} -> #NAME? | BZ10: {=_xll.BQL($C10, "NET_INCOME(FPT=BA, FPR=2024, FYE=C1231, AE=A)", "currency=USD")/1000000000} -> #NAME? | CA10: {=_xll.BQL($C10, "NET_INCOME(FPT=BA, FPR=2025, FYE=C1231, AE=E)", "currency=USD")/1000000000} -> #NAME? | CB10: {=_xll.BQL($C10, "NET_INCOME(FPT=BA, FPR=2026, FYE=C1231, AE=E)", "currency=USD")/1000000000} -> #NAME? | CC10: {=_xll.BQL($C10, "NET_INCOME(FPT=BA, FPR=2027, FYE=C1231, AE=E)", "currency=USD")/1000000000} -> #NAME? | CD10: {=-_xll.BQL($C10, "CF_DVD_PAID(FPT=BA, FPR=2024, FYE=C1231, AE=A)", "currency=USD")/1000000000} -> #NAME? | CE10: {=-_xll.BQL($C10, "CF_DVD_PAID(FPT=BA, FPR=2025, FYE=C1231, AE=E)", "currency=USD")/1000000000} -> #NAME? | CF10: {=-_xll.BQL($C10, "CF_DVD_PAID(FPT=BA, FPR=2026, FYE=C1231, AE=E)", "currency=USD")/1000000000} -> #NAME? | CG10: {=-_xll.BQL($C10, "CF_DVD_PAID(FPT=BA, FPR=2027, FYE=C1231, AE=E)", "currency=USD")/1000000000} -> #NAME? | CH10: =CD10/$F10 -> #NAME? | CI10: =CE10/$F10 -> #NAME? | CJ10: =CF10/$F10 -> #NAME? | CK10: =CG10/$F10 -> #NAME? | CL10: {=_xll.BDP($C10,"INTERVAL_AVG", "MARKET_DATA_OVERRIDE=turnover", "CALC_INTERVAL=5D","CRNCY=HKD")/1000000} -> #NAME? | CM10: {=_xll.BDP($C10,"INTERVAL_AVG", "MARKET_DATA_OVERRIDE=turnover", "CALC_INTERVAL=10D","CRNCY=HKD")/1000000} -> #NAME? | CN10: {=_xll.BDP($C10,"INTERVAL_AVG", "MARKET_DATA_OVERRIDE=turnover", "CALC_INTERVAL=20D","CRNCY=HKD")/1000000} -> #NAME? | CO10: {=_xll.BDP($C10,"INTERVAL_AVG", "MARKET_DATA_OVERRIDE=turnover", "CALC_INTERVAL=1m","CRNCY=HKD")/1000000} -> #NAME? | CP10: {=_xll.BDP($C10,"INTERVAL_AVG", "MARKET_DATA_OVERRIDE=turnover", "CALC_INTERVAL=3M","CRNCY=HKD")/1000000} -> #NAME? | CQ10: {=_xll.BDP($C10,"INTERVAL_AVG", "MARKET_DATA_OVERRIDE=turnover", "CALC_INTERVAL=6M","CRNCY=HKD")/1000000} -> #NAME? | CR10: =_xll.BDP($C10,"chg pct 1m")/100 -> #NAME? | CS10: =_xll.BDP($C10,"chg pct 3m")/100 -> #NAME? | CT10: =_xll.BDP($C10,"chg pct 6m")/100 -> #NAME? | CU10: =_xll.BDP($C10,"chg pct 1yr")/100 -> #NAME? | CV10: =_xll.BDP($C10,"chg pct ytd")/100 -> #NAME? | CW10: {=_xll.BQL($C10, "volatility(calc_interval=range(-1M, 0D))")} -> #NAME? | CX10: {=_xll.BQL($C10, "volatility(calc_interval=range(-3M, 0D))")} -> #NAME? | CY10: {=_xll.BQL($C10, "volatility(calc_interval=range(-6M, 0D))")} -> #NAME? | CZ10: =_xll.BDP($C10,CZ$1) -> #NAME?
A11: =_xll.BDP($C11,"security name") -> #NAME? | B11: =_xll.BDP($C11,"NAME_CHINESE_SIMPLIFIED") -> #NAME? | C11: abf ln EQUITY | D11: =_xll.BDP($C11,"LISTING_DATE") -> #NAME? | E11: =_xll.BDP($C11,E$1,"EQY_FUND_CRNCY="&$B$1) -> #NAME? | F11: =_xll.BDP($C11,F$1,"EQY_FUND_CRNCY="&$C$1) -> #NAME? | G11: =_xll.BDP($C11,G$1) -> #NAME? | H11: =_xll.BDP($C11,H$1,"EQY_FUND_CRNCY="&$B$1) -> #NAME? | I11: =_xll.BDP($C11,I$1,"EQY_FUND_CRNCY="&$C$1) -> #NAME? | J11: =_xll.BDP($C11,J$1,"EQY_FUND_CRNCY="&$B$1) -> #NAME? | K11: =_xll.BDP($C11,K$1,"EQY_FUND_CRNCY="&$C$1) -> #NAME? | L11: =_xll.BDP($C11,L$1,"EQY_FUND_CRNCY="&$B$1) -> #NAME? | M11: =_xll.BDP($C11,M$1,"EQY_FUND_CRNCY="&$C$1) -> #NAME? | N11: =_xll.BDP($C11,N$1)/100 -> #NAME? | O11: =_xll.BDP($C11,O$1)/100 -> #NAME? | P11: =_xll.BDP($C11,P$1)/100 -> #NAME? | Q11: =_xll.BDP($C11,Q$1)/100 -> #NAME? | R11: =_xll.BDP($C11,R$1)/100 -> #NAME? | S11: =_xll.BDP($C11,S$1)/100 -> #NAME? | T11: =_xll.BDP($C11,T$1)/100 -> #NAME? | U11: =_xll.BDP($C11,U$1)/100 -> #NAME? | ... W11: =_xll.BDP($C11,W$1)/100 -> #NAME? | X11: {=_xll.BDP($C11,"CRNCY_ADJ_CURR_EV", "EQY_FUND_CRNCY=HKD")} -> #NAME? | Y11: {=_xll.BDP($C11,"CRNCY_ADJ_CURR_EV", "EQY_FUND_CRNCY=USD")} -> #NAME? | Z11: =_xll.BDP($C11,Z$1)/100 -> #NAME? | AA11: =_xll.BDP($C11,"TRAIL_12M_NET_SALES","EQY_FUND_CRNCY=HKD") -> #NAME? | AB11: =_xll.BDP($C11,"TRAIL_12M_NET_INC","EQY_FUND_CRNCY=HKD") -> #NAME? | AC11: =_xll.BDP($C11,"TRAIL_12M_EBITDA","EQY_FUND_CRNCY=HKD") -> #NAME? | AD11: {=_xll.BQL($C11, "PE_RATIO(FPT=BA, FPR=2025, FYE=C1231, AE=E)")} -> #NAME? | AE11: {=_xll.BQL($C11, "PE_RATIO(FPT=BA, FPR=2026, FYE=C1231, AE=E)")} -> #NAME? | AF11: {=_xll.BQL($C11, "PE_RATIO(FPT=BA, FPR=2027, FYE=C1231, AE=E)")} -> #NAME? | AG11: {=_xll.BQL($C11, "PX_TO_SALES_RATIO(FPT=BA, FPR=2025, FYE=C1231, AE=E)")} -> #NAME? | AH11: {=_xll.BQL($C11, "PX_TO_SALES_RATIO(FPT=BA, FPR=2026, FYE=C1231, AE=E)")} -> #NAME? | AI11: {=_xll.BQL($C11, "PX_TO_SALES_RATIO(FPT=BA, FPR=2027, FYE=C1231, AE=E)")} -> #NAME? | AJ11: =IF(AC11<0,"N/A",$X11/AC11) -> #NAME? | AK11: {=IF(_xll.BQL($C11, "CURR_ENTP_VAL(FPT=A,FPO=0)/EBITDA(FPT=BA, FPR=2026, FYE=C1231, AE=E)")<0,"N/A",_xll.BQL($C11, "CURR_ENTP_VAL(FPT=A,FPO=0)/EBITDA(FPT=BA, FPR=2026, FYE=C1231, AE=E)"))} -> #NAME? | AL11: {=IF(_xll.BQL($C11, "CURR_ENTP_VAL(FPT=A,FPO=0)/EBITDA(FPT=BA, FPR=2027, FYE=C1231, AE=E)")<0,"N/A",_xll.BQL($C11, "CURR_ENTP_VAL(FPT=A,FPO=0)/EBITDA(FPT=BA, FPR=2027, FYE=C1231, AE=E)"))} -> #NAME? | AM11: =_xll.BDP($C11,AM$1) -> #NAME? | AN11: {=_xll.BQL($C11, "PX_TO_BOOK_RATIO(FPT=BA, FPR=2026, FYE=C1231, AE=E)")} -> #NAME? | AO11: {=_xll.BQL($C11, "PX_TO_BOOK_RATIO(FPT=BA, FPR=2027, FYE=C1231, AE=E)")} -> #NAME? | AP11: =_xll.BDP($C11,"BEST Px bps ratio","BEST fperiod override","27Y") -> #NAME? | AQ11: =Z11 -> #NAME? | AR11: =_xll.BDP($C11,"BEST_ROE","BEST fperiod override","26Y")/100 -> #NAME? | AS11: =_xll.BDP($C11,"BEST_ROE","BEST fperiod override","27Y")/100 -> #NAME? | AT11: =_xll.BDP($C11,AT$1) -> #NAME? | AU11: =_xll.BDP($C11,$AU$1,"BEST fperiod override","26Y") -> #NAME? | AV11: =_xll.BDP($C11,$AU$1,"BEST fperiod override","27Y") -> #NAME? | AW11: =(BP11/BN11)^(1/2)-1 -> #NAME? | AX11: =(BV11/BT11)^(1/2)-1 -> #NAME? | AY11: =(CB11/BZ11)^(1/2)-1 -> #NAME? | AZ11: {=_xll.BQL($C11, "CF_CASH_FROM_OPER(FPT=BA, FPR=2022, FYE=C1231, AE=A)", "currency=USD")/1000000000} -> #NAME? | BA11: {=_xll.BQL($C11, "CF_CASH_FROM_OPER(FPT=BA, FPR=2023, FYE=C1231, AE=A)", "currency=USD")/1000000000} -> #NAME? | BB11: {=_xll.BQL($C11, "CF_CASH_FROM_OPER(FPT=BA, FPR=2024, FYE=C1231, AE=A)", "currency=USD")/1000000000} -> #NAME? | BC11: {=_xll.BQL($C11, "CF_CASH_FROM_OPER(FPT=BA, FPR=2025, FYE=C1231, AE=E)", "currency=USD")/1000000000} -> #NAME? | BD11: {=_xll.BQL($C11, "CF_CASH_FROM_OPER(FPT=BA, FPR=2026, FYE=C1231, AE=E)", "currency=USD")/1000000000} -> #NAME? | BE11: {=_xll.BQL($C11, "CF_CASH_FROM_OPER(FPT=BA, FPR=2027, FYE=C1231, AE=E)", "currency=USD")/1000000000} -> #NAME? | BF11: {=_xll.BQL($C11, "CF_FREE_CASH_FLOW(FPT=BA, FPR=2022, FYE=C1231, AE=A)", "currency=USD")/1000000000} -> #NAME? | BG11: {=_xll.BQL($C11, "CF_FREE_CASH_FLOW(FPT=BA, FPR=2023, FYE=C1231, AE=A)", "currency=USD")/1000000000} -> #NAME? | BH11: {=_xll.BQL($C11, "CF_FREE_CASH_FLOW(FPT=BA, FPR=2024, FYE=C1231, AE=A)", "currency=USD")/1000000000} -> #NAME? | BI11: {=_xll.BQL($C11, "CF_FREE_CASH_FLOW(FPT=BA, FPR=2025, FYE=C1231, AE=E)", "currency=USD")/1000000000} -> #NAME? | BJ11: {=_xll.BQL($C11, "CF_FREE_CASH_FLOW(FPT=BA, FPR=2026, FYE=C1231, AE=E)", "currency=USD")/1000000000} -> #NAME? | BK11: {=_xll.BQL($C11, "CF_FREE_CASH_FLOW(FPT=BA, FPR=2027, FYE=C1231, AE=E)", "currency=USD")/1000000000} -> #NAME? | BL11: {=_xll.BQL($C11, "SALES_REV_TURN(FPT=BA, FPR=2022, FYE=C1231, AE=A)", "currency=USD")/1000000000} -> #NAME? | BM11: {=_xll.BQL($C11, "SALES_REV_TURN(FPT=BA, FPR=2023, FYE=C1231, AE=A)", "currency=USD")/1000000000} -> #NAME? | BN11: {=_xll.BQL($C11, "SALES_REV_TURN(FPT=BA, FPR=2024, FYE=C1231, AE=A)", "currency=USD")/1000000000} -> #NAME? | BO11: {=_xll.BQL($C11, "SALES_REV_TURN(FPT=BA, FPR=2025, FYE=C1231, AE=E)", "currency=USD")/1000000000} -> #NAME? | BP11: {=_xll.BQL($C11, "SALES_REV_TURN(FPT=BA, FPR=2026, FYE=C1231, AE=E)", "currency=USD")/1000000000} -> #NAME? | BQ11: {=_xll.BQL($C11, "SALES_REV_TURN(FPT=BA, FPR=2027, FYE=C1231, AE=E)", "currency=USD")/1000000000} -> #NAME? | BR11: {=_xll.BQL($C11, "EBITDA(FPT=BA, FPR=2022, FYE=C1231, AE=A)", "currency=USD")/1000000000} -> #NAME? | BS11: {=_xll.BQL($C11, "EBITDA(FPT=BA, FPR=2023, FYE=C1231, AE=A)", "currency=USD")/1000000000} -> #NAME? | BT11: {=_xll.BQL($C11, "EBITDA(FPT=BA, FPR=2024, FYE=C1231, AE=A)", "currency=USD")/1000000000} -> #NAME? | BU11: {=_xll.BQL($C11, "EBITDA(FPT=BA, FPR=2025, FYE=C1231, AE=E)", "currency=USD")/1000000000} -> #NAME? | BV11: {=_xll.BQL($C11, "EBITDA(FPT=BA, FPR=2026, FYE=C1231, AE=E)", "currency=USD")/1000000000} -> #NAME? | BW11: {=_xll.BQL($C11, "EBITDA(FPT=BA, FPR=2027, FYE=C1231, AE=E)", "currency=USD")/1000000000} -> #NAME? | BX11: {=_xll.BQL($C11, "NET_INCOME(FPT=BA, FPR=2022, FYE=C1231, AE=A)", "currency=USD")/1000000000} -> #NAME? | BY11: {=_xll.BQL($C11, "NET_INCOME(FPT=BA, FPR=2023, FYE=C1231, AE=A)", "currency=USD")/1000000000} -> #NAME? | BZ11: {=_xll.BQL($C11, "NET_INCOME(FPT=BA, FPR=2024, FYE=C1231, AE=A)", "currency=USD")/1000000000} -> #NAME? | CA11: {=_xll.BQL($C11, "NET_INCOME(FPT=BA, FPR=2025, FYE=C1231, AE=E)", "currency=USD")/1000000000} -> #NAME? | CB11: {=_xll.BQL($C11, "NET_INCOME(FPT=BA, FPR=2026, FYE=C1231, AE=E)", "currency=USD")/1000000000} -> #NAME? | CC11: {=_xll.BQL($C11, "NET_INCOME(FPT=BA, FPR=2027, FYE=C1231, AE=E)", "currency=USD")/1000000000} -> #NAME? | CD11: {=-_xll.BQL($C11, "CF_DVD_PAID(FPT=BA, FPR=2024, FYE=C1231, AE=A)", "currency=USD")/1000000000} -> #NAME? | CE11: {=-_xll.BQL($C11, "CF_DVD_PAID(FPT=BA, FPR=2025, FYE=C1231, AE=E)", "currency=USD")/1000000000} -> #NAME? | CF11: {=-_xll.BQL($C11, "CF_DVD_PAID(FPT=BA, FPR=2026, FYE=C1231, AE=E)", "currency=USD")/1000000000} -> #NAME? | CG11: {=-_xll.BQL($C11, "CF_DVD_PAID(FPT=BA, FPR=2027, FYE=C1231, AE=E)", "currency=USD")/1000000000} -> #NAME? | CH11: =CD11/$F11 -> #NAME? | CI11: =CE11/$F11 -> #NAME? | CJ11: =CF11/$F11 -> #NAME? | CK11: =CG11/$F11 -> #NAME? | CL11: {=_xll.BDP($C11,"INTERVAL_AVG", "MARKET_DATA_OVERRIDE=turnover", "CALC_INTERVAL=5D","CRNCY=HKD")/1000000} -> #NAME? | CM11: {=_xll.BDP($C11,"INTERVAL_AVG", "MARKET_DATA_OVERRIDE=turnover", "CALC_INTERVAL=10D","CRNCY=HKD")/1000000} -> #NAME? | CN11: {=_xll.BDP($C11,"INTERVAL_AVG", "MARKET_DATA_OVERRIDE=turnover", "CALC_INTERVAL=20D","CRNCY=HKD")/1000000} -> #NAME? | CO11: {=_xll.BDP($C11,"INTERVAL_AVG", "MARKET_DATA_OVERRIDE=turnover", "CALC_INTERVAL=1m","CRNCY=HKD")/1000000} -> #NAME? | CP11: {=_xll.BDP($C11,"INTERVAL_AVG", "MARKET_DATA_OVERRIDE=turnover", "CALC_INTERVAL=3M","CRNCY=HKD")/1000000} -> #NAME? | CQ11: {=_xll.BDP($C11,"INTERVAL_AVG", "MARKET_DATA_OVERRIDE=turnover", "CALC_INTERVAL=6M","CRNCY=HKD")/1000000} -> #NAME? | CR11: =_xll.BDP($C11,"chg pct 1m")/100 -> #NAME? | CS11: =_xll.BDP($C11,"chg pct 3m")/100 -> #NAME? | CT11: =_xll.BDP($C11,"chg pct 6m")/100 -> #NAME? | CU11: =_xll.BDP($C11,"chg pct 1yr")/100 -> #NAME? | CV11: =_xll.BDP($C11,"chg pct ytd")/100 -> #NAME? | CW11: {=_xll.BQL($C11, "volatility(calc_interval=range(-1M, 0D))")} -> #NAME? | CX11: {=_xll.BQL($C11, "volatility(calc_interval=range(-3M, 0D))")} -> #NAME? | CY11: {=_xll.BQL($C11, "volatility(calc_interval=range(-6M, 0D))")} -> #NAME? | CZ11: =_xll.BDP($C11,CZ$1) -> #NAME?
A12: =_xll.BDP($C12,"security name") -> #NAME? | B12: =_xll.BDP($C12,"NAME_CHINESE_SIMPLIFIED") -> #NAME? | C12: MANH US EQUITY | D12: =_xll.BDP($C12,"LISTING_DATE") -> #NAME? | E12: =_xll.BDP($C12,E$1,"EQY_FUND_CRNCY="&$B$1) -> #NAME? | F12: =_xll.BDP($C12,F$1,"EQY_FUND_CRNCY="&$C$1) -> #NAME? | G12: =_xll.BDP($C12,G$1) -> #NAME? | H12: =_xll.BDP($C12,H$1,"EQY_FUND_CRNCY="&$B$1) -> #NAME? | I12: =_xll.BDP($C12,I$1,"EQY_FUND_CRNCY="&$C$1) -> #NAME? | J12: =_xll.BDP($C12,J$1,"EQY_FUND_CRNCY="&$B$1) -> #NAME? | K12: =_xll.BDP($C12,K$1,"EQY_FUND_CRNCY="&$C$1) -> #NAME? | L12: =_xll.BDP($C12,L$1,"EQY_FUND_CRNCY="&$B$1) -> #NAME? | M12: =_xll.BDP($C12,M$1,"EQY_FUND_CRNCY="&$C$1) -> #NAME? | N12: =_xll.BDP($C12,N$1)/100 -> #NAME? | O12: =_xll.BDP($C12,O$1)/100 -> #NAME? | P12: =_xll.BDP($C12,P$1)/100 -> #NAME? | Q12: =_xll.BDP($C12,Q$1)/100 -> #NAME? | R12: =_xll.BDP($C12,R$1)/100 -> #NAME? | S12: =_xll.BDP($C12,S$1)/100 -> #NAME? | T12: =_xll.BDP($C12,T$1)/100 -> #NAME? | U12: =_xll.BDP($C12,U$1)/100 -> #NAME? | ... W12: =_xll.BDP($C12,W$1)/100 -> #NAME? | X12: {=_xll.BDP($C12,"CRNCY_ADJ_CURR_EV", "EQY_FUND_CRNCY=HKD")} -> #NAME? | Y12: {=_xll.BDP($C12,"CRNCY_ADJ_CURR_EV", "EQY_FUND_CRNCY=USD")} -> #NAME? | Z12: =_xll.BDP($C12,Z$1)/100 -> #NAME? | AA12: =_xll.BDP($C12,"TRAIL_12M_NET_SALES","EQY_FUND_CRNCY=HKD") -> #NAME? | AB12: =_xll.BDP($C12,"TRAIL_12M_NET_INC","EQY_FUND_CRNCY=HKD") -> #NAME? | AC12: =_xll.BDP($C12,"TRAIL_12M_EBITDA","EQY_FUND_CRNCY=HKD") -> #NAME? | AD12: {=_xll.BQL($C12, "PE_RATIO(FPT=BA, FPR=2025, FYE=C1231, AE=E)")} -> #NAME? | AE12: {=_xll.BQL($C12, "PE_RATIO(FPT=BA, FPR=2026, FYE=C1231, AE=E)")} -> #NAME? | AF12: {=_xll.BQL($C12, "PE_RATIO(FPT=BA, FPR=2027, FYE=C1231, AE=E)")} -> #NAME? | AG12: {=_xll.BQL($C12, "PX_TO_SALES_RATIO(FPT=BA, FPR=2025, FYE=C1231, AE=E)")} -> #NAME? | AH12: {=_xll.BQL($C12, "PX_TO_SALES_RATIO(FPT=BA, FPR=2026, FYE=C1231, AE=E)")} -> #NAME? | AI12: {=_xll.BQL($C12, "PX_TO_SALES_RATIO(FPT=BA, FPR=2027, FYE=C1231, AE=E)")} -> #NAME? | AJ12: =IF(AC12<0,"N/A",$X12/AC12) -> #NAME? | AK12: {=IF(_xll.BQL($C12, "CURR_ENTP_VAL(FPT=A,FPO=0)/EBITDA(FPT=BA, FPR=2026, FYE=C1231, AE=E)")<0,"N/A",_xll.BQL($C12, "CURR_ENTP_VAL(FPT=A,FPO=0)/EBITDA(FPT=BA, FPR=2026, FYE=C1231, AE=E)"))} -> #NAME? | AL12: {=IF(_xll.BQL($C12, "CURR_ENTP_VAL(FPT=A,FPO=0)/EBITDA(FPT=BA, FPR=2027, FYE=C1231, AE=E)")<0,"N/A",_xll.BQL($C12, "CURR_ENTP_VAL(FPT=A,FPO=0)/EBITDA(FPT=BA, FPR=2027, FYE=C1231, AE=E)"))} -> #NAME? | AM12: =_xll.BDP($C12,AM$1) -> #NAME? | AN12: {=_xll.BQL($C12, "PX_TO_BOOK_RATIO(FPT=BA, FPR=2026, FYE=C1231, AE=E)")} -> #NAME? | AO12: {=_xll.BQL($C12, "PX_TO_BOOK_RATIO(FPT=BA, FPR=2027, FYE=C1231, AE=E)")} -> #NAME? | AP12: =_xll.BDP($C12,"BEST Px bps ratio","BEST fperiod override","27Y") -> #NAME? | AQ12: =Z12 -> #NAME? | AR12: =_xll.BDP($C12,"BEST_ROE","BEST fperiod override","26Y")/100 -> #NAME? | AS12: =_xll.BDP($C12,"BEST_ROE","BEST fperiod override","27Y")/100 -> #NAME? | AT12: =_xll.BDP($C12,AT$1) -> #NAME? | AU12: =_xll.BDP($C12,$AU$1,"BEST fperiod override","26Y") -> #NAME? | AV12: =_xll.BDP($C12,$AU$1,"BEST fperiod override","27Y") -> #NAME? | AW12: =(BP12/BN12)^(1/2)-1 -> #NAME? | AX12: =(BV12/BT12)^(1/2)-1 -> #NAME? | AY12: =(CB12/BZ12)^(1/2)-1 -> #NAME? | AZ12: {=_xll.BQL($C12, "CF_CASH_FROM_OPER(FPT=BA, FPR=2022, FYE=C1231, AE=A)", "currency=USD")/1000000000} -> #NAME? | BA12: {=_xll.BQL($C12, "CF_CASH_FROM_OPER(FPT=BA, FPR=2023, FYE=C1231, AE=A)", "currency=USD")/1000000000} -> #NAME? | BB12: {=_xll.BQL($C12, "CF_CASH_FROM_OPER(FPT=BA, FPR=2024, FYE=C1231, AE=A)", "currency=USD")/1000000000} -> #NAME? | BC12: {=_xll.BQL($C12, "CF_CASH_FROM_OPER(FPT=BA, FPR=2025, FYE=C1231, AE=E)", "currency=USD")/1000000000} -> #NAME? | BD12: {=_xll.BQL($C12, "CF_CASH_FROM_OPER(FPT=BA, FPR=2026, FYE=C1231, AE=E)", "currency=USD")/1000000000} -> #NAME? | BE12: {=_xll.BQL($C12, "CF_CASH_FROM_OPER(FPT=BA, FPR=2027, FYE=C1231, AE=E)", "currency=USD")/1000000000} -> #NAME? | BF12: {=_xll.BQL($C12, "CF_FREE_CASH_FLOW(FPT=BA, FPR=2022, FYE=C1231, AE=A)", "currency=USD")/1000000000} -> #NAME? | BG12: {=_xll.BQL($C12, "CF_FREE_CASH_FLOW(FPT=BA, FPR=2023, FYE=C1231, AE=A)", "currency=USD")/1000000000} -> #NAME? | BH12: {=_xll.BQL($C12, "CF_FREE_CASH_FLOW(FPT=BA, FPR=2024, FYE=C1231, AE=A)", "currency=USD")/1000000000} -> #NAME? | BI12: {=_xll.BQL($C12, "CF_FREE_CASH_FLOW(FPT=BA, FPR=2025, FYE=C1231, AE=E)", "currency=USD")/1000000000} -> #NAME? | BJ12: {=_xll.BQL($C12, "CF_FREE_CASH_FLOW(FPT=BA, FPR=2026, FYE=C1231, AE=E)", "currency=USD")/1000000000} -> #NAME? | BK12: {=_xll.BQL($C12, "CF_FREE_CASH_FLOW(FPT=BA, FPR=2027, FYE=C1231, AE=E)", "currency=USD")/1000000000} -> #NAME? | BL12: {=_xll.BQL($C12, "SALES_REV_TURN(FPT=BA, FPR=2022, FYE=C1231, AE=A)", "currency=USD")/1000000000} -> #NAME? | BM12: {=_xll.BQL($C12, "SALES_REV_TURN(FPT=BA, FPR=2023, FYE=C1231, AE=A)", "currency=USD")/1000000000} -> #NAME? | BN12: {=_xll.BQL($C12, "SALES_REV_TURN(FPT=BA, FPR=2024, FYE=C1231, AE=A)", "currency=USD")/1000000000} -> #NAME? | BO12: {=_xll.BQL($C12, "SALES_REV_TURN(FPT=BA, FPR=2025, FYE=C1231, AE=E)", "currency=USD")/1000000000} -> #NAME? | BP12: {=_xll.BQL($C12, "SALES_REV_TURN(FPT=BA, FPR=2026, FYE=C1231, AE=E)", "currency=USD")/1000000000} -> #NAME? | BQ12: {=_xll.BQL($C12, "SALES_REV_TURN(FPT=BA, FPR=2027, FYE=C1231, AE=E)", "currency=USD")/1000000000} -> #NAME? | BR12: {=_xll.BQL($C12, "EBITDA(FPT=BA, FPR=2022, FYE=C1231, AE=A)", "currency=USD")/1000000000} -> #NAME? | BS12: {=_xll.BQL($C12, "EBITDA(FPT=BA, FPR=2023, FYE=C1231, AE=A)", "currency=USD")/1000000000} -> #NAME? | BT12: {=_xll.BQL($C12, "EBITDA(FPT=BA, FPR=2024, FYE=C1231, AE=A)", "currency=USD")/1000000000} -> #NAME? | BU12: {=_xll.BQL($C12, "EBITDA(FPT=BA, FPR=2025, FYE=C1231, AE=E)", "currency=USD")/1000000000} -> #NAME? | BV12: {=_xll.BQL($C12, "EBITDA(FPT=BA, FPR=2026, FYE=C1231, AE=E)", "currency=USD")/1000000000} -> #NAME? | BW12: {=_xll.BQL($C12, "EBITDA(FPT=BA, FPR=2027, FYE=C1231, AE=E)", "currency=USD")/1000000000} -> #NAME? | BX12: {=_xll.BQL($C12, "NET_INCOME(FPT=BA, FPR=2022, FYE=C1231, AE=A)", "currency=USD")/1000000000} -> #NAME? | BY12: {=_xll.BQL($C12, "NET_INCOME(FPT=BA, FPR=2023, FYE=C1231, AE=A)", "currency=USD")/1000000000} -> #NAME? | BZ12: {=_xll.BQL($C12, "NET_INCOME(FPT=BA, FPR=2024, FYE=C1231, AE=A)", "currency=USD")/1000000000} -> #NAME? | CA12: {=_xll.BQL($C12, "NET_INCOME(FPT=BA, FPR=2025, FYE=C1231, AE=E)", "currency=USD")/1000000000} -> #NAME? | CB12: {=_xll.BQL($C12, "NET_INCOME(FPT=BA, FPR=2026, FYE=C1231, AE=E)", "currency=USD")/1000000000} -> #NAME? | CC12: {=_xll.BQL($C12, "NET_INCOME(FPT=BA, FPR=2027, FYE=C1231, AE=E)", "currency=USD")/1000000000} -> #NAME? | CD12: {=-_xll.BQL($C12, "CF_DVD_PAID(FPT=BA, FPR=2024, FYE=C1231, AE=A)", "currency=USD")/1000000000} -> #NAME? | CE12: {=-_xll.BQL($C12, "CF_DVD_PAID(FPT=BA, FPR=2025, FYE=C1231, AE=E)", "currency=USD")/1000000000} -> #NAME? | CF12: {=-_xll.BQL($C12, "CF_DVD_PAID(FPT=BA, FPR=2026, FYE=C1231, AE=E)", "currency=USD")/1000000000} -> #NAME? | CG12: {=-_xll.BQL($C12, "CF_DVD_PAID(FPT=BA, FPR=2027, FYE=C1231, AE=E)", "currency=USD")/1000000000} -> #NAME? | CH12: =CD12/$F12 -> #NAME? | CI12: =CE12/$F12 -> #NAME? | CJ12: =CF12/$F12 -> #NAME? | CK12: =CG12/$F12 -> #NAME? | CL12: {=_xll.BDP($C12,"INTERVAL_AVG", "MARKET_DATA_OVERRIDE=turnover", "CALC_INTERVAL=5D","CRNCY=HKD")/1000000} -> #NAME? | CM12: {=_xll.BDP($C12,"INTERVAL_AVG", "MARKET_DATA_OVERRIDE=turnover", "CALC_INTERVAL=10D","CRNCY=HKD")/1000000} -> #NAME? | CN12: {=_xll.BDP($C12,"INTERVAL_AVG", "MARKET_DATA_OVERRIDE=turnover", "CALC_INTERVAL=20D","CRNCY=HKD")/1000000} -> #NAME? | CO12: {=_xll.BDP($C12,"INTERVAL_AVG", "MARKET_DATA_OVERRIDE=turnover", "CALC_INTERVAL=1m","CRNCY=HKD")/1000000} -> #NAME? | CP12: {=_xll.BDP($C12,"INTERVAL_AVG", "MARKET_DATA_OVERRIDE=turnover", "CALC_INTERVAL=3M","CRNCY=HKD")/1000000} -> #NAME? | CQ12: {=_xll.BDP($C12,"INTERVAL_AVG", "MARKET_DATA_OVERRIDE=turnover", "CALC_INTERVAL=6M","CRNCY=HKD")/1000000} -> #NAME? | CR12: =_xll.BDP($C12,"chg pct 1m")/100 -> #NAME? | CS12: =_xll.BDP($C12,"chg pct 3m")/100 -> #NAME? | CT12: =_xll.BDP($C12,"chg pct 6m")/100 -> #NAME? | CU12: =_xll.BDP($C12,"chg pct 1yr")/100 -> #NAME? | CV12: =_xll.BDP($C12,"chg pct ytd")/100 -> #NAME? | CW12: {=_xll.BQL($C12, "volatility(calc_interval=range(-1M, 0D))")} -> #NAME? | CX12: {=_xll.BQL($C12, "volatility(calc_interval=range(-3M, 0D))")} -> #NAME? | CY12: {=_xll.BQL($C12, "volatility(calc_interval=range(-6M, 0D))")} -> #NAME? | CZ12: =_xll.BDP($C12,CZ$1) -> #NAME?
