Workbook

Sheet Sheet1
A1: Currency | B1: HKD | C1: USD | E1: CRNCY_ADJ_MKT_CAP | F1: Crncy Adj Mkt Cap | G1: Px Last | H1: Net Assets | I1: Net Assets | J1: Sales Rev Turn | K1: Sales Rev Turn | L1: Net Income | M1: Net Income | N1: Gross_Margin_Adjusted | O1: EBITDA_MARGIN_ADJUSTED | P1: Prof Margin | Q1: Sales_Growth | R1: Net Inc Growth | S1: TOT_DEBT_TO_TOT_EQY | T1: TOT_DEBT_TO_COM_EQY | U1: NET_DEBT_TO_SHRHLDR_EQTY | V1: TOT_DEBT_TO_TOT_ASSET | W1: RETURN_ON_ASSET | Z1: RETURN_COM_EQY | AD1: Pe Ratio | AJ1: BEST_EV_TO_BEST_EBITDA | AM1: Px To Book Ratio | AT1: EQY_DVD_YLD_IND | AU1: BEST_DIV_YLD | CZ1: CIE_DES
A3: Company Name | B3: 公司名 | C3: Stock Code | E3: Operating Data | AD3: Valuation | AW3: Forecast CAGR | AZ3: Key financials (USD'b) | CW3: Volatility
D4: Listing date | E4: Market Capitalization (HKD 'm) | F4: Market Capitalization (USD 'm) | G4: Price (Traded Currency) | H4: Net Assets (HKD 'm) | I4: Net Assets (USD 'm) | J4: Revenue (HKD 'm) | K4: Revenue (USD 'm) | L4: Net Profit (HKD 'm) | M4: Net Profit (USD 'm) | N4: GP Margin (%) | O4: EBITDA Margin (%) | P4: NP Margin (%) | Q4: Revenue Growth (%) | R4: NP Growth (%) | S4: Debt to equity | T4: Debt to common equity | U4: Net debt To Shareholders Equity | V4: Total Debt to Total Assets | W4: ROA | X4: EV (HKD'm) | Y4: EV (USD'm) | Z4: ROE | AA4: TTM Sales Profit (HKD 'm) | AB4: TTM Net Profit (HKD 'm) | AC4: TTM EBITDA (HKD 'm) | AD4: PE Ratio (x) | AG4: PS Ratio (x) | AJ4: EV/EBITDA (x) | AM4: PB Ratio (x) | AQ4: ROE (%) | AT4: Dividend Yield (x) | AW4: Revenue | AX4: EBITDA | AY4: Net profit | AZ4: cash flow from operations (USD'b) | BF4: Free cash flow (USD'b) | BL4: Revenue | BR4: EBITDA | BX4: Net profit | CD4: Dividend | CH4: Dividend yield | CL4: 5D Avg ADTV (HKD'm) | CM4: 10D Avg ADTV (HKD'm) | CN4: 20D Avg ADTV (HKD'm) | CO4: 1M Avg ADTV (HKD'm) | CP4: 3M Avg ADTV (HKD'm) | CQ4: 6M Avg ADTV (HKD'm) | CR4: 1M Return | CS4: 3M Return | CT4: 6M Return | CU4: 1Y Return | CV4: YTD Return | CW4: 30-day volatility (%) | CX4: 90-day volatility (%) | CY4: 180-day volatility (%)
AD5: TTM | AE5: 2026F | AF5: 2027F | AG5: TTM | AH5: 2026F | AI5: 2027F | AJ5: TTM | AK5: 2026F | AL5: 2027F | AM5: TTM | AN5: 2026F | AO5: 2027F | AP5: 2027F | AQ5: TTM | AR5: 2026F | AS5: 2027F | AT5: TTM | AU5: 2026F | AV5: 2027F | AW5: 2026 vs 2024 | AZ5: CY2022A | BA5: CY2023A | BB5: CY2024A | BC5: CY2025F | BD5: CY2026F | BE5: CY2027F | BF5: CY2022A | BG5: CY2023A | BH5: CY2024A | BI5: CY2025F | BJ5: CY2026F | BK5: CY2027F | BL5: CY2022A | BM5: CY2023A | BN5: CY2024A | BO5: CY2025F | BP5: CY2026F | BQ5: CY2027F | BR5: CY2022A | BS5: CY2023A | BT5: CY2024A | BU5: CY2025F | BV5: CY2026F | BW5: CY2027F | BX5: CY2022A | BY5: CY2023A | BZ5: CY2024A | CA5: CY2025F | CB5: CY2026F | CC5: CY2027F | CD5: CY2024A | CE5: CY2025F | CF5: CY2026F | CG5: CY2027F | CH5: CY2024A | CI5: CY2025F | CJ5: CY2026F | CK5: CY2027F
A7: =_xll.BDP($C7,"security name") -> PDS Ltd | B7: =_xll.BDP($C7,"NAME_CHINESE_SIMPLIFIED") -> PDS Ltd | C7: pdsl in Equity | D7: =_xll.BDP($C7,"LISTING_DATE") -> 10/21/2014 | E7: =_xll.BDP($C7,E$1,"EQY_FUND_CRNCY="&$B$1) -> 3363.6485 | F7: =_xll.BDP($C7,F$1,"EQY_FUND_CRNCY="&$C$1) -> 429.36539 | G7: =_xll.BDP($C7,G$1) -> 293.8 | H7: =_xll.BDP($C7,H$1,"EQY_FUND_CRNCY="&$B$1) -> 1544.2295 | I7: =_xll.BDP($C7,I$1,"EQY_FUND_CRNCY="&$C$1) -> 196.94544 | J7: =_xll.BDP($C7,J$1,"EQY_FUND_CRNCY="&$B$1) -> 11590.735 | K7: =_xll.BDP($C7,K$1,"EQY_FUND_CRNCY="&$C$1) -> 1484.796 | L7: =_xll.BDP($C7,L$1,"EQY_FUND_CRNCY="&$B$1) -> 98.747584 | M7: =_xll.BDP($C7,M$1,"EQY_FUND_CRNCY="&$C$1) -> 12.64976 | N7: =_xll.BDP($C7,N$1)/100 -> #VALUE! | O7: =_xll.BDP($C7,O$1)/100 -> 0.029377399 | P7: =_xll.BDP($C7,P$1)/100 -> 0.0085195274 | Q7: =_xll.BDP($C7,Q$1)/100 -> 0.083469248 | R7: =_xll.BDP($C7,R$1)/100 -> -0.28810317 | S7: =_xll.BDP($C7,S$1)/100 -> 0.6799445 | T7: =_xll.BDP($C7,T$1)/100 -> 0.7167187 | U7: =_xll.BDP($C7,U$1)/100 -> 0.12262357 | ... W7: =_xll.BDP($C7,W$1)/100 -> 0.022891973 | X7: {=_xll.BDP($C7,"CRNCY_ADJ_CURR_EV", "EQY_FUND_CRNCY=HKD")} -> 3632.2403 | Y7: {=_xll.BDP($C7,"CRNCY_ADJ_CURR_EV", "EQY_FUND_CRNCY=USD")} -> 463.62063 | Z7: =_xll.BDP($C7,Z$1)/100 -> 0.065611822 | AA7: =_xll.BDP($C7,"TRAIL_12M_NET_SALES","EQY_FUND_CRNCY=HKD") -> 11590.735 | AB7: =_xll.BDP($C7,"TRAIL_12M_NET_INC","EQY_FUND_CRNCY=HKD") -> 98.747584 | AC7: =_xll.BDP($C7,"TRAIL_12M_EBITDA","EQY_FUND_CRNCY=HKD") -> 340.37462 | AD7: =IF(AB7<0,"N/A",$E7/AB7) -> 34.063097 | AE7: {=_xll.BQL($C7, "PE_RATIO(FPT=BA, FPR=2026, FYE=C1231, AE=E)")} -> 34.159526 | AF7: {=_xll.BQL($C7, "PE_RATIO(FPT=BA, FPR=2027, FYE=C1231, AE=E)")} -> 27.694363 | AG7: =$E7/AA7 -> 0.29020149 | AH7: {=_xll.BQL($C7, "PX_TO_SALES_RATIO(FPT=BA, FPR=2026, FYE=C1231, AE=E)")} -> 0.29706215 | AI7: {=_xll.BQL($C7, "PX_TO_SALES_RATIO(FPT=BA, FPR=2027, FYE=C1231, AE=E)")} -> 0.27930084 | AJ7: =IF(AC7<0,"N/A",$X7/AC7) -> 10.671302 | AK7: {=IF(_xll.BQL($C7, "CURR_ENTP_VAL(FPT=A,FPO=0)/EBITDA(FPT=BA, FPR=2026, FYE=C1231, AE=E)")<0,"N/A",_xll.BQL($C7, "CURR_ENTP_VAL(FPT=A,FPO=0)/EBITDA(FPT=BA, FPR=2026, FYE=C1231, AE=E)"))} -> #N/A | AL7: {=IF(_xll.BQL($C7, "CURR_ENTP_VAL(FPT=A,FPO=0)/EBITDA(FPT=BA, FPR=2027, FYE=C1231, AE=E)")<0,"N/A",_xll.BQL($C7, "CURR_ENTP_VAL(FPT=A,FPO=0)/EBITDA(FPT=BA, FPR=2027, FYE=C1231, AE=E)"))} -> #N/A | AM7: =_xll.BDP($C7,AM$1) -> 2.3563056 | AN7: {=_xll.BQL($C7, "PX_TO_BOOK_RATIO(FPT=BA, FPR=2026, FYE=C1231, AE=E)")} -> 2.2737624 | AO7: {=_xll.BQL($C7, "PX_TO_BOOK_RATIO(FPT=BA, FPR=2027, FYE=C1231, AE=E)")} -> 2.1338398 | AP7: =_xll.BDP($C7,"BEST Px bps ratio","BEST fperiod override","27Y") -> 2.2325228 | AQ7: =Z7 -> 0.065611822 | AR7: =_xll.BDP($C7,"BEST_ROE","BEST fperiod override","26Y")/100 -> 0.0555 | AS7: =_xll.BDP($C7,"BEST_ROE","BEST fperiod override","27Y")/100 -> 0.0699 | AT7: =_xll.BDP($C7,AT$1) -> 1.1232131 | AU7: =_xll.BDP($C7,$AU$1,"BEST fperiod override","26Y") -> #N/A N/A | AV7: =_xll.BDP($C7,$AU$1,"BEST fperiod override","27Y") -> #N/A N/A | AW7: =(BP7/BN7)^(1/2)-1 -> -0.004529693 | AX7: =(BV7/BT7)^(1/2)-1 -> #VALUE! | AY7: =(CB7/BZ7)^(1/2)-1 -> -0.1925306 | AZ7: {=_xll.BQL($C7, "CF_CASH_FROM_OPER(FPT=BA, FPR=2022, FYE=C1231, AE=A)", "currency=USD")/1000000000} -> 0.054043298 | BA7: {=_xll.BQL($C7, "CF_CASH_FROM_OPER(FPT=BA, FPR=2023, FYE=C1231, AE=A)", "currency=USD")/1000000000} -> 0.021999611 | BB7: {=_xll.BQL($C7, "CF_CASH_FROM_OPER(FPT=BA, FPR=2024, FYE=C1231, AE=A)", "currency=USD")/1000000000} -> -0.0098155305 | BC7: {=_xll.BQL($C7, "CF_CASH_FROM_OPER(FPT=BA, FPR=2025, FYE=C1231, AE=E)", "currency=USD")/1000000000} -> #VALUE! | BD7: {=_xll.BQL($C7, "CF_CASH_FROM_OPER(FPT=BA, FPR=2026, FYE=C1231, AE=E)", "currency=USD")/1000000000} -> #VALUE! | BE7: {=_xll.BQL($C7, "CF_CASH_FROM_OPER(FPT=BA, FPR=2027, FYE=C1231, AE=E)", "currency=USD")/1000000000} -> #VALUE! | BF7: {=_xll.BQL($C7, "CF_FREE_CASH_FLOW(FPT=BA, FPR=2022, FYE=C1231, AE=A)", "currency=USD")/1000000000} -> 0.049792862 | BG7: {=_xll.BQL($C7, "CF_FREE_CASH_FLOW(FPT=BA, FPR=2023, FYE=C1231, AE=A)", "currency=USD")/1000000000} -> 0.0062953556 | BH7: {=_xll.BQL($C7, "CF_FREE_CASH_FLOW(FPT=BA, FPR=2024, FYE=C1231, AE=A)", "currency=USD")/1000000000} -> -0.022833284 | BI7: {=_xll.BQL($C7, "CF_FREE_CASH_FLOW(FPT=BA, FPR=2025, FYE=C1231, AE=E)", "currency=USD")/1000000000} -> #VALUE! | BJ7: {=_xll.BQL($C7, "CF_FREE_CASH_FLOW(FPT=BA, FPR=2026, FYE=C1231, AE=E)", "currency=USD")/1000000000} -> #VALUE! | BK7: {=_xll.BQL($C7, "CF_FREE_CASH_FLOW(FPT=BA, FPR=2027, FYE=C1231, AE=E)", "currency=USD")/1000000000} -> #VALUE! | BL7: {=_xll.BQL($C7, "SALES_REV_TURN(FPT=BA, FPR=2022, FYE=C1231, AE=A)", "currency=USD")/1000000000} -> 1.3512945 | BM7: {=_xll.BQL($C7, "SALES_REV_TURN(FPT=BA, FPR=2023, FYE=C1231, AE=A)", "currency=USD")/1000000000} -> 1.1990861 | BN7: {=_xll.BQL($C7, "SALES_REV_TURN(FPT=BA, FPR=2024, FYE=C1231, AE=A)", "currency=USD")/1000000000} -> 1.4662796 | BO7: {=_xll.BQL($C7, "SALES_REV_TURN(FPT=BA, FPR=2025, FYE=C1231, AE=E)", "currency=USD")/1000000000} -> 1.3931129 | BP7: {=_xll.BQL($C7, "SALES_REV_TURN(FPT=BA, FPR=2026, FYE=C1231, AE=E)", "currency=USD")/1000000000} -> 1.453026 | BQ7: {=_xll.BQL($C7, "SALES_REV_TURN(FPT=BA, FPR=2027, FYE=C1231, AE=E)", "currency=USD")/1000000000} -> 1.5454269 | BR7: {=_xll.BQL($C7, "EBITDA(FPT=BA, FPR=2022, FYE=C1231, AE=A)", "currency=USD")/1000000000} -> 0.054375123 | BS7: {=_xll.BQL($C7, "EBITDA(FPT=BA, FPR=2023, FYE=C1231, AE=A)", "currency=USD")/1000000000} -> 0.049776924 | BT7: {=_xll.BQL($C7, "EBITDA(FPT=BA, FPR=2024, FYE=C1231, AE=A)", "currency=USD")/1000000000} -> 0.052570466 | BU7: {=_xll.BQL($C7, "EBITDA(FPT=BA, FPR=2025, FYE=C1231, AE=E)", "currency=USD")/1000000000} -> #VALUE! | BV7: {=_xll.BQL($C7, "EBITDA(FPT=BA, FPR=2026, FYE=C1231, AE=E)", "currency=USD")/1000000000} -> #VALUE! | BW7: {=_xll.BQL($C7, "EBITDA(FPT=BA, FPR=2027, FYE=C1231, AE=E)", "currency=USD")/1000000000} -> #VALUE! | BX7: {=_xll.BQL($C7, "NET_INCOME(FPT=BA, FPR=2022, FYE=C1231, AE=A)", "currency=USD")/1000000000} -> 0.036362788 | BY7: {=_xll.BQL($C7, "NET_INCOME(FPT=BA, FPR=2023, FYE=C1231, AE=A)", "currency=USD")/1000000000} -> 0.018778827 | BZ7: {=_xll.BQL($C7, "NET_INCOME(FPT=BA, FPR=2024, FYE=C1231, AE=A)", "currency=USD")/1000000000} -> 0.019408024 | CA7: {=_xll.BQL($C7, "NET_INCOME(FPT=BA, FPR=2025, FYE=C1231, AE=E)", "currency=USD")/1000000000} -> 0.011725291 | CB7: {=_xll.BQL($C7, "NET_INCOME(FPT=BA, FPR=2026, FYE=C1231, AE=E)", "currency=USD")/1000000000} -> 0.012654164 | CC7: {=_xll.BQL($C7, "NET_INCOME(FPT=BA, FPR=2027, FYE=C1231, AE=E)", "currency=USD")/1000000000} -> 0.015608947 | CD7: {=-_xll.BQL($C7, "CF_DVD_PAID(FPT=BA, FPR=2024, FYE=C1231, AE=A)", "currency=USD")/1000000000} -> 0.0074249516 | CE7: {=-_xll.BQL($C7, "CF_DVD_PAID(FPT=BA, FPR=2025, FYE=C1231, AE=E)", "currency=USD")/1000000000} -> #VALUE! | CF7: {=-_xll.BQL($C7, "CF_DVD_PAID(FPT=BA, FPR=2026, FYE=C1231, AE=E)", "currency=USD")/1000000000} -> #VALUE! | CG7: {=-_xll.BQL($C7, "CF_DVD_PAID(FPT=BA, FPR=2027, FYE=C1231, AE=E)", "currency=USD")/1000000000} -> #VALUE! | CH7: =CD7/$F7 -> 1.7292851e-05 | CI7: =CE7/$F7 -> #VALUE! | CJ7: =CF7/$F7 -> #VALUE! | CK7: =CG7/$F7 -> #VALUE! | CL7: {=_xll.BDP($C7,"INTERVAL_AVG", "MARKET_DATA_OVERRIDE=turnover", "CALC_INTERVAL=5D","CRNCY=HKD")/1000000} -> 7.2448675 | CM7: {=_xll.BDP($C7,"INTERVAL_AVG", "MARKET_DATA_OVERRIDE=turnover", "CALC_INTERVAL=10D","CRNCY=HKD")/1000000} -> 4.2623237 | CN7: {=_xll.BDP($C7,"INTERVAL_AVG", "MARKET_DATA_OVERRIDE=turnover", "CALC_INTERVAL=20D","CRNCY=HKD")/1000000} -> 3.4449756 | CO7: {=_xll.BDP($C7,"INTERVAL_AVG", "MARKET_DATA_OVERRIDE=turnover", "CALC_INTERVAL=1m","CRNCY=HKD")/1000000} -> 3.3175718 | CP7: {=_xll.BDP($C7,"INTERVAL_AVG", "MARKET_DATA_OVERRIDE=turnover", "CALC_INTERVAL=3M","CRNCY=HKD")/1000000} -> 10.078578 | CQ7: {=_xll.BDP($C7,"INTERVAL_AVG", "MARKET_DATA_OVERRIDE=turnover", "CALC_INTERVAL=6M","CRNCY=HKD")/1000000} -> 7.5417473 | CR7: =_xll.BDP($C7,"chg pct 1m")/100 -> -0.000340231 | CS7: =_xll.BDP($C7,"chg pct 3m")/100 -> -0.03876982 | CT7: =_xll.BDP($C7,"chg pct 6m")/100 -> -0.2788414 | CU7: =_xll.BDP($C7,"chg pct 1yr")/100 -> -0.2847231 | CV7: =_xll.BDP($C7,"chg pct ytd")/100 -> -0.2132816 | CW7: {=_xll.BQL($C7, "volatility(calc_interval=range(-1M, 0D))")} -> 0.36384718 | CX7: {=_xll.BQL($C7, "volatility(calc_interval=range(-3M, 0D))")} -> 0.43541756 | CY7: {=_xll.BQL($C7, "volatility(calc_interval=range(-6M, 0D))")} -> 0.43323304 | CZ7: =_xll.BDP($C7,CZ$1) -> PDS Limited is a consumer-driven manufacturing and sourcing company. The Company designs, produces, and markets blazers, school wear, shirts, softs, and footwear products, as well as invests in sustainability, technology, and direct to consumer digital brands. PDS serves brand agencies and retailers worldwide.
A8: =_xll.BDP($C8,"security name") -> Walmart Inc | B8: =_xll.BDP($C8,"NAME_CHINESE_SIMPLIFIED") -> 沃尔玛股份有限公司 | C8: wmt us Equity | D8: =_xll.BDP($C8,"LISTING_DATE") -> #N/A Field Not Applicable | E8: =_xll.BDP($C8,E$1,"EQY_FUND_CRNCY="&$B$1) -> 8380084.2 | F8: =_xll.BDP($C8,F$1,"EQY_FUND_CRNCY="&$C$1) -> 1069706.9 | G8: =_xll.BDP($C8,G$1) -> 134.2 | H8: =_xll.BDP($C8,H$1,"EQY_FUND_CRNCY="&$B$1) -> 829276.42 | I8: =_xll.BDP($C8,I$1,"EQY_FUND_CRNCY="&$C$1) -> 106180 | J8: =_xll.BDP($C8,J$1,"EQY_FUND_CRNCY="&$B$1) -> 5560443 | K8: =_xll.BDP($C8,K$1,"EQY_FUND_CRNCY="&$C$1) -> 713163 | L8: =_xll.BDP($C8,L$1,"EQY_FUND_CRNCY="&$B$1) -> 170696.99 | M8: =_xll.BDP($C8,M$1,"EQY_FUND_CRNCY="&$C$1) -> 21893 | N8: =_xll.BDP($C8,N$1)/100 -> 0.249267 | O8: =_xll.BDP($C8,O$1)/100 -> 0.06575916 | P8: =_xll.BDP($C8,P$1)/100 -> 0.030698452 | Q8: =_xll.BDP($C8,Q$1)/100 -> 0.047252142 | R8: =_xll.BDP($C8,R$1)/100 -> 0.1264149 | S8: =_xll.BDP($C8,S$1)/100 -> 0.63189866 | T8: =_xll.BDP($C8,T$1)/100 -> 0.67352962 | U8: =_xll.BDP($C8,U$1)/100 -> 0.5308721 | ... W8: =_xll.BDP($C8,W$1)/100 -> 0.080268969 | X8: {=_xll.BDP($C8,"CRNCY_ADJ_CURR_EV", "EQY_FUND_CRNCY=HKD")} -> 8871581.5 | Y8: {=_xll.BDP($C8,"CRNCY_ADJ_CURR_EV", "EQY_FUND_CRNCY=USD")} -> 1132637.9 | Z8: =_xll.BDP($C8,Z$1)/100 -> 0.22969102 | AA8: =_xll.BDP($C8,"TRAIL_12M_NET_SALES","EQY_FUND_CRNCY=HKD") -> 5560443 | AB8: =_xll.BDP($C8,"TRAIL_12M_NET_INC","EQY_FUND_CRNCY=HKD") -> 170696.99 | AC8: =_xll.BDP($C8,"TRAIL_12M_EBITDA","EQY_FUND_CRNCY=HKD") -> 362258.42 | AD8: =IF(AB8<0,"N/A",$E8/AB8) -> 49.093332 | AE8: {=_xll.BQL($C8, "PE_RATIO(FPT=BA, FPR=2026, FYE=C1231, AE=E)")} -> 46.576104 | AF8: {=_xll.BQL($C8, "PE_RATIO(FPT=BA, FPR=2027, FYE=C1231, AE=E)")} -> 40.85241 | AG8: =$E8/AA8 -> 1.5070893 | AH8: {=_xll.BQL($C8, "PX_TO_SALES_RATIO(FPT=BA, FPR=2026, FYE=C1231, AE=E)")} -> 1.433405 | AI8: {=_xll.BQL($C8, "PX_TO_SALES_RATIO(FPT=BA, FPR=2027, FYE=C1231, AE=E)")} -> 1.3671795 | AJ8: =IF(AC8<0,"N/A",$X8/AC8) -> 24.489648 | AK8: {=IF(_xll.BQL($C8, "CURR_ENTP_VAL(FPT=A,FPO=0)/EBITDA(FPT=BA, FPR=2026, FYE=C1231, AE=E)")<0,"N/A",_xll.BQL($C8, "CURR_ENTP_VAL(FPT=A,FPO=0)/EBITDA(FPT=BA, FPR=2026, FYE=C1231, AE=E)"))} -> 21.698405 | AL8: {=IF(_xll.BQL($C8, "CURR_ENTP_VAL(FPT=A,FPO=0)/EBITDA(FPT=BA, FPR=2027, FYE=C1231, AE=E)")<0,"N/A",_xll.BQL($C8, "CURR_ENTP_VAL(FPT=A,FPO=0)/EBITDA(FPT=BA, FPR=2027, FYE=C1231, AE=E)"))} -> 19.712839 | AM8: =_xll.BDP($C8,AM$1) -> 10.735515 | AN8: {=_xll.BQL($C8, "PX_TO_BOOK_RATIO(FPT=BA, FPR=2026, FYE=C1231, AE=E)")} -> 9.7242299 | AO8: {=_xll.BQL($C8, "PX_TO_BOOK_RATIO(FPT=BA, FPR=2027, FYE=C1231, AE=E)")} -> 8.8181213 | AP8: =_xll.BDP($C8,"BEST Px bps ratio","BEST fperiod override","27Y") -> 9.7232285 | AQ8: =Z8 -> 0.22969102 | AR8: =_xll.BDP($C8,"BEST_ROE","BEST fperiod override","26Y")/100 -> 0.21592 | AS8: =_xll.BDP($C8,"BEST_ROE","BEST fperiod override","27Y")/100 -> 0.21427 | AT8: =_xll.BDP($C8,AT$1) -> 0.73770493 | AU8: =_xll.BDP($C8,$AU$1,"BEST fperiod override","26Y") -> 0.695231 | AV8: =_xll.BDP($C8,$AU$1,"BEST fperiod override","27Y") -> 0.73099851 | AW8: =(BP8/BN8)^(1/2)-1 -> 0.048698146 | AX8: =(BV8/BT8)^(1/2)-1 -> 0.077160566 | AY8: =(CB8/BZ8)^(1/2)-1 -> 0.079747432 | AZ8: {=_xll.BQL($C8, "CF_CASH_FROM_OPER(FPT=BA, FPR=2022, FYE=C1231, AE=A)", "currency=USD")/1000000000} -> 27.070967 | BA8: {=_xll.BQL($C8, "CF_CASH_FROM_OPER(FPT=BA, FPR=2023, FYE=C1231, AE=A)", "currency=USD")/1000000000} -> 34.523402 | BB8: {=_xll.BQL($C8, "CF_CASH_FROM_OPER(FPT=BA, FPR=2024, FYE=C1231, AE=A)", "currency=USD")/1000000000} -> 37.51688 | BC8: {=_xll.BQL($C8, "CF_CASH_FROM_OPER(FPT=BA, FPR=2025, FYE=C1231, AE=E)", "currency=USD")/1000000000} -> 39.156214 | BD8: {=_xll.BQL($C8, "CF_CASH_FROM_OPER(FPT=BA, FPR=2026, FYE=C1231, AE=E)", "currency=USD")/1000000000} -> 40.128463 | BE8: {=_xll.BQL($C8, "CF_CASH_FROM_OPER(FPT=BA, FPR=2027, FYE=C1231, AE=E)", "currency=USD")/1000000000} -> 43.735809 | BF8: {=_xll.BQL($C8, "CF_FREE_CASH_FLOW(FPT=BA, FPR=2022, FYE=C1231, AE=A)", "currency=USD")/1000000000} -> 10.307641 | BG8: {=_xll.BQL($C8, "CF_FREE_CASH_FLOW(FPT=BA, FPR=2023, FYE=C1231, AE=A)", "currency=USD")/1000000000} -> 14.300185 | BH8: {=_xll.BQL($C8, "CF_FREE_CASH_FLOW(FPT=BA, FPR=2024, FYE=C1231, AE=A)", "currency=USD")/1000000000} -> 14.123065 | BI8: {=_xll.BQL($C8, "CF_FREE_CASH_FLOW(FPT=BA, FPR=2025, FYE=C1231, AE=E)", "currency=USD")/1000000000} -> 16.499711 | BJ8: {=_xll.BQL($C8, "CF_FREE_CASH_FLOW(FPT=BA, FPR=2026, FYE=C1231, AE=E)", "currency=USD")/1000000000} -> 14.119226 | BK8: {=_xll.BQL($C8, "CF_FREE_CASH_FLOW(FPT=BA, FPR=2027, FYE=C1231, AE=E)", "currency=USD")/1000000000} -> 18.194063 | BL8: {=_xll.BQL($C8, "SALES_REV_TURN(FPT=BA, FPR=2022, FYE=C1231, AE=A)", "currency=USD")/1000000000} -> 607.52284 | BM8: {=_xll.BQL($C8, "SALES_REV_TURN(FPT=BA, FPR=2023, FYE=C1231, AE=A)", "currency=USD")/1000000000} -> 644.97783 | BN8: {=_xll.BQL($C8, "SALES_REV_TURN(FPT=BA, FPR=2024, FYE=C1231, AE=A)", "currency=USD")/1000000000} -> 678.57037 | BO8: {=_xll.BQL($C8, "SALES_REV_TURN(FPT=BA, FPR=2025, FYE=C1231, AE=E)", "currency=USD")/1000000000} -> 706.70368 | BP8: {=_xll.BQL($C8, "SALES_REV_TURN(FPT=BA, FPR=2026, FYE=C1231, AE=E)", "currency=USD")/1000000000} -> 746.26984 | BQ8: {=_xll.BQL($C8, "SALES_REV_TURN(FPT=BA, FPR=2027, FYE=C1231, AE=E)", "currency=USD")/1000000000} -> 782.41879 | BR8: {=_xll.BQL($C8, "EBITDA(FPT=BA, FPR=2022, FYE=C1231, AE=A)", "currency=USD")/1000000000} -> 31.447467 | BS8: {=_xll.BQL($C8, "EBITDA(FPT=BA, FPR=2023, FYE=C1231, AE=A)", "currency=USD")/1000000000} -> 38.191424 | BT8: {=_xll.BQL($C8, "EBITDA(FPT=BA, FPR=2024, FYE=C1231, AE=A)", "currency=USD")/1000000000} -> 42.030543 | BU8: {=_xll.BQL($C8, "EBITDA(FPT=BA, FPR=2025, FYE=C1231, AE=E)", "currency=USD")/1000000000} -> 44.809955 | BV8: {=_xll.BQL($C8, "EBITDA(FPT=BA, FPR=2026, FYE=C1231, AE=E)", "currency=USD")/1000000000} -> 48.766984 | BW8: {=_xll.BQL($C8, "EBITDA(FPT=BA, FPR=2027, FYE=C1231, AE=E)", "currency=USD")/1000000000} -> 53.679012 | BX8: {=_xll.BQL($C8, "NET_INCOME(FPT=BA, FPR=2022, FYE=C1231, AE=A)", "currency=USD")/1000000000} -> 10.765837 | BY8: {=_xll.BQL($C8, "NET_INCOME(FPT=BA, FPR=2023, FYE=C1231, AE=A)", "currency=USD")/1000000000} -> 15.774163 | BZ8: {=_xll.BQL($C8, "NET_INCOME(FPT=BA, FPR=2024, FYE=C1231, AE=A)", "currency=USD")/1000000000} -> 19.51687 | CA8: {=_xll.BQL($C8, "NET_INCOME(FPT=BA, FPR=2025, FYE=C1231, AE=E)", "currency=USD")/1000000000} -> 20.761634 | CB8: {=_xll.BQL($C8, "NET_INCOME(FPT=BA, FPR=2026, FYE=C1231, AE=E)", "currency=USD")/1000000000} -> 22.753831 | CC8: {=_xll.BQL($C8, "NET_INCOME(FPT=BA, FPR=2027, FYE=C1231, AE=E)", "currency=USD")/1000000000} -> 25.800935 | CD8: {=-_xll.BQL($C8, "CF_DVD_PAID(FPT=BA, FPR=2024, FYE=C1231, AE=A)", "currency=USD")/1000000000} -> 6.6374565 | CE8: {=-_xll.BQL($C8, "CF_DVD_PAID(FPT=BA, FPR=2025, FYE=C1231, AE=E)", "currency=USD")/1000000000} -> 7.398584 | CF8: {=-_xll.BQL($C8, "CF_DVD_PAID(FPT=BA, FPR=2026, FYE=C1231, AE=E)", "currency=USD")/1000000000} -> 7.6709596 | CG8: {=-_xll.BQL($C8, "CF_DVD_PAID(FPT=BA, FPR=2027, FYE=C1231, AE=E)", "currency=USD")/1000000000} -> 8.139111 | CH8: =CD8/$F8 -> 6.2049299e-06 | CI8: =CE8/$F8 -> 6.9164589e-06 | CJ8: =CF8/$F8 -> 7.1710853e-06 | CK8: =CG8/$F8 -> 7.6087299e-06 | CL8: {=_xll.BDP($C8,"INTERVAL_AVG", "MARKET_DATA_OVERRIDE=turnover", "CALC_INTERVAL=5D","CRNCY=HKD")/1000000} -> 19123.993 | CM8: {=_xll.BDP($C8,"INTERVAL_AVG", "MARKET_DATA_OVERRIDE=turnover", "CALC_INTERVAL=10D","CRNCY=HKD")/1000000} -> 17589.413 | CN8: {=_xll.BDP($C8,"INTERVAL_AVG", "MARKET_DATA_OVERRIDE=turnover", "CALC_INTERVAL=20D","CRNCY=HKD")/1000000} -> 16368.912 | CO8: {=_xll.BDP($C8,"INTERVAL_AVG", "MARKET_DATA_OVERRIDE=turnover", "CALC_INTERVAL=1m","CRNCY=HKD")/1000000} -> 16610.733 | CP8: {=_xll.BDP($C8,"INTERVAL_AVG", "MARKET_DATA_OVERRIDE=turnover", "CALC_INTERVAL=3M","CRNCY=HKD")/1000000} -> 18447.682 | CQ8: {=_xll.BDP($C8,"INTERVAL_AVG", "MARKET_DATA_OVERRIDE=turnover", "CALC_INTERVAL=6M","CRNCY=HKD")/1000000} -> 23745.789 | CR8: =_xll.BDP($C8,"chg pct 1m")/100 -> 0.0490932 | CS8: =_xll.BDP($C8,"chg pct 3m")/100 -> 0.09114564 | CT8: =_xll.BDP($C8,"chg pct 6m")/100 -> 0.2529176 | CU8: =_xll.BDP($C8,"chg pct 1yr")/100 -> 0.3721881 | CV8: =_xll.BDP($C8,"chg pct ytd")/100 -> 0.2045597 | CW8: {=_xll.BQL($C8, "volatility(calc_interval=range(-1M, 0D))")} -> 0.2058647 | CX8: {=_xll.BQL($C8, "volatility(calc_interval=range(-3M, 0D))")} -> 0.22858561 | CY8: {=_xll.BQL($C8, "volatility(calc_interval=range(-6M, 0D))")} -> 0.2382971 | CZ8: =_xll.BDP($C8,CZ$1) -> Walmart Inc. operates discount stores, supercenters, and neighborhood markets. The Company offers merchandise such as apparel, house wares, small appliances, electronics, musical instruments, books, home improvement, shoes, jewelry, toddler, games, household essentials, pets, pharmaceutical products, party supplies, and automotive tools. Walmart serves customers worldwide.
A9: =_xll.BDP($C9,"security name") -> American Eagle Outfitters Inc | B9: =_xll.BDP($C9,"NAME_CHINESE_SIMPLIFIED") -> 美鹰傲飞AEO有限公司 | C9: aeo us Equity | D9: =_xll.BDP($C9,"LISTING_DATE") -> #N/A Field Not Applicable | E9: =_xll.BDP($C9,E$1,"EQY_FUND_CRNCY="&$B$1) -> 20157.569 | F9: =_xll.BDP($C9,F$1,"EQY_FUND_CRNCY="&$C$1) -> 2573.0877 | G9: =_xll.BDP($C9,G$1) -> 15.36 | H9: =_xll.BDP($C9,H$1,"EQY_FUND_CRNCY="&$B$1) -> 13210.269 | I9: =_xll.BDP($C9,I$1,"EQY_FUND_CRNCY="&$C$1) -> 1691.434 | J9: =_xll.BDP($C9,J$1,"EQY_FUND_CRNCY="&$B$1) -> 43251.108 | K9: =_xll.BDP($C9,K$1,"EQY_FUND_CRNCY="&$C$1) -> 5547.236 | L9: =_xll.BDP($C9,L$1,"EQY_FUND_CRNCY="&$B$1) -> 1496.8675 | M9: =_xll.BDP($C9,M$1,"EQY_FUND_CRNCY="&$C$1) -> 191.983 | N9: =_xll.BDP($C9,N$1)/100 -> 0.36510453 | O9: =_xll.BDP($C9,O$1)/100 -> 0.17345972 | P9: =_xll.BDP($C9,P$1)/100 -> 0.034608767 | Q9: =_xll.BDP($C9,Q$1)/100 -> 0.041020506 | R9: =_xll.BDP($C9,R$1)/100 -> -0.41713826 | S9: =_xll.BDP($C9,S$1)/100 -> 1.0052553 | T9: =_xll.BDP($C9,T$1)/100 -> 1.0042347 | U9: =_xll.BDP($C9,U$1)/100 -> 0.86400061 | ... W9: =_xll.BDP($C9,W$1)/100 -> 0.048972413 | X9: {=_xll.BDP($C9,"CRNCY_ADJ_CURR_EV", "EQY_FUND_CRNCY=HKD")} -> 31557.824 | Y9: {=_xll.BDP($C9,"CRNCY_ADJ_CURR_EV", "EQY_FUND_CRNCY=USD")} -> 4032.7687 | Z9: =_xll.BDP($C9,Z$1)/100 -> 0.11097242 | AA9: =_xll.BDP($C9,"TRAIL_12M_NET_SALES","EQY_FUND_CRNCY=HKD") -> 43251.108 | AB9: =_xll.BDP($C9,"TRAIL_12M_NET_INC","EQY_FUND_CRNCY=HKD") -> 1496.8675 | AC9: =_xll.BDP($C9,"TRAIL_12M_EBITDA","EQY_FUND_CRNCY=HKD") -> 6710.1391 | AD9: =IF(AB9<0,"N/A",$E9/AB9) -> 13.466502 | AE9: {=_xll.BQL($C9, "PE_RATIO(FPT=BA, FPR=2026, FYE=C1231, AE=E)")} -> 8.8269914 | AF9: {=_xll.BQL($C9, "PE_RATIO(FPT=BA, FPR=2027, FYE=C1231, AE=E)")} -> 7.7833708 | AG9: =$E9/AA9 -> 0.46605903 | AH9: {=_xll.BQL($C9, "PX_TO_SALES_RATIO(FPT=BA, FPR=2026, FYE=C1231, AE=E)")} -> 0.44585488 | AI9: {=_xll.BQL($C9, "PX_TO_SALES_RATIO(FPT=BA, FPR=2027, FYE=C1231, AE=E)")} -> 0.43027257 | AJ9: =IF(AC9<0,"N/A",$X9/AC9) -> 4.7030059 | AK9: {=IF(_xll.BQL($C9, "CURR_ENTP_VAL(FPT=A,FPO=0)/EBITDA(FPT=BA, FPR=2026, FYE=C1231, AE=E)")<0,"N/A",_xll.BQL($C9, "CURR_ENTP_VAL(FPT=A,FPO=0)/EBITDA(FPT=BA, FPR=2026, FYE=C1231, AE=E)"))} -> 8.3320805 | AL9: {=IF(_xll.BQL($C9, "CURR_ENTP_VAL(FPT=A,FPO=0)/EBITDA(FPT=BA, FPR=2027, FYE=C1231, AE=E)")<0,"N/A",_xll.BQL($C9, "CURR_ENTP_VAL(FPT=A,FPO=0)/EBITDA(FPT=BA, FPR=2027, FYE=C1231, AE=E)"))} -> 7.6098393 | AM9: =_xll.BDP($C9,AM$1) -> 1.5327586 | AN9: {=_xll.BQL($C9, "PX_TO_BOOK_RATIO(FPT=BA, FPR=2026, FYE=C1231, AE=E)")} -> 1.2597358 | AO9: {=_xll.BQL($C9, "PX_TO_BOOK_RATIO(FPT=BA, FPR=2027, FYE=C1231, AE=E)")} -> 1.1445369 | AP9: =_xll.BDP($C9,"BEST Px bps ratio","BEST fperiod override","27Y") -> 1.2687923 | AQ9: =Z9 -> 0.11097242 | AR9: =_xll.BDP($C9,"BEST_ROE","BEST fperiod override","26Y")/100 -> 0.13893 | AS9: =_xll.BDP($C9,"BEST_ROE","BEST fperiod override","27Y")/100 -> 0.17072 | AT9: =_xll.BDP($C9,AT$1) -> 3.2552083 | AU9: =_xll.BDP($C9,$AU$1,"BEST fperiod override","26Y") -> 3.2747396 | AV9: =_xll.BDP($C9,$AU$1,"BEST fperiod override","27Y") -> 3.2356771 | AW9: =(BP9/BN9)^(1/2)-1 -> 0.038917207 | AX9: =(BV9/BT9)^(1/2)-1 -> 0.02443777 | AY9: =(CB9/BZ9)^(1/2)-1 -> 0.015840872 | AZ9: {=_xll.BQL($C9, "CF_CASH_FROM_OPER(FPT=BA, FPR=2022, FYE=C1231, AE=A)", "currency=USD")/1000000000} -> 0.30877057 | BA9: {=_xll.BQL($C9, "CF_CASH_FROM_OPER(FPT=BA, FPR=2023, FYE=C1231, AE=A)", "currency=USD")/1000000000} -> 0.62958049 | BB9: {=_xll.BQL($C9, "CF_CASH_FROM_OPER(FPT=BA, FPR=2024, FYE=C1231, AE=A)", "currency=USD")/1000000000} -> 0.44467309 | BC9: {=_xll.BQL($C9, "CF_CASH_FROM_OPER(FPT=BA, FPR=2025, FYE=C1231, AE=E)", "currency=USD")/1000000000} -> 0.88413334 | BD9: {=_xll.BQL($C9, "CF_CASH_FROM_OPER(FPT=BA, FPR=2026, FYE=C1231, AE=E)", "currency=USD")/1000000000} -> 0.60041393 | BE9: {=_xll.BQL($C9, "CF_CASH_FROM_OPER(FPT=BA, FPR=2027, FYE=C1231, AE=E)", "currency=USD")/1000000000} -> 0.60689928 | BF9: {=_xll.BQL($C9, "CF_FREE_CASH_FLOW(FPT=BA, FPR=2022, FYE=C1231, AE=A)", "currency=USD")/1000000000} -> 0.038662615 | BG9: {=_xll.BQL($C9, "CF_FREE_CASH_FLOW(FPT=BA, FPR=2023, FYE=C1231, AE=A)", "currency=USD")/1000000000} -> 0.45008166 | BH9: {=_xll.BQL($C9, "CF_FREE_CASH_FLOW(FPT=BA, FPR=2024, FYE=C1231, AE=A)", "currency=USD")/1000000000} -> 0.23123481 | BI9: {=_xll.BQL($C9, "CF_FREE_CASH_FLOW(FPT=BA, FPR=2025, FYE=C1231, AE=E)", "currency=USD")/1000000000} -> 0.49798702 | BJ9: {=_xll.BQL($C9, "CF_FREE_CASH_FLOW(FPT=BA, FPR=2026, FYE=C1231, AE=E)", "currency=USD")/1000000000} -> 0.35781943 | BK9: {=_xll.BQL($C9, "CF_FREE_CASH_FLOW(FPT=BA, FPR=2027, FYE=C1231, AE=E)", "currency=USD")/1000000000} -> 0.32122047 | BL9: {=_xll.BQL($C9, "SALES_REV_TURN(FPT=BA, FPR=2022, FYE=C1231, AE=A)", "currency=USD")/1000000000} -> 5.0100486 | BM9: {=_xll.BQL($C9, "SALES_REV_TURN(FPT=BA, FPR=2023, FYE=C1231, AE=A)", "currency=USD")/1000000000} -> 5.1396258 | BN9: {=_xll.BQL($C9, "SALES_REV_TURN(FPT=BA, FPR=2024, FYE=C1231, AE=A)", "currency=USD")/1000000000} -> 5.3468644 | BO9: {=_xll.BQL($C9, "SALES_REV_TURN(FPT=BA, FPR=2025, FYE=C1231, AE=E)", "currency=USD")/1000000000} -> 5.3619101 | BP9: {=_xll.BQL($C9, "SALES_REV_TURN(FPT=BA, FPR=2026, FYE=C1231, AE=E)", "currency=USD")/1000000000} -> 5.7711326 | BQ9: {=_xll.BQL($C9, "SALES_REV_TURN(FPT=BA, FPR=2027, FYE=C1231, AE=E)", "currency=USD")/1000000000} -> 5.980134 | BR9: {=_xll.BQL($C9, "EBITDA(FPT=BA, FPR=2022, FYE=C1231, AE=A)", "currency=USD")/1000000000} -> 0.4586707 | BS9: {=_xll.BQL($C9, "EBITDA(FPT=BA, FPR=2023, FYE=C1231, AE=A)", "currency=USD")/1000000000} -> 0.47541237 | BT9: {=_xll.BQL($C9, "EBITDA(FPT=BA, FPR=2024, FYE=C1231, AE=A)", "currency=USD")/1000000000} -> 0.6021329 | BU9: {=_xll.BQL($C9, "EBITDA(FPT=BA, FPR=2025, FYE=C1231, AE=E)", "currency=USD")/1000000000} -> 0.458687 | BV9: {=_xll.BQL($C9, "EBITDA(FPT=BA, FPR=2026, FYE=C1231, AE=E)", "currency=USD")/1000000000} -> 0.63192207 | BW9: {=_xll.BQL($C9, "EBITDA(FPT=BA, FPR=2027, FYE=C1231, AE=E)", "currency=USD")/1000000000} -> 0.69189707 | BX9: {=_xll.BQL($C9, "NET_INCOME(FPT=BA, FPR=2022, FYE=C1231, AE=A)", "currency=USD")/1000000000} -> 0.12441023 | BY9: {=_xll.BQL($C9, "NET_INCOME(FPT=BA, FPR=2023, FYE=C1231, AE=A)", "currency=USD")/1000000000} -> 0.18464497 | BZ9: {=_xll.BQL($C9, "NET_INCOME(FPT=BA, FPR=2024, FYE=C1231, AE=A)", "currency=USD")/1000000000} -> 0.29487917 | CA9: {=_xll.BQL($C9, "NET_INCOME(FPT=BA, FPR=2025, FYE=C1231, AE=E)", "currency=USD")/1000000000} -> 0.20500813 | CB9: {=_xll.BQL($C9, "NET_INCOME(FPT=BA, FPR=2026, FYE=C1231, AE=E)", "currency=USD")/1000000000} -> 0.30429545 | CC9: {=_xll.BQL($C9, "NET_INCOME(FPT=BA, FPR=2027, FYE=C1231, AE=E)", "currency=USD")/1000000000} -> 0.35161115 | CD9: {=-_xll.BQL($C9, "CF_DVD_PAID(FPT=BA, FPR=2024, FYE=C1231, AE=A)", "currency=USD")/1000000000} -> 0.09664705 | CE9: {=-_xll.BQL($C9, "CF_DVD_PAID(FPT=BA, FPR=2025, FYE=C1231, AE=E)", "currency=USD")/1000000000} -> 0.090614801 | CF9: {=-_xll.BQL($C9, "CF_DVD_PAID(FPT=BA, FPR=2026, FYE=C1231, AE=E)", "currency=USD")/1000000000} -> 0.088729529 | CG9: {=-_xll.BQL($C9, "CF_DVD_PAID(FPT=BA, FPR=2027, FYE=C1231, AE=E)", "currency=USD")/1000000000} -> 0.093559922 | CH9: =CD9/$F9 -> 3.7560729e-05 | CI9: =CE9/$F9 -> 3.5216367e-05 | CJ9: =CF9/$F9 -> 3.4483679e-05 | CK9: =CG9/$F9 -> 3.6360953e-05 | CL9: {=_xll.BDP($C9,"INTERVAL_AVG", "MARKET_DATA_OVERRIDE=turnover", "CALC_INTERVAL=5D","CRNCY=HKD")/1000000} -> 554.67983 | CM9: {=_xll.BDP($C9,"INTERVAL_AVG", "MARKET_DATA_OVERRIDE=turnover", "CALC_INTERVAL=10D","CRNCY=HKD")/1000000} -> 543.59402 | CN9: {=_xll.BDP($C9,"INTERVAL_AVG", "MARKET_DATA_OVERRIDE=turnover", "CALC_INTERVAL=20D","CRNCY=HKD")/1000000} -> 540.68725 | CO9: {=_xll.BDP($C9,"INTERVAL_AVG", "MARKET_DATA_OVERRIDE=turnover", "CALC_INTERVAL=1m","CRNCY=HKD")/1000000} -> 563.99768 | CP9: {=_xll.BDP($C9,"INTERVAL_AVG", "MARKET_DATA_OVERRIDE=turnover", "CALC_INTERVAL=3M","CRNCY=HKD")/1000000} -> 780.81676 | CQ9: {=_xll.BDP($C9,"INTERVAL_AVG", "MARKET_DATA_OVERRIDE=turnover", "CALC_INTERVAL=6M","CRNCY=HKD")/1000000} -> 1081.9367 | CR9: =_xll.BDP($C9,"chg pct 1m")/100 -> -0.2273642 | CS9: =_xll.BDP($C9,"chg pct 3m")/100 -> -0.391924 | CT9: =_xll.BDP($C9,"chg pct 6m")/100 -> -0.1242874 | CU9: =_xll.BDP($C9,"chg pct 1yr")/100 -> 0.3391456 | CV9: =_xll.BDP($C9,"chg pct ytd")/100 -> -0.4175199 | CW9: {=_xll.BQL($C9, "volatility(calc_interval=range(-1M, 0D))")} -> 0.37298253 | CX9: {=_xll.BQL($C9, "volatility(calc_interval=range(-3M, 0D))")} -> 0.53793434 | CY9: {=_xll.BQL($C9, "volatility(calc_interval=range(-6M, 0D))")} -> 0.5440254 | CZ9: =_xll.BDP($C9,CZ$1) -> American Eagle Outfitters, Inc. retails men's and women's casual apparel, footwear, outerwear, and accessories. The Company provides products include jeans, khakis, t-shirts, and other similar apparel. American Eagle serves customers in the United States.
A10: =_xll.BDP($C10,"security name") -> Costco Wholesale Corp | B10: =_xll.BDP($C10,"NAME_CHINESE_SIMPLIFIED") -> 开市客公司 | C10: cost us Equity | D10: =_xll.BDP($C10,"LISTING_DATE") -> 12/5/1985 | E10: =_xll.BDP($C10,E$1,"EQY_FUND_CRNCY="&$B$1) -> 3803390.2 | F10: =_xll.BDP($C10,F$1,"EQY_FUND_CRNCY="&$C$1) -> 485497.85 | G10: =_xll.BDP($C10,G$1) -> 1094.32 | H10: =_xll.BDP($C10,H$1,"EQY_FUND_CRNCY="&$B$1) -> 227315.88 | I10: =_xll.BDP($C10,I$1,"EQY_FUND_CRNCY="&$C$1) -> 29164 | J10: =_xll.BDP($C10,J$1,"EQY_FUND_CRNCY="&$B$1) -> 2145593.8 | K10: =_xll.BDP($C10,K$1,"EQY_FUND_CRNCY="&$C$1) -> 275235 | L10: =_xll.BDP($C10,L$1,"EQY_FUND_CRNCY="&$B$1) -> 63135.736 | M10: =_xll.BDP($C10,M$1,"EQY_FUND_CRNCY="&$C$1) -> 8099 | N10: =_xll.BDP($C10,N$1)/100 -> 0.12843207 | O10: =_xll.BDP($C10,O$1)/100 -> 0.047097934 | P10: =_xll.BDP($C10,P$1)/100 -> 0.029425763 | Q10: =_xll.BDP($C10,Q$1)/100 -> 0.081673236 | R10: =_xll.BDP($C10,R$1)/100 -> 0.09936202 | S10: =_xll.BDP($C10,S$1)/100 -> 0.29262104 | T10: =_xll.BDP($C10,T$1)/100 -> 0.29262104 | U10: =_xll.BDP($C10,U$1)/100 -> -0.23144973 | ... W10: =_xll.BDP($C10,W$1)/100 -> 0.10899957 | X10: {=_xll.BDP($C10,"CRNCY_ADJ_CURR_EV", "EQY_FUND_CRNCY=HKD")} -> 3724627.8 | Y10: {=_xll.BDP($C10,"CRNCY_ADJ_CURR_EV", "EQY_FUND_CRNCY=USD")} -> 475422.85 | Z10: =_xll.BDP($C10,Z$1)/100 -> 0.29651082 | AA10: =_xll.BDP($C10,"TRAIL_12M_NET_SALES","EQY_FUND_CRNCY=HKD") -> 2232256.2 | AB10: =_xll.BDP($C10,"TRAIL_12M_NET_INC","EQY_FUND_CRNCY=HKD") -> 66663.958 | AC10: =_xll.BDP($C10,"TRAIL_12M_EBITDA","EQY_FUND_CRNCY=HKD") -> 104959.28 | AD10: =IF(AB10<0,"N/A",$E10/AB10) -> 57.053171 | AE10: {=_xll.BQL($C10, "PE_RATIO(FPT=BA, FPR=2026, FYE=C1231, AE=E)")} -> 51.687613 | AF10: {=_xll.BQL($C10, "PE_RATIO(FPT=BA, FPR=2027, FYE=C1231, AE=E)")} -> 46.888178 | AG10: =$E10/AA10 -> 1.7038323 | AH10: {=_xll.BQL($C10, "PX_TO_SALES_RATIO(FPT=BA, FPR=2026, FYE=C1231, AE=E)")} -> 1.5700454 | AI10: {=_xll.BQL($C10, "PX_TO_SALES_RATIO(FPT=BA, FPR=2027, FYE=C1231, AE=E)")} -> 1.4522641 | AJ10: =IF(AC10<0,"N/A",$X10/AC10) -> 35.486408 | AK10: {=IF(_xll.BQL($C10, "CURR_ENTP_VAL(FPT=A,FPO=0)/EBITDA(FPT=BA, FPR=2026, FYE=C1231, AE=E)")<0,"N/A",_xll.BQL($C10, "CURR_ENTP_VAL(FPT=A,FPO=0)/EBITDA(FPT=BA, FPR=2026, FYE=C1231, AE=E)"))} -> 27.964893 | AL10: {=IF(_xll.BQL($C10, "CURR_ENTP_VAL(FPT=A,FPO=0)/EBITDA(FPT=BA, FPR=2027, FYE=C1231, AE=E)")<0,"N/A",_xll.BQL($C10, "CURR_ENTP_VAL(FPT=A,FPO=0)/EBITDA(FPT=BA, FPR=2027, FYE=C1231, AE=E)"))} -> 25.553506 | AM10: =_xll.BDP($C10,AM$1) -> 15.132016 | AN10: {=_xll.BQL($C10, "PX_TO_BOOK_RATIO(FPT=BA, FPR=2026, FYE=C1231, AE=E)")} -> 12.562627 | AO10: {=_xll.BQL($C10, "PX_TO_BOOK_RATIO(FPT=BA, FPR=2027, FYE=C1231, AE=E)")} -> 10.905653 | AP10: =_xll.BDP($C10,"BEST Px bps ratio","BEST fperiod override","27Y") -> 11.56212 | AQ10: =Z10 -> 0.29651082 | AR10: =_xll.BDP($C10,"BEST_ROE","BEST fperiod override","26Y")/100 -> 0.28724 | AS10: =_xll.BDP($C10,"BEST_ROE","BEST fperiod override","27Y")/100 -> 0.26459 | AT10: =_xll.BDP($C10,AT$1) -> 0.53711385 | AU10: =_xll.BDP($C10,$AU$1,"BEST fperiod override","26Y") -> 0.49382265 | AV10: =_xll.BDP($C10,$AU$1,"BEST fperiod override","27Y") -> 0.5353096 | AW10: =(BP10/BN10)^(1/2)-1 -> 0.085310885 | AX10: =(BV10/BT10)^(1/2)-1 -> 0.10881618 | AY10: =(CB10/BZ10)^(1/2)-1 -> 0.11049497 | AZ10: {=_xll.BQL($C10, "CF_CASH_FROM_OPER(FPT=BA, FPR=2022, FYE=C1231, AE=A)", "currency=USD")/1000000000} -> 8.1110476 | BA10: {=_xll.BQL($C10, "CF_CASH_FROM_OPER(FPT=BA, FPR=2023, FYE=C1231, AE=A)", "currency=USD")/1000000000} -> 11.855583 | BB10: {=_xll.BQL($C10, "CF_CASH_FROM_OPER(FPT=BA, FPR=2024, FYE=C1231, AE=A)", "currency=USD")/1000000000} -> 10.853845 | BC10: {=_xll.BQL($C10, "CF_CASH_FROM_OPER(FPT=BA, FPR=2025, FYE=C1231, AE=E)", "currency=USD")/1000000000} -> 12.776401 | BD10: {=_xll.BQL($C10, "CF_CASH_FROM_OPER(FPT=BA, FPR=2026, FYE=C1231, AE=E)", "currency=USD")/1000000000} -> 14.729238 | BE10: {=_xll.BQL($C10, "CF_CASH_FROM_OPER(FPT=BA, FPR=2027, FYE=C1231, AE=E)", "currency=USD")/1000000000} -> 15.302553 | BF10: {=_xll.BQL($C10, "CF_FREE_CASH_FLOW(FPT=BA, FPR=2022, FYE=C1231, AE=A)", "currency=USD")/1000000000} -> 4.1279286 | BG10: {=_xll.BQL($C10, "CF_FREE_CASH_FLOW(FPT=BA, FPR=2023, FYE=C1231, AE=A)", "currency=USD")/1000000000} -> 7.5544048 | BH10: {=_xll.BQL($C10, "CF_FREE_CASH_FLOW(FPT=BA, FPR=2024, FYE=C1231, AE=A)", "currency=USD")/1000000000} -> 5.8486071 | BI10: {=_xll.BQL($C10, "CF_FREE_CASH_FLOW(FPT=BA, FPR=2025, FYE=C1231, AE=E)", "currency=USD")/1000000000} -> 6.8187958 | BJ10: {=_xll.BQL($C10, "CF_FREE_CASH_FLOW(FPT=BA, FPR=2026, FYE=C1231, AE=E)", "currency=USD")/1000000000} -> 7.5226847 | BK10: {=_xll.BQL($C10, "CF_FREE_CASH_FLOW(FPT=BA, FPR=2027, FYE=C1231, AE=E)", "currency=USD")/1000000000} -> 8.8964661 | BL10: {=_xll.BQL($C10, "SALES_REV_TURN(FPT=BA, FPR=2022, FYE=C1231, AE=A)", "currency=USD")/1000000000} -> 233.28688 | BM10: {=_xll.BQL($C10, "SALES_REV_TURN(FPT=BA, FPR=2023, FYE=C1231, AE=A)", "currency=USD")/1000000000} -> 243.02776 | BN10: {=_xll.BQL($C10, "SALES_REV_TURN(FPT=BA, FPR=2024, FYE=C1231, AE=A)", "currency=USD")/1000000000} -> 262.52263 | BO10: {=_xll.BQL($C10, "SALES_REV_TURN(FPT=BA, FPR=2025, FYE=C1231, AE=E)", "currency=USD")/1000000000} -> 282.94784 | BP10: {=_xll.BQL($C10, "SALES_REV_TURN(FPT=BA, FPR=2026, FYE=C1231, AE=E)", "currency=USD")/1000000000} -> 309.22533 | BQ10: {=_xll.BQL($C10, "SALES_REV_TURN(FPT=BA, FPR=2027, FYE=C1231, AE=E)", "currency=USD")/1000000000} -> 334.30408 | BR10: {=_xll.BQL($C10, "EBITDA(FPT=BA, FPR=2022, FYE=C1231, AE=A)", "currency=USD")/1000000000} -> 9.8537738 | BS10: {=_xll.BQL($C10, "EBITDA(FPT=BA, FPR=2023, FYE=C1231, AE=A)", "currency=USD")/1000000000} -> 10.393083 | BT10: {=_xll.BQL($C10, "EBITDA(FPT=BA, FPR=2024, FYE=C1231, AE=A)", "currency=USD")/1000000000} -> 11.970952 | BU10: {=_xll.BQL($C10, "EBITDA(FPT=BA, FPR=2025, FYE=C1231, AE=E)", "currency=USD")/1000000000} -> 13.17599 | BV10: {=_xll.BQL($C10, "EBITDA(FPT=BA, FPR=2026, FYE=C1231, AE=E)", "currency=USD")/1000000000} -> 14.717967 | BW10: {=_xll.BQL($C10, "EBITDA(FPT=BA, FPR=2027, FYE=C1231, AE=E)", "currency=USD")/1000000000} -> 16.106845 | BX10: {=_xll.BQL($C10, "NET_INCOME(FPT=BA, FPR=2022, FYE=C1231, AE=A)", "currency=USD")/1000000000} -> 5.9809762 | BY10: {=_xll.BQL($C10, "NET_INCOME(FPT=BA, FPR=2023, FYE=C1231, AE=A)", "currency=USD")/1000000000} -> 6.5277024 | BZ10: {=_xll.BQL($C10, "NET_INCOME(FPT=BA, FPR=2024, FYE=C1231, AE=A)", "currency=USD")/1000000000} -> 7.6373214 | CA10: {=_xll.BQL($C10, "NET_INCOME(FPT=BA, FPR=2025, FYE=C1231, AE=E)", "currency=USD")/1000000000} -> 8.3099475 | CB10: {=_xll.BQL($C10, "NET_INCOME(FPT=BA, FPR=2026, FYE=C1231, AE=E)", "currency=USD")/1000000000} -> 9.4183377 | CC10: {=_xll.BQL($C10, "NET_INCOME(FPT=BA, FPR=2027, FYE=C1231, AE=E)", "currency=USD")/1000000000} -> 10.381945 | CD10: {=-_xll.BQL($C10, "CF_DVD_PAID(FPT=BA, FPR=2024, FYE=C1231, AE=A)", "currency=USD")/1000000000} -> 5.68975 | CE10: {=-_xll.BQL($C10, "CF_DVD_PAID(FPT=BA, FPR=2025, FYE=C1231, AE=E)", "currency=USD")/1000000000} -> 2.3518354 | CF10: {=-_xll.BQL($C10, "CF_DVD_PAID(FPT=BA, FPR=2026, FYE=C1231, AE=E)", "currency=USD")/1000000000} -> 4.3629676 | CG10: {=-_xll.BQL($C10, "CF_DVD_PAID(FPT=BA, FPR=2027, FYE=C1231, AE=E)", "currency=USD")/1000000000} -> 3.0642975 | CH10: =CD10/$F10 -> 1.1719413e-05 | CI10: =CE10/$F10 -> 4.8441727e-06 | CJ10: =CF10/$F10 -> 8.9865848e-06 | CK10: =CG10/$F10 -> 6.3116603e-06 | CL10: {=_xll.BDP($C10,"INTERVAL_AVG", "MARKET_DATA_OVERRIDE=turnover", "CALC_INTERVAL=5D","CRNCY=HKD")/1000000} -> 18203.075 | CM10: {=_xll.BDP($C10,"INTERVAL_AVG", "MARKET_DATA_OVERRIDE=turnover", "CALC_INTERVAL=10D","CRNCY=HKD")/1000000} -> 16602.223 | CN10: {=_xll.BDP($C10,"INTERVAL_AVG", "MARKET_DATA_OVERRIDE=turnover", "CALC_INTERVAL=20D","CRNCY=HKD")/1000000} -> 15043.904 | CO10: {=_xll.BDP($C10,"INTERVAL_AVG", "MARKET_DATA_OVERRIDE=turnover", "CALC_INTERVAL=1m","CRNCY=HKD")/1000000} -> 14440.37 | CP10: {=_xll.BDP($C10,"INTERVAL_AVG", "MARKET_DATA_OVERRIDE=turnover", "CALC_INTERVAL=3M","CRNCY=HKD")/1000000} -> 14496.744 | CQ10: {=_xll.BDP($C10,"INTERVAL_AVG", "MARKET_DATA_OVERRIDE=turnover", "CALC_INTERVAL=6M","CRNCY=HKD")/1000000} -> 16842.298 | CR10: =_xll.BDP($C10,"chg pct 1m")/100 -> 0.09668882 | CS10: =_xll.BDP($C10,"chg pct 3m")/100 -> 0.1106803 | CT10: =_xll.BDP($C10,"chg pct 6m")/100 -> 0.2250445 | CU10: =_xll.BDP($C10,"chg pct 1yr")/100 -> 0.05545809 | CV10: =_xll.BDP($C10,"chg pct ytd")/100 -> 0.2690122 | CW10: {=_xll.BQL($C10, "volatility(calc_interval=range(-1M, 0D))")} -> 0.18496035 | CX10: {=_xll.BQL($C10, "volatility(calc_interval=range(-3M, 0D))")} -> 0.18377653 | CY10: {=_xll.BQL($C10, "volatility(calc_interval=range(-6M, 0D))")} -> 0.1952656 | CZ10: =_xll.BDP($C10,CZ$1) -> Costco Wholesale Corporation is a membership warehouse club The Company sells all kinds of food, automotive supplies, toys, hardware, sporting goods, jewelry, electronics, apparel, health, and beauty aids, as well as other goods. Costco Wholesale serves customers worldwide.
A11: =_xll.BDP($C11,"security name") -> Associated British Foods PLC | B11: =_xll.BDP($C11,"NAME_CHINESE_SIMPLIFIED") -> 英国联合食品公共有限公司 | C11: abf ln EQUITY | D11: =_xll.BDP($C11,"LISTING_DATE") -> #N/A Field Not Applicable | E11: =_xll.BDP($C11,E$1,"EQY_FUND_CRNCY="&$B$1) -> 135311.2 | F11: =_xll.BDP($C11,F$1,"EQY_FUND_CRNCY="&$C$1) -> 17272.3 | G11: =_xll.BDP($C11,G$1) -> 1833 | H11: =_xll.BDP($C11,H$1,"EQY_FUND_CRNCY="&$B$1) -> 118036.02 | I11: =_xll.BDP($C11,I$1,"EQY_FUND_CRNCY="&$C$1) -> 15168.216 | J11: =_xll.BDP($C11,J$1,"EQY_FUND_CRNCY="&$B$1) -> 198050.84 | K11: =_xll.BDP($C11,K$1,"EQY_FUND_CRNCY="&$C$1) -> 25404.338 | L11: =_xll.BDP($C11,L$1,"EQY_FUND_CRNCY="&$B$1) -> 10432.299 | M11: =_xll.BDP($C11,M$1,"EQY_FUND_CRNCY="&$C$1) -> 1338.1698 | N11: =_xll.BDP($C11,N$1)/100 -> 0.23922093 | O11: =_xll.BDP($C11,O$1)/100 -> 0.13253507 | P11: =_xll.BDP($C11,P$1)/100 -> 0.052674855 | Q11: =_xll.BDP($C11,Q$1)/100 -> -0.027195921 | R11: =_xll.BDP($C11,R$1)/100 -> -0.29553265 | S11: =_xll.BDP($C11,S$1)/100 -> 0.32951904 | T11: =_xll.BDP($C11,T$1)/100 -> 0.33330319 | U11: =_xll.BDP($C11,U$1)/100 -> 0.23502593 | ... W11: =_xll.BDP($C11,W$1)/100 -> 0.049596701 | X11: {=_xll.BDP($C11,"CRNCY_ADJ_CURR_EV", "EQY_FUND_CRNCY=HKD")} -> 168838.28 | Y11: {=_xll.BDP($C11,"CRNCY_ADJ_CURR_EV", "EQY_FUND_CRNCY=USD")} -> 21558.665 | Z11: =_xll.BDP($C11,Z$1)/100 -> 0.084613672 | AA11: =_xll.BDP($C11,"TRAIL_12M_NET_SALES","EQY_FUND_CRNCY=HKD") -> 202525.2 | AB11: =_xll.BDP($C11,"TRAIL_12M_NET_INC","EQY_FUND_CRNCY=HKD") -> 9907.2577 | AC11: =_xll.BDP($C11,"TRAIL_12M_EBITDA","EQY_FUND_CRNCY=HKD") -> 24622.143 | AD11: =IF(AB11<0,"N/A",$E11/AB11) -> 13.657785 | AE11: {=_xll.BQL($C11, "PE_RATIO(FPT=BA, FPR=2026, FYE=C1231, AE=E)")} -> 11.27466 | AF11: {=_xll.BQL($C11, "PE_RATIO(FPT=BA, FPR=2027, FYE=C1231, AE=E)")} -> 10.646149 | AG11: =$E11/AA11 -> 0.66812028 | AH11: {=_xll.BQL($C11, "PX_TO_SALES_RATIO(FPT=BA, FPR=2026, FYE=C1231, AE=E)")} -> 0.68200855 | AI11: {=_xll.BQL($C11, "PX_TO_SALES_RATIO(FPT=BA, FPR=2027, FYE=C1231, AE=E)")} -> 0.644861 | AJ11: =IF(AC11<0,"N/A",$X11/AC11) -> 6.8571725 | AK11: {=IF(_xll.BQL($C11, "CURR_ENTP_VAL(FPT=A,FPO=0)/EBITDA(FPT=BA, FPR=2026, FYE=C1231, AE=E)")<0,"N/A",_xll.BQL($C11, "CURR_ENTP_VAL(FPT=A,FPO=0)/EBITDA(FPT=BA, FPR=2026, FYE=C1231, AE=E)"))} -> 7.290167 | AL11: {=IF(_xll.BQL($C11, "CURR_ENTP_VAL(FPT=A,FPO=0)/EBITDA(FPT=BA, FPR=2027, FYE=C1231, AE=E)")<0,"N/A",_xll.BQL($C11, "CURR_ENTP_VAL(FPT=A,FPO=0)/EBITDA(FPT=BA, FPR=2027, FYE=C1231, AE=E)"))} -> 6.9691059 | AM11: =_xll.BDP($C11,AM$1) -> 1.1298633 | AN11: {=_xll.BQL($C11, "PX_TO_BOOK_RATIO(FPT=BA, FPR=2026, FYE=C1231, AE=E)")} -> 1.1192199 | AO11: {=_xll.BQL($C11, "PX_TO_BOOK_RATIO(FPT=BA, FPR=2027, FYE=C1231, AE=E)")} -> 1.0494899 | AP11: =_xll.BDP($C11,"BEST Px bps ratio","BEST fperiod override","27Y") -> 1.0751994 | AQ11: =Z11 -> 0.084613672 | AR11: =_xll.BDP($C11,"BEST_ROE","BEST fperiod override","26Y")/100 -> 0.09814 | AS11: =_xll.BDP($C11,"BEST_ROE","BEST fperiod override","27Y")/100 -> 0.10043 | AT11: =_xll.BDP($C11,AT$1) -> 3.4369885 | AU11: =_xll.BDP($C11,$AU$1,"BEST fperiod override","26Y") -> 3.2460447 | AV11: =_xll.BDP($C11,$AU$1,"BEST fperiod override","27Y") -> 3.3715221 | AW11: =(BP11/BN11)^(1/2)-1 -> 0.0023239674 | AX11: =(BV11/BT11)^(1/2)-1 -> 0.0087649321 | AY11: =(CB11/BZ11)^(1/2)-1 -> -0.10748368 | AZ11: {=_xll.BQL($C11, "CF_CASH_FROM_OPER(FPT=BA, FPR=2022, FYE=C1231, AE=A)", "currency=USD")/1000000000} -> 1.1691067 | BA11: {=_xll.BQL($C11, "CF_CASH_FROM_OPER(FPT=BA, FPR=2023, FYE=C1231, AE=A)", "currency=USD")/1000000000} -> 2.9357923 | BB11: {=_xll.BQL($C11, "CF_CASH_FROM_OPER(FPT=BA, FPR=2024, FYE=C1231, AE=A)", "currency=USD")/1000000000} -> 3.3824466 | BC11: {=_xll.BQL($C11, "CF_CASH_FROM_OPER(FPT=BA, FPR=2025, FYE=C1231, AE=E)", "currency=USD")/1000000000} -> 2.3953424 | BD11: {=_xll.BQL($C11, "CF_CASH_FROM_OPER(FPT=BA, FPR=2026, FYE=C1231, AE=E)", "currency=USD")/1000000000} -> 1.9686017 | BE11: {=_xll.BQL($C11, "CF_CASH_FROM_OPER(FPT=BA, FPR=2027, FYE=C1231, AE=E)", "currency=USD")/1000000000} -> 2.0516051 | BF11: {=_xll.BQL($C11, "CF_FREE_CASH_FLOW(FPT=BA, FPR=2022, FYE=C1231, AE=A)", "currency=USD")/1000000000} -> 0.21227288 | BG11: {=_xll.BQL($C11, "CF_FREE_CASH_FLOW(FPT=BA, FPR=2023, FYE=C1231, AE=A)", "currency=USD")/1000000000} -> 1.621035 | BH11: {=_xll.BQL($C11, "CF_FREE_CASH_FLOW(FPT=BA, FPR=2024, FYE=C1231, AE=A)", "currency=USD")/1000000000} -> 1.9691316 | BI11: {=_xll.BQL($C11, "CF_FREE_CASH_FLOW(FPT=BA, FPR=2025, FYE=C1231, AE=E)", "currency=USD")/1000000000} -> 0.91571912 | BJ11: {=_xll.BQL($C11, "CF_FREE_CASH_FLOW(FPT=BA, FPR=2026, FYE=C1231, AE=E)", "currency=USD")/1000000000} -> 0.94270928 | BK11: {=_xll.BQL($C11, "CF_FREE_CASH_FLOW(FPT=BA, FPR=2027, FYE=C1231, AE=E)", "currency=USD")/1000000000} -> 0.92799304 | BL11: {=_xll.BQL($C11, "SALES_REV_TURN(FPT=BA, FPR=2022, FYE=C1231, AE=A)", "currency=USD")/1000000000} -> 21.937978 | BM11: {=_xll.BQL($C11, "SALES_REV_TURN(FPT=BA, FPR=2023, FYE=C1231, AE=A)", "currency=USD")/1000000000} -> 24.950845 | BN11: {=_xll.BQL($C11, "SALES_REV_TURN(FPT=BA, FPR=2024, FYE=C1231, AE=A)", "currency=USD")/1000000000} -> 25.454993 | BO11: {=_xll.BQL($C11, "SALES_REV_TURN(FPT=BA, FPR=2025, FYE=C1231, AE=E)", "currency=USD")/1000000000} -> 26.137291 | BP11: {=_xll.BQL($C11, "SALES_REV_TURN(FPT=BA, FPR=2026, FYE=C1231, AE=E)", "currency=USD")/1000000000} -> 25.573444 | BQ11: {=_xll.BQL($C11, "SALES_REV_TURN(FPT=BA, FPR=2027, FYE=C1231, AE=E)", "currency=USD")/1000000000} -> 27.046615 | BR11: {=_xll.BQL($C11, "EBITDA(FPT=BA, FPR=2022, FYE=C1231, AE=A)", "currency=USD")/1000000000} -> 2.3553044 | BS11: {=_xll.BQL($C11, "EBITDA(FPT=BA, FPR=2023, FYE=C1231, AE=A)", "currency=USD")/1000000000} -> 2.9400949 | BT11: {=_xll.BQL($C11, "EBITDA(FPT=BA, FPR=2024, FYE=C1231, AE=A)", "currency=USD")/1000000000} -> 3.3878779 | BU11: {=_xll.BQL($C11, "EBITDA(FPT=BA, FPR=2025, FYE=C1231, AE=E)", "currency=USD")/1000000000} -> 3.5387547 | BV11: {=_xll.BQL($C11, "EBITDA(FPT=BA, FPR=2026, FYE=C1231, AE=E)", "currency=USD")/1000000000} -> 3.4475273 | BW11: {=_xll.BQL($C11, "EBITDA(FPT=BA, FPR=2027, FYE=C1231, AE=E)", "currency=USD")/1000000000} -> 3.6063521 | BX11: {=_xll.BQL($C11, "NET_INCOME(FPT=BA, FPR=2022, FYE=C1231, AE=A)", "currency=USD")/1000000000} -> 0.890859 | BY11: {=_xll.BQL($C11, "NET_INCOME(FPT=BA, FPR=2023, FYE=C1231, AE=A)", "currency=USD")/1000000000} -> 1.4193107 | BZ11: {=_xll.BQL($C11, "NET_INCOME(FPT=BA, FPR=2024, FYE=C1231, AE=A)", "currency=USD")/1000000000} -> 1.7471448 | CA11: {=_xll.BQL($C11, "NET_INCOME(FPT=BA, FPR=2025, FYE=C1231, AE=E)", "currency=USD")/1000000000} -> 1.5377899 | CB11: {=_xll.BQL($C11, "NET_INCOME(FPT=BA, FPR=2026, FYE=C1231, AE=E)", "currency=USD")/1000000000} -> 1.39175 | CC11: {=_xll.BQL($C11, "NET_INCOME(FPT=BA, FPR=2027, FYE=C1231, AE=E)", "currency=USD")/1000000000} -> 1.4961078 | CD11: {=-_xll.BQL($C11, "CF_DVD_PAID(FPT=BA, FPR=2024, FYE=C1231, AE=A)", "currency=USD")/1000000000} -> 0.77610423 | CE11: {=-_xll.BQL($C11, "CF_DVD_PAID(FPT=BA, FPR=2025, FYE=C1231, AE=E)", "currency=USD")/1000000000} -> 0.49583445 | CF11: {=-_xll.BQL($C11, "CF_DVD_PAID(FPT=BA, FPR=2026, FYE=C1231, AE=E)", "currency=USD")/1000000000} -> 0.55177703 | CG11: {=-_xll.BQL($C11, "CF_DVD_PAID(FPT=BA, FPR=2027, FYE=C1231, AE=E)", "currency=USD")/1000000000} -> 0.47900223 | CH11: =CD11/$F11 -> 4.4933463e-05 | CI11: =CE11/$F11 -> 2.8706916e-05 | CJ11: =CF11/$F11 -> 3.1945777e-05 | CK11: =CG11/$F11 -> 2.7732395e-05 | CL11: {=_xll.BDP($C11,"INTERVAL_AVG", "MARKET_DATA_OVERRIDE=turnover", "CALC_INTERVAL=5D","CRNCY=HKD")/1000000} -> 129.2982 | CM11: {=_xll.BDP($C11,"INTERVAL_AVG", "MARKET_DATA_OVERRIDE=turnover", "CALC_INTERVAL=10D","CRNCY=HKD")/1000000} -> 135.86173 | CN11: {=_xll.BDP($C11,"INTERVAL_AVG", "MARKET_DATA_OVERRIDE=turnover", "CALC_INTERVAL=20D","CRNCY=HKD")/1000000} -> 149.59612 | CO11: {=_xll.BDP($C11,"INTERVAL_AVG", "MARKET_DATA_OVERRIDE=turnover", "CALC_INTERVAL=1m","CRNCY=HKD")/1000000} -> 163.17554 | CP11: {=_xll.BDP($C11,"INTERVAL_AVG", "MARKET_DATA_OVERRIDE=turnover", "CALC_INTERVAL=3M","CRNCY=HKD")/1000000} -> 160.5872 | CQ11: {=_xll.BDP($C11,"INTERVAL_AVG", "MARKET_DATA_OVERRIDE=turnover", "CALC_INTERVAL=6M","CRNCY=HKD")/1000000} -> 154.51915 | CR11: =_xll.BDP($C11,"chg pct 1m")/100 -> -0.02758621 | CS11: =_xll.BDP($C11,"chg pct 3m")/100 -> -0.06168416 | CT11: =_xll.BDP($C11,"chg pct 6m")/100 -> -0.126727 | CU11: =_xll.BDP($C11,"chg pct 1yr")/100 -> -0.1390324 | CV11: =_xll.BDP($C11,"chg pct ytd")/100 -> -0.1382228 | CW11: {=_xll.BQL($C11, "volatility(calc_interval=range(-1M, 0D))")} -> 0.21825153 | CX11: {=_xll.BQL($C11, "volatility(calc_interval=range(-3M, 0D))")} -> 0.21275675 | CY11: {=_xll.BQL($C11, "volatility(calc_interval=range(-6M, 0D))")} -> 0.2706094 | CZ11: =_xll.BDP($C11,CZ$1) -> Associated British Foods PLC operates as a group company. The Company, through its subsidiaries, offers groceries, clothing, and household products, as well as produces sugar and baker's yeast ingredients including emulsifiers, enzymes, and lactose. Associated British Foods serves customers worldwide.
A12: =_xll.BDP($C12,"security name") -> Manhattan Associates Inc | B12: =_xll.BDP($C12,"NAME_CHINESE_SIMPLIFIED") -> 曼哈顿联合软件公司 | C12: MANH US EQUITY | D12: =_xll.BDP($C12,"LISTING_DATE") -> 4/23/1998 | E12: =_xll.BDP($C12,E$1,"EQY_FUND_CRNCY="&$B$1) -> 62764.157 | F12: =_xll.BDP($C12,F$1,"EQY_FUND_CRNCY="&$C$1) -> 8012.0704 | G12: =_xll.BDP($C12,G$1) -> 135.42 | H12: =_xll.BDP($C12,H$1,"EQY_FUND_CRNCY="&$B$1) -> 2450.0993 | I12: =_xll.BDP($C12,I$1,"EQY_FUND_CRNCY="&$C$1) -> 314.765 | J12: =_xll.BDP($C12,J$1,"EQY_FUND_CRNCY="&$B$1) -> 8430.351 | K12: =_xll.BDP($C12,K$1,"EQY_FUND_CRNCY="&$C$1) -> 1081.392 | L12: =_xll.BDP($C12,L$1,"EQY_FUND_CRNCY="&$B$1) -> 1714.6778 | M12: =_xll.BDP($C12,M$1,"EQY_FUND_CRNCY="&$C$1) -> 219.948 | N12: =_xll.BDP($C12,N$1)/100 -> 0.56321205 | O12: =_xll.BDP($C12,O$1)/100 -> 0.26997703 | P12: =_xll.BDP($C12,P$1)/100 -> 0.2033934 | Q12: =_xll.BDP($C12,Q$1)/100 -> 0.037453758 | R12: =_xll.BDP($C12,R$1)/100 -> 0.007253943 | S12: =_xll.BDP($C12,S$1)/100 -> 0.19399552 | T12: =_xll.BDP($C12,T$1)/100 -> 0.19399552 | U12: =_xll.BDP($C12,U$1)/100 -> -0.85042492 | ... W12: =_xll.BDP($C12,W$1)/100 -> 0.29909875 | X12: {=_xll.BDP($C12,"CRNCY_ADJ_CURR_EV", "EQY_FUND_CRNCY=HKD")} -> 61427.69 | Y12: {=_xll.BDP($C12,"CRNCY_ADJ_CURR_EV", "EQY_FUND_CRNCY=USD")} -> 7841.6224 | Z12: =_xll.BDP($C12,Z$1)/100 -> 0.96236036 | AA12: =_xll.BDP($C12,"TRAIL_12M_NET_SALES","EQY_FUND_CRNCY=HKD") -> 8590.7453 | AB12: =_xll.BDP($C12,"TRAIL_12M_NET_INC","EQY_FUND_CRNCY=HKD") -> 1690.8118 | AC12: =_xll.BDP($C12,"TRAIL_12M_EBITDA","EQY_FUND_CRNCY=HKD") -> 2248.8958 | AD12: =IF(AB12<0,"N/A",$E12/AB12) -> 37.120723 | AE12: {=_xll.BQL($C12, "PE_RATIO(FPT=BA, FPR=2026, FYE=C1231, AE=E)")} -> 25.272783 | AF12: {=_xll.BQL($C12, "PE_RATIO(FPT=BA, FPR=2027, FYE=C1231, AE=E)")} -> 22.705603 | AG12: =$E12/AA12 -> 7.30602 | AH12: {=_xll.BQL($C12, "PX_TO_SALES_RATIO(FPT=BA, FPR=2026, FYE=C1231, AE=E)")} -> 6.9463799 | AI12: {=_xll.BQL($C12, "PX_TO_SALES_RATIO(FPT=BA, FPR=2027, FYE=C1231, AE=E)")} -> 6.3989913 | AJ12: =IF(AC12<0,"N/A",$X12/AC12) -> 27.314601 | AK12: {=IF(_xll.BQL($C12, "CURR_ENTP_VAL(FPT=A,FPO=0)/EBITDA(FPT=BA, FPR=2026, FYE=C1231, AE=E)")<0,"N/A",_xll.BQL($C12, "CURR_ENTP_VAL(FPT=A,FPO=0)/EBITDA(FPT=BA, FPR=2026, FYE=C1231, AE=E)"))} -> 22.767815 | AL12: {=IF(_xll.BQL($C12, "CURR_ENTP_VAL(FPT=A,FPO=0)/EBITDA(FPT=BA, FPR=2027, FYE=C1231, AE=E)")<0,"N/A",_xll.BQL($C12, "CURR_ENTP_VAL(FPT=A,FPO=0)/EBITDA(FPT=BA, FPR=2027, FYE=C1231, AE=E)"))} -> 20.555926 | AM12: =_xll.BDP($C12,AM$1) -> 39.049862 | AN12: {=_xll.BQL($C12, "PX_TO_BOOK_RATIO(FPT=BA, FPR=2026, FYE=C1231, AE=E)")} -> 28.509473 | AO12: {=_xll.BQL($C12, "PX_TO_BOOK_RATIO(FPT=BA, FPR=2027, FYE=C1231, AE=E)")} -> 12.603071 | AP12: =_xll.BDP($C12,"BEST Px bps ratio","BEST fperiod override","27Y") -> 26.244186 | AQ12: =Z12 -> 0.96236036 | AR12: =_xll.BDP($C12,"BEST_ROE","BEST fperiod override","26Y")/100 -> 1.05773 | AS12: =_xll.BDP($C12,"BEST_ROE","BEST fperiod override","27Y")/100 -> 1.47583 | AT12: =_xll.BDP($C12,AT$1) -> #N/A N/A | AU12: =_xll.BDP($C12,$AU$1,"BEST fperiod override","26Y") -> 0 | AV12: =_xll.BDP($C12,$AU$1,"BEST fperiod override","27Y") -> 0 | AW12: =(BP12/BN12)^(1/2)-1 -> 0.051927743 | AX12: =(BV12/BT12)^(1/2)-1 -> 0.21950629 | AY12: =(CB12/BZ12)^(1/2)-1 -> 0.0073823964 | AZ12: {=_xll.BQL($C12, "CF_CASH_FROM_OPER(FPT=BA, FPR=2022, FYE=C1231, AE=A)", "currency=USD")/1000000000} -> 0.17963 | BA12: {=_xll.BQL($C12, "CF_CASH_FROM_OPER(FPT=BA, FPR=2023, FYE=C1231, AE=A)", "currency=USD")/1000000000} -> 0.246218 | BB12: {=_xll.BQL($C12, "CF_CASH_FROM_OPER(FPT=BA, FPR=2024, FYE=C1231, AE=A)", "currency=USD")/1000000000} -> 0.295003 | BC12: {=_xll.BQL($C12, "CF_CASH_FROM_OPER(FPT=BA, FPR=2025, FYE=C1231, AE=E)", "currency=USD")/1000000000} -> 0.33073013 | BD12: {=_xll.BQL($C12, "CF_CASH_FROM_OPER(FPT=BA, FPR=2026, FYE=C1231, AE=E)", "currency=USD")/1000000000} -> 0.38220333 | BE12: {=_xll.BQL($C12, "CF_CASH_FROM_OPER(FPT=BA, FPR=2027, FYE=C1231, AE=E)", "currency=USD")/1000000000} -> 0.41356057 | BF12: {=_xll.BQL($C12, "CF_FREE_CASH_FLOW(FPT=BA, FPR=2022, FYE=C1231, AE=A)", "currency=USD")/1000000000} -> 0.173043 | BG12: {=_xll.BQL($C12, "CF_FREE_CASH_FLOW(FPT=BA, FPR=2023, FYE=C1231, AE=A)", "currency=USD")/1000000000} -> 0.241488 | BH12: {=_xll.BQL($C12, "CF_FREE_CASH_FLOW(FPT=BA, FPR=2024, FYE=C1231, AE=A)", "currency=USD")/1000000000} -> 0.286328 | BI12: {=_xll.BQL($C12, "CF_FREE_CASH_FLOW(FPT=BA, FPR=2025, FYE=C1231, AE=E)", "currency=USD")/1000000000} -> 0.3199796 | BJ12: {=_xll.BQL($C12, "CF_FREE_CASH_FLOW(FPT=BA, FPR=2026, FYE=C1231, AE=E)", "currency=USD")/1000000000} -> 0.37471904 | BK12: {=_xll.BQL($C12, "CF_FREE_CASH_FLOW(FPT=BA, FPR=2027, FYE=C1231, AE=E)", "currency=USD")/1000000000} -> 0.41477038 | BL12: {=_xll.BQL($C12, "SALES_REV_TURN(FPT=BA, FPR=2022, FYE=C1231, AE=A)", "currency=USD")/1000000000} -> 0.767084 | BM12: {=_xll.BQL($C12, "SALES_REV_TURN(FPT=BA, FPR=2023, FYE=C1231, AE=A)", "currency=USD")/1000000000} -> 0.928725 | BN12: {=_xll.BQL($C12, "SALES_REV_TURN(FPT=BA, FPR=2024, FYE=C1231, AE=A)", "currency=USD")/1000000000} -> 1.042352 | BO12: {=_xll.BQL($C12, "SALES_REV_TURN(FPT=BA, FPR=2025, FYE=C1231, AE=E)", "currency=USD")/1000000000} -> 1.0758333 | BP12: {=_xll.BQL($C12, "SALES_REV_TURN(FPT=BA, FPR=2026, FYE=C1231, AE=E)", "currency=USD")/1000000000} -> 1.1534167 | BQ12: {=_xll.BQL($C12, "SALES_REV_TURN(FPT=BA, FPR=2027, FYE=C1231, AE=E)", "currency=USD")/1000000000} -> 1.2520833 | BR12: {=_xll.BQL($C12, "EBITDA(FPT=BA, FPR=2022, FYE=C1231, AE=A)", "currency=USD")/1000000000} -> 0.166663 | BS12: {=_xll.BQL($C12, "EBITDA(FPT=BA, FPR=2023, FYE=C1231, AE=A)", "currency=USD")/1000000000} -> 0.223433 | BT12: {=_xll.BQL($C12, "EBITDA(FPT=BA, FPR=2024, FYE=C1231, AE=A)", "currency=USD")/1000000000} -> 0.276897 | BU12: {=_xll.BQL($C12, "EBITDA(FPT=BA, FPR=2025, FYE=C1231, AE=E)", "currency=USD")/1000000000} -> 0.391 | BV12: {=_xll.BQL($C12, "EBITDA(FPT=BA, FPR=2026, FYE=C1231, AE=E)", "currency=USD")/1000000000} -> 0.4118 | BW12: {=_xll.BQL($C12, "EBITDA(FPT=BA, FPR=2027, FYE=C1231, AE=E)", "currency=USD")/1000000000} -> 0.45611111 | BX12: {=_xll.BQL($C12, "NET_INCOME(FPT=BA, FPR=2022, FYE=C1231, AE=A)", "currency=USD")/1000000000} -> 0.128959 | BY12: {=_xll.BQL($C12, "NET_INCOME(FPT=BA, FPR=2023, FYE=C1231, AE=A)", "currency=USD")/1000000000} -> 0.176568 | BZ12: {=_xll.BQL($C12, "NET_INCOME(FPT=BA, FPR=2024, FYE=C1231, AE=A)", "currency=USD")/1000000000} -> 0.218364 | CA12: {=_xll.BQL($C12, "NET_INCOME(FPT=BA, FPR=2025, FYE=C1231, AE=E)", "currency=USD")/1000000000} -> 0.2144 | CB12: {=_xll.BQL($C12, "NET_INCOME(FPT=BA, FPR=2026, FYE=C1231, AE=E)", "currency=USD")/1000000000} -> 0.2216 | CC12: {=_xll.BQL($C12, "NET_INCOME(FPT=BA, FPR=2027, FYE=C1231, AE=E)", "currency=USD")/1000000000} -> 0.2537 | CD12: {=-_xll.BQL($C12, "CF_DVD_PAID(FPT=BA, FPR=2024, FYE=C1231, AE=A)", "currency=USD")/1000000000} -> 0 | CE12: {=-_xll.BQL($C12, "CF_DVD_PAID(FPT=BA, FPR=2025, FYE=C1231, AE=E)", "currency=USD")/1000000000} -> #VALUE! | CF12: {=-_xll.BQL($C12, "CF_DVD_PAID(FPT=BA, FPR=2026, FYE=C1231, AE=E)", "currency=USD")/1000000000} -> #VALUE! | CG12: {=-_xll.BQL($C12, "CF_DVD_PAID(FPT=BA, FPR=2027, FYE=C1231, AE=E)", "currency=USD")/1000000000} -> #VALUE! | CH12: =CD12/$F12 -> 0 | CI12: =CE12/$F12 -> #VALUE! | CJ12: =CF12/$F12 -> #VALUE! | CK12: =CG12/$F12 -> #VALUE! | CL12: {=_xll.BDP($C12,"INTERVAL_AVG", "MARKET_DATA_OVERRIDE=turnover", "CALC_INTERVAL=5D","CRNCY=HKD")/1000000} -> 570.01422 | CM12: {=_xll.BDP($C12,"INTERVAL_AVG", "MARKET_DATA_OVERRIDE=turnover", "CALC_INTERVAL=10D","CRNCY=HKD")/1000000} -> 599.99188 | CN12: {=_xll.BDP($C12,"INTERVAL_AVG", "MARKET_DATA_OVERRIDE=turnover", "CALC_INTERVAL=20D","CRNCY=HKD")/1000000} -> 758.0417 | CO12: {=_xll.BDP($C12,"INTERVAL_AVG", "MARKET_DATA_OVERRIDE=turnover", "CALC_INTERVAL=1m","CRNCY=HKD")/1000000} -> 801.78106 | CP12: {=_xll.BDP($C12,"INTERVAL_AVG", "MARKET_DATA_OVERRIDE=turnover", "CALC_INTERVAL=3M","CRNCY=HKD")/1000000} -> 751.70417 | CQ12: {=_xll.BDP($C12,"INTERVAL_AVG", "MARKET_DATA_OVERRIDE=turnover", "CALC_INTERVAL=6M","CRNCY=HKD")/1000000} -> 834.43368 | CR12: =_xll.BDP($C12,"chg pct 1m")/100 -> 0.01188073 | CS12: =_xll.BDP($C12,"chg pct 3m")/100 -> -0.06134334 | CT12: =_xll.BDP($C12,"chg pct 6m")/100 -> -0.1971305 | CU12: =_xll.BDP($C12,"chg pct 1yr")/100 -> -0.2941361 | CV12: =_xll.BDP($C12,"chg pct ytd")/100 -> -0.2186256 | CW12: {=_xll.BQL($C12, "volatility(calc_interval=range(-1M, 0D))")} -> 0.51654275 | CX12: {=_xll.BQL($C12, "volatility(calc_interval=range(-3M, 0D))")} -> 0.49307174 | CY12: {=_xll.BQL($C12, "volatility(calc_interval=range(-6M, 0D))")} -> 0.43677486 | CZ12: =_xll.BDP($C12,CZ$1) -> Manhattan Associates, Inc. provides information technology solutions for distribution centers. The solutions are designed to enable the efficient movement of goods through the supply chain. The Company offers solutions optimize the receipt, storage, and distribution of inventory, as well as manage equipment and personnel within a distribution center.
